2023-11-18 18:44:54,405 - ERROR - An error occurred: [WinError 10061] No connection could be made because the target machine actively refused it
Traceback (most recent call last):
  File "c:\Users\Marios Stefanidis\Documents\GitHub\Diploma-Thesis\code\slarchive-server\encryption\ssl_con.py", line 140, in run
    self.connect()
  File "c:\Users\Marios Stefanidis\Documents\GitHub\Diploma-Thesis\code\slarchive-server\encryption\ssl_con.py", line 26, in connect
    self.client_socket.connect(('127.0.0.1', 8443)) # Connect to the server
    ^^^^^^^^^^^^^^^^^^^^^^^^^^^^^^^^^^^^^^^^^^^^^^^
ConnectionRefusedError: [WinError 10061] No connection could be made because the target machine actively refused it
2023-11-18 18:44:54,406 - INFO - SSL Connection closed!
2023-11-18 19:16:27,056 - ERROR - An error occurred: [WinError 10061] No connection could be made because the target machine actively refused it
Traceback (most recent call last):
  File "c:\Users\Marios Stefanidis\Documents\GitHub\Diploma-Thesis\code\slarchive-server\encryption\ssl_con.py", line 140, in run
    self.connect()
  File "c:\Users\Marios Stefanidis\Documents\GitHub\Diploma-Thesis\code\slarchive-server\encryption\ssl_con.py", line 26, in connect
    self.client_socket.connect(('127.0.0.1', 8443)) # Connect to the server
    ^^^^^^^^^^^^^^^^^^^^^^^^^^^^^^^^^^^^^^^^^^^^^^^
ConnectionRefusedError: [WinError 10061] No connection could be made because the target machine actively refused it
2023-11-18 19:16:27,057 - INFO - SSL Connection closed!
2023-11-18 19:16:42,666 - ERROR - An error occurred: [WinError 10061] No connection could be made because the target machine actively refused it
Traceback (most recent call last):
  File "c:\Users\Marios Stefanidis\Documents\GitHub\Diploma-Thesis\code\slarchive-server\encryption\ssl_con.py", line 140, in run
    self.connect()
  File "c:\Users\Marios Stefanidis\Documents\GitHub\Diploma-Thesis\code\slarchive-server\encryption\ssl_con.py", line 26, in connect
    self.client_socket.connect(('127.0.0.1', 8443)) # Connect to the server
    ^^^^^^^^^^^^^^^^^^^^^^^^^^^^^^^^^^^^^^^^^^^^^^^
ConnectionRefusedError: [WinError 10061] No connection could be made because the target machine actively refused it
2023-11-18 19:16:42,667 - INFO - SSL Connection closed!
2023-11-18 19:18:25,895 - ERROR - An error occurred: [WinError 10061] No connection could be made because the target machine actively refused it
Traceback (most recent call last):
  File "c:\Users\Marios Stefanidis\Documents\GitHub\Diploma-Thesis\code\slarchive-server\encryption\ssl_con.py", line 140, in run
    self.connect()
  File "c:\Users\Marios Stefanidis\Documents\GitHub\Diploma-Thesis\code\slarchive-server\encryption\ssl_con.py", line 26, in connect
    self.client_socket.connect(('127.0.0.1', 8443)) # Connect to the server
    ^^^^^^^^^^^^^^^^^^^^^^^^^^^^^^^^^^^^^^^^^^^^^^^
ConnectionRefusedError: [WinError 10061] No connection could be made because the target machine actively refused it
2023-11-18 19:18:25,896 - INFO - SSL Connection closed!
2023-11-18 19:18:28,665 - ERROR - An error occurred: [WinError 10061] No connection could be made because the target machine actively refused it
Traceback (most recent call last):
  File "c:\Users\Marios Stefanidis\Documents\GitHub\Diploma-Thesis\code\slarchive-server\encryption\ssl_con.py", line 140, in run
    self.connect()
  File "c:\Users\Marios Stefanidis\Documents\GitHub\Diploma-Thesis\code\slarchive-server\encryption\ssl_con.py", line 26, in connect
    self.client_socket.connect(('127.0.0.1', 8443)) # Connect to the server
    ^^^^^^^^^^^^^^^^^^^^^^^^^^^^^^^^^^^^^^^^^^^^^^^
ConnectionRefusedError: [WinError 10061] No connection could be made because the target machine actively refused it
2023-11-18 19:18:28,666 - INFO - SSL Connection closed!
2023-11-18 19:20:11,456 - INFO - Handshake was successful!
2023-11-18 19:20:11,511 - INFO - Master Key and IV were successfully sent.
2023-11-18 19:20:11,727 - INFO - Encryption process completed for source file: .\..\archive\2023\HP\UPR\HHE.D\HP.UPR..HHE.D.2023.322.
2023-11-18 19:20:11,727 - INFO - Total Size of Data and Chunk Size were successfully sent.
2023-11-18 19:20:11,727 - INFO - Encrypted data were sent successfully.
2023-11-18 19:20:11,917 - ERROR - TLS handshake error: 
Traceback (most recent call last):
  File "c:\Users\Marios Stefanidis\Documents\GitHub\Diploma-Thesis\code\slarchive-server\encryption\ssl_con.py", line 147, in run
    rejection_message = self.ssl_socket.recv(4096)
                        ^^^^^^^^^^^^^^^^^^^^^^^^^^
  File "C:\Users\Marios Stefanidis\AppData\Local\Programs\Python\Python311\Lib\site-packages\OpenSSL\SSL.py", line 2076, in recv
    self._raise_ssl_error(self._ssl, result)
  File "C:\Users\Marios Stefanidis\AppData\Local\Programs\Python\Python311\Lib\site-packages\OpenSSL\SSL.py", line 1814, in _raise_ssl_error
    raise ZeroReturnError()
OpenSSL.SSL.ZeroReturnError
2023-11-18 19:20:11,937 - INFO - SSL Connection closed!
2023-11-18 19:20:25,606 - INFO - Handshake was successful!
2023-11-18 19:20:25,617 - INFO - Master Key and IV were successfully sent.
2023-11-18 19:20:25,797 - INFO - Encryption process completed for source file: .\..\archive\2023\HP\UPR\HHN.D\HP.UPR..HHN.D.2023.322.
2023-11-18 19:20:25,797 - INFO - Total Size of Data and Chunk Size were successfully sent.
2023-11-18 19:20:25,797 - INFO - Encrypted data were sent successfully.
2023-11-18 19:20:25,919 - ERROR - TLS handshake error: 
Traceback (most recent call last):
  File "c:\Users\Marios Stefanidis\Documents\GitHub\Diploma-Thesis\code\slarchive-server\encryption\ssl_con.py", line 147, in run
    rejection_message = self.ssl_socket.recv(4096)
                        ^^^^^^^^^^^^^^^^^^^^^^^^^^
  File "C:\Users\Marios Stefanidis\AppData\Local\Programs\Python\Python311\Lib\site-packages\OpenSSL\SSL.py", line 2076, in recv
    self._raise_ssl_error(self._ssl, result)
  File "C:\Users\Marios Stefanidis\AppData\Local\Programs\Python\Python311\Lib\site-packages\OpenSSL\SSL.py", line 1814, in _raise_ssl_error
    raise ZeroReturnError()
OpenSSL.SSL.ZeroReturnError
2023-11-18 19:20:25,921 - INFO - SSL Connection closed!
2023-11-18 19:20:27,089 - INFO - Handshake was successful!
2023-11-18 19:20:27,102 - INFO - Master Key and IV were successfully sent.
2023-11-18 19:20:27,281 - INFO - Encryption process completed for source file: .\..\archive\2023\HP\UPR\HHZ.D\HP.UPR..HHZ.D.2023.322.
2023-11-18 19:20:27,281 - INFO - Total Size of Data and Chunk Size were successfully sent.
2023-11-18 19:20:27,281 - INFO - Encrypted data were sent successfully.
2023-11-18 19:20:27,398 - ERROR - TLS handshake error: 
Traceback (most recent call last):
  File "c:\Users\Marios Stefanidis\Documents\GitHub\Diploma-Thesis\code\slarchive-server\encryption\ssl_con.py", line 147, in run
    rejection_message = self.ssl_socket.recv(4096)
                        ^^^^^^^^^^^^^^^^^^^^^^^^^^
  File "C:\Users\Marios Stefanidis\AppData\Local\Programs\Python\Python311\Lib\site-packages\OpenSSL\SSL.py", line 2076, in recv
    self._raise_ssl_error(self._ssl, result)
  File "C:\Users\Marios Stefanidis\AppData\Local\Programs\Python\Python311\Lib\site-packages\OpenSSL\SSL.py", line 1814, in _raise_ssl_error
    raise ZeroReturnError()
OpenSSL.SSL.ZeroReturnError
2023-11-18 19:20:27,398 - INFO - SSL Connection closed!
2023-11-18 19:20:50,380 - INFO - Handshake was successful!
2023-11-18 19:20:50,392 - INFO - Master Key and IV were successfully sent.
2023-11-18 19:20:50,568 - INFO - Encryption process completed for source file: .\..\archive\2023\HP\UPR\HNE.D\HP.UPR..HNE.D.2023.322.
2023-11-18 19:20:50,575 - INFO - Total Size of Data and Chunk Size were successfully sent.
2023-11-18 19:20:50,576 - INFO - Encrypted data were sent successfully.
2023-11-18 19:20:50,697 - ERROR - TLS handshake error: 
Traceback (most recent call last):
  File "c:\Users\Marios Stefanidis\Documents\GitHub\Diploma-Thesis\code\slarchive-server\encryption\ssl_con.py", line 147, in run
    rejection_message = self.ssl_socket.recv(4096)
                        ^^^^^^^^^^^^^^^^^^^^^^^^^^
  File "C:\Users\Marios Stefanidis\AppData\Local\Programs\Python\Python311\Lib\site-packages\OpenSSL\SSL.py", line 2076, in recv
    self._raise_ssl_error(self._ssl, result)
  File "C:\Users\Marios Stefanidis\AppData\Local\Programs\Python\Python311\Lib\site-packages\OpenSSL\SSL.py", line 1814, in _raise_ssl_error
    raise ZeroReturnError()
OpenSSL.SSL.ZeroReturnError
2023-11-18 19:20:50,700 - INFO - SSL Connection closed!
2023-11-18 19:20:53,426 - INFO - Handshake was successful!
2023-11-18 19:20:53,442 - INFO - Master Key and IV were successfully sent.
2023-11-18 19:20:53,637 - INFO - Encryption process completed for source file: .\..\archive\2023\HP\UPR\HNN.D\HP.UPR..HNN.D.2023.322.
2023-11-18 19:20:53,643 - INFO - Total Size of Data and Chunk Size were successfully sent.
2023-11-18 19:20:53,643 - INFO - Encrypted data were sent successfully.
2023-11-18 19:20:53,771 - ERROR - TLS handshake error: 
Traceback (most recent call last):
  File "c:\Users\Marios Stefanidis\Documents\GitHub\Diploma-Thesis\code\slarchive-server\encryption\ssl_con.py", line 147, in run
    rejection_message = self.ssl_socket.recv(4096)
                        ^^^^^^^^^^^^^^^^^^^^^^^^^^
  File "C:\Users\Marios Stefanidis\AppData\Local\Programs\Python\Python311\Lib\site-packages\OpenSSL\SSL.py", line 2076, in recv
    self._raise_ssl_error(self._ssl, result)
  File "C:\Users\Marios Stefanidis\AppData\Local\Programs\Python\Python311\Lib\site-packages\OpenSSL\SSL.py", line 1814, in _raise_ssl_error
    raise ZeroReturnError()
OpenSSL.SSL.ZeroReturnError
2023-11-18 19:20:53,775 - INFO - SSL Connection closed!
2023-11-18 19:20:54,506 - INFO - Handshake was successful!
2023-11-18 19:20:54,516 - INFO - Master Key and IV were successfully sent.
2023-11-18 19:20:54,696 - INFO - Encryption process completed for source file: .\..\archive\2023\HP\UPR\HNN.D\HP.UPR..HNN.D.2023.322.
2023-11-18 19:20:54,706 - INFO - Total Size of Data and Chunk Size were successfully sent.
2023-11-18 19:20:54,706 - INFO - Encrypted data were sent successfully.
2023-11-18 19:20:54,843 - ERROR - TLS handshake error: 
Traceback (most recent call last):
  File "c:\Users\Marios Stefanidis\Documents\GitHub\Diploma-Thesis\code\slarchive-server\encryption\ssl_con.py", line 147, in run
    rejection_message = self.ssl_socket.recv(4096)
                        ^^^^^^^^^^^^^^^^^^^^^^^^^^
  File "C:\Users\Marios Stefanidis\AppData\Local\Programs\Python\Python311\Lib\site-packages\OpenSSL\SSL.py", line 2076, in recv
    self._raise_ssl_error(self._ssl, result)
  File "C:\Users\Marios Stefanidis\AppData\Local\Programs\Python\Python311\Lib\site-packages\OpenSSL\SSL.py", line 1814, in _raise_ssl_error
    raise ZeroReturnError()
OpenSSL.SSL.ZeroReturnError
2023-11-18 19:20:54,845 - INFO - SSL Connection closed!
2023-11-18 19:21:16,141 - INFO - Handshake was successful!
2023-11-18 19:21:16,147 - INFO - Master Key and IV were successfully sent.
2023-11-18 19:21:16,336 - INFO - Encryption process completed for source file: .\..\archive\2023\HP\UPR\HNE.D\HP.UPR..HNE.D.2023.322.
2023-11-18 19:21:16,345 - INFO - Total Size of Data and Chunk Size were successfully sent.
2023-11-18 19:21:16,345 - INFO - Encrypted data were sent successfully.
2023-11-18 19:21:16,460 - ERROR - TLS handshake error: 
Traceback (most recent call last):
  File "c:\Users\Marios Stefanidis\Documents\GitHub\Diploma-Thesis\code\slarchive-server\encryption\ssl_con.py", line 147, in run
    rejection_message = self.ssl_socket.recv(4096)
                        ^^^^^^^^^^^^^^^^^^^^^^^^^^
  File "C:\Users\Marios Stefanidis\AppData\Local\Programs\Python\Python311\Lib\site-packages\OpenSSL\SSL.py", line 2076, in recv
    self._raise_ssl_error(self._ssl, result)
  File "C:\Users\Marios Stefanidis\AppData\Local\Programs\Python\Python311\Lib\site-packages\OpenSSL\SSL.py", line 1814, in _raise_ssl_error
    raise ZeroReturnError()
OpenSSL.SSL.ZeroReturnError
2023-11-18 19:21:16,460 - INFO - SSL Connection closed!
2023-11-18 19:21:17,166 - INFO - Handshake was successful!
2023-11-18 19:21:17,179 - INFO - Master Key and IV were successfully sent.
2023-11-18 19:21:17,360 - INFO - Encryption process completed for source file: .\..\archive\2023\HP\UPR\HHZ.D\HP.UPR..HHZ.D.2023.322.
2023-11-18 19:21:17,366 - INFO - Total Size of Data and Chunk Size were successfully sent.
2023-11-18 19:21:17,366 - INFO - Encrypted data were sent successfully.
2023-11-18 19:21:17,477 - ERROR - TLS handshake error: 
Traceback (most recent call last):
  File "c:\Users\Marios Stefanidis\Documents\GitHub\Diploma-Thesis\code\slarchive-server\encryption\ssl_con.py", line 147, in run
    rejection_message = self.ssl_socket.recv(4096)
                        ^^^^^^^^^^^^^^^^^^^^^^^^^^
  File "C:\Users\Marios Stefanidis\AppData\Local\Programs\Python\Python311\Lib\site-packages\OpenSSL\SSL.py", line 2076, in recv
    self._raise_ssl_error(self._ssl, result)
  File "C:\Users\Marios Stefanidis\AppData\Local\Programs\Python\Python311\Lib\site-packages\OpenSSL\SSL.py", line 1814, in _raise_ssl_error
    raise ZeroReturnError()
OpenSSL.SSL.ZeroReturnError
2023-11-18 19:21:17,477 - INFO - SSL Connection closed!
2023-11-18 19:21:18,300 - INFO - Handshake was successful!
2023-11-18 19:21:18,312 - INFO - Master Key and IV were successfully sent.
2023-11-18 19:21:18,493 - INFO - Encryption process completed for source file: .\..\archive\2023\HP\UPR\HHN.D\HP.UPR..HHN.D.2023.322.
2023-11-18 19:21:18,494 - INFO - Total Size of Data and Chunk Size were successfully sent.
2023-11-18 19:21:18,494 - INFO - Encrypted data were sent successfully.
2023-11-18 19:21:18,607 - ERROR - TLS handshake error: 
Traceback (most recent call last):
  File "c:\Users\Marios Stefanidis\Documents\GitHub\Diploma-Thesis\code\slarchive-server\encryption\ssl_con.py", line 147, in run
    rejection_message = self.ssl_socket.recv(4096)
                        ^^^^^^^^^^^^^^^^^^^^^^^^^^
  File "C:\Users\Marios Stefanidis\AppData\Local\Programs\Python\Python311\Lib\site-packages\OpenSSL\SSL.py", line 2076, in recv
    self._raise_ssl_error(self._ssl, result)
  File "C:\Users\Marios Stefanidis\AppData\Local\Programs\Python\Python311\Lib\site-packages\OpenSSL\SSL.py", line 1814, in _raise_ssl_error
    raise ZeroReturnError()
OpenSSL.SSL.ZeroReturnError
2023-11-18 19:21:18,607 - INFO - SSL Connection closed!
2023-11-18 19:21:19,347 - INFO - Handshake was successful!
2023-11-18 19:21:19,367 - INFO - Master Key and IV were successfully sent.
2023-11-18 19:21:19,545 - INFO - Encryption process completed for source file: .\..\archive\2023\HP\UPR\HHE.D\HP.UPR..HHE.D.2023.322.
2023-11-18 19:21:19,546 - INFO - Total Size of Data and Chunk Size were successfully sent.
2023-11-18 19:21:19,546 - INFO - Encrypted data were sent successfully.
2023-11-18 19:21:19,685 - ERROR - TLS handshake error: 
Traceback (most recent call last):
  File "c:\Users\Marios Stefanidis\Documents\GitHub\Diploma-Thesis\code\slarchive-server\encryption\ssl_con.py", line 147, in run
    rejection_message = self.ssl_socket.recv(4096)
                        ^^^^^^^^^^^^^^^^^^^^^^^^^^
  File "C:\Users\Marios Stefanidis\AppData\Local\Programs\Python\Python311\Lib\site-packages\OpenSSL\SSL.py", line 2076, in recv
    self._raise_ssl_error(self._ssl, result)
  File "C:\Users\Marios Stefanidis\AppData\Local\Programs\Python\Python311\Lib\site-packages\OpenSSL\SSL.py", line 1814, in _raise_ssl_error
    raise ZeroReturnError()
OpenSSL.SSL.ZeroReturnError
2023-11-18 19:21:19,687 - INFO - SSL Connection closed!
2023-11-18 19:26:29,342 - INFO - Handshake was successful!
2023-11-18 19:26:29,358 - INFO - Master Key and IV were successfully sent.
2023-11-18 19:26:29,358 - ERROR - An error occurred: 'DataEncryption' object has no attribute 'configure_logging'
Traceback (most recent call last):
  File "c:\Users\Marios Stefanidis\Documents\GitHub\Diploma-Thesis\code\slarchive-server\encryption\ssl_con.py", line 144, in run
    self.send_encrypted_data()
  File "c:\Users\Marios Stefanidis\Documents\GitHub\Diploma-Thesis\code\slarchive-server\encryption\ssl_con.py", line 119, in send_encrypted_data
    encrypted_data = self.encrypt_data(master_key, init_value)
                     ^^^^^^^^^^^^^^^^^^^^^^^^^^^^^^^^^^^^^^^^^
  File "c:\Users\Marios Stefanidis\Documents\GitHub\Diploma-Thesis\code\slarchive-server\encryption\ssl_con.py", line 52, in encrypt_data
    script.configure_logging()
    ^^^^^^^^^^^^^^^^^^^^^^^^
AttributeError: 'DataEncryption' object has no attribute 'configure_logging'
2023-11-18 19:26:29,359 - INFO - SSL Connection closed!
2023-11-18 19:26:33,686 - ERROR - An error occurred: [WinError 10061] No connection could be made because the target machine actively refused it
Traceback (most recent call last):
  File "c:\Users\Marios Stefanidis\Documents\GitHub\Diploma-Thesis\code\slarchive-server\encryption\ssl_con.py", line 140, in run
    self.connect()
  File "c:\Users\Marios Stefanidis\Documents\GitHub\Diploma-Thesis\code\slarchive-server\encryption\ssl_con.py", line 26, in connect
    self.client_socket.connect(('127.0.0.1', 8443)) # Connect to the server
    ^^^^^^^^^^^^^^^^^^^^^^^^^^^^^^^^^^^^^^^^^^^^^^^
ConnectionRefusedError: [WinError 10061] No connection could be made because the target machine actively refused it
2023-11-18 19:26:33,688 - INFO - SSL Connection closed!
2023-11-18 19:26:36,379 - ERROR - An error occurred: [WinError 10061] No connection could be made because the target machine actively refused it
Traceback (most recent call last):
  File "c:\Users\Marios Stefanidis\Documents\GitHub\Diploma-Thesis\code\slarchive-server\encryption\ssl_con.py", line 140, in run
    self.connect()
  File "c:\Users\Marios Stefanidis\Documents\GitHub\Diploma-Thesis\code\slarchive-server\encryption\ssl_con.py", line 26, in connect
    self.client_socket.connect(('127.0.0.1', 8443)) # Connect to the server
    ^^^^^^^^^^^^^^^^^^^^^^^^^^^^^^^^^^^^^^^^^^^^^^^
ConnectionRefusedError: [WinError 10061] No connection could be made because the target machine actively refused it
2023-11-18 19:26:36,380 - INFO - SSL Connection closed!
2023-11-18 19:34:05,213 - INFO - Handshake was successful!
2023-11-18 19:34:05,228 - INFO - Master Key and IV were successfully sent.
2023-11-18 19:34:05,228 - ERROR - An error occurred: 'DataEncryption' object has no attribute 'configure_logging'
Traceback (most recent call last):
  File "c:\Users\Marios Stefanidis\Documents\GitHub\Diploma-Thesis\code\slarchive-server\encryption\ssl_con.py", line 144, in run
    self.send_encrypted_data()
  File "c:\Users\Marios Stefanidis\Documents\GitHub\Diploma-Thesis\code\slarchive-server\encryption\ssl_con.py", line 119, in send_encrypted_data
    encrypted_data = self.encrypt_data(master_key, init_value)
                     ^^^^^^^^^^^^^^^^^^^^^^^^^^^^^^^^^^^^^^^^^
  File "c:\Users\Marios Stefanidis\Documents\GitHub\Diploma-Thesis\code\slarchive-server\encryption\ssl_con.py", line 52, in encrypt_data
    script.configure_logging()
    ^^^^^^^^^^^^^^^^^^^^^^^^
AttributeError: 'DataEncryption' object has no attribute 'configure_logging'
2023-11-18 19:34:05,229 - INFO - SSL Connection closed!
2023-11-18 19:34:40,187 - ERROR - An error occurred: [WinError 10061] No connection could be made because the target machine actively refused it
Traceback (most recent call last):
  File "c:\Users\Marios Stefanidis\Documents\GitHub\Diploma-Thesis\code\slarchive-server\encryption\ssl_con.py", line 140, in run
    self.connect()
  File "c:\Users\Marios Stefanidis\Documents\GitHub\Diploma-Thesis\code\slarchive-server\encryption\ssl_con.py", line 26, in connect
    self.client_socket.connect(('127.0.0.1', 8443)) # Connect to the server
    ^^^^^^^^^^^^^^^^^^^^^^^^^^^^^^^^^^^^^^^^^^^^^^^
ConnectionRefusedError: [WinError 10061] No connection could be made because the target machine actively refused it
2023-11-18 19:34:40,189 - INFO - SSL Connection closed!
2023-11-18 19:34:43,531 - ERROR - An error occurred: [WinError 10061] No connection could be made because the target machine actively refused it
Traceback (most recent call last):
  File "c:\Users\Marios Stefanidis\Documents\GitHub\Diploma-Thesis\code\slarchive-server\encryption\ssl_con.py", line 140, in run
    self.connect()
  File "c:\Users\Marios Stefanidis\Documents\GitHub\Diploma-Thesis\code\slarchive-server\encryption\ssl_con.py", line 26, in connect
    self.client_socket.connect(('127.0.0.1', 8443)) # Connect to the server
    ^^^^^^^^^^^^^^^^^^^^^^^^^^^^^^^^^^^^^^^^^^^^^^^
ConnectionRefusedError: [WinError 10061] No connection could be made because the target machine actively refused it
2023-11-18 19:34:43,531 - INFO - SSL Connection closed!
2023-11-18 19:34:46,258 - ERROR - An error occurred: [WinError 10061] No connection could be made because the target machine actively refused it
Traceback (most recent call last):
  File "c:\Users\Marios Stefanidis\Documents\GitHub\Diploma-Thesis\code\slarchive-server\encryption\ssl_con.py", line 140, in run
    self.connect()
  File "c:\Users\Marios Stefanidis\Documents\GitHub\Diploma-Thesis\code\slarchive-server\encryption\ssl_con.py", line 26, in connect
    self.client_socket.connect(('127.0.0.1', 8443)) # Connect to the server
    ^^^^^^^^^^^^^^^^^^^^^^^^^^^^^^^^^^^^^^^^^^^^^^^
ConnectionRefusedError: [WinError 10061] No connection could be made because the target machine actively refused it
2023-11-18 19:34:46,259 - INFO - SSL Connection closed!
2023-11-18 19:41:16,318 - INFO - Handshake was successful!
2023-11-18 19:41:16,335 - INFO - Master Key and IV were successfully sent.
2023-11-18 19:41:16,518 - INFO - Total Size of Data and Chunk Size were successfully sent.
2023-11-18 19:41:16,518 - INFO - Encrypted data were sent successfully.
2023-11-18 19:41:16,724 - ERROR - TLS handshake error: 
Traceback (most recent call last):
  File "c:\Users\Marios Stefanidis\Documents\GitHub\Diploma-Thesis\code\slarchive-server\encryption\ssl_con.py", line 146, in run
    rejection_message = self.ssl_socket.recv(4096)
                        ^^^^^^^^^^^^^^^^^^^^^^^^^^
  File "C:\Users\Marios Stefanidis\AppData\Local\Programs\Python\Python311\Lib\site-packages\OpenSSL\SSL.py", line 2076, in recv
    self._raise_ssl_error(self._ssl, result)
  File "C:\Users\Marios Stefanidis\AppData\Local\Programs\Python\Python311\Lib\site-packages\OpenSSL\SSL.py", line 1814, in _raise_ssl_error
    raise ZeroReturnError()
OpenSSL.SSL.ZeroReturnError
2023-11-18 19:41:16,726 - INFO - SSL Connection closed!
2023-11-18 19:42:07,862 - INFO - Handshake was successful!
2023-11-18 19:42:07,879 - INFO - Master Key and IV were successfully sent.
2023-11-18 19:42:08,067 - INFO - Total Size of Data and Chunk Size were successfully sent.
2023-11-18 19:42:08,067 - INFO - Encrypted data were sent successfully.
2023-11-18 19:42:08,210 - ERROR - TLS handshake error: 
Traceback (most recent call last):
  File "c:\Users\Marios Stefanidis\Documents\GitHub\Diploma-Thesis\code\slarchive-server\encryption\ssl_con.py", line 146, in run
    rejection_message = self.ssl_socket.recv(4096)
                        ^^^^^^^^^^^^^^^^^^^^^^^^^^
  File "C:\Users\Marios Stefanidis\AppData\Local\Programs\Python\Python311\Lib\site-packages\OpenSSL\SSL.py", line 2076, in recv
    self._raise_ssl_error(self._ssl, result)
  File "C:\Users\Marios Stefanidis\AppData\Local\Programs\Python\Python311\Lib\site-packages\OpenSSL\SSL.py", line 1814, in _raise_ssl_error
    raise ZeroReturnError()
OpenSSL.SSL.ZeroReturnError
2023-11-18 19:42:08,212 - INFO - SSL Connection closed!
2023-11-18 19:43:00,564 - INFO - Handshake was successful!
2023-11-18 19:43:00,577 - INFO - Master Key and IV were successfully sent.
2023-11-18 19:43:00,757 - INFO - Total Size of Data and Chunk Size were successfully sent.
2023-11-18 19:43:00,757 - INFO - Encrypted data were sent successfully.
2023-11-18 19:43:00,894 - ERROR - TLS handshake error: 
Traceback (most recent call last):
  File "c:\Users\Marios Stefanidis\Documents\GitHub\Diploma-Thesis\code\slarchive-server\encryption\ssl_con.py", line 146, in run
    rejection_message = self.ssl_socket.recv(4096)
                        ^^^^^^^^^^^^^^^^^^^^^^^^^^
  File "C:\Users\Marios Stefanidis\AppData\Local\Programs\Python\Python311\Lib\site-packages\OpenSSL\SSL.py", line 2076, in recv
    self._raise_ssl_error(self._ssl, result)
  File "C:\Users\Marios Stefanidis\AppData\Local\Programs\Python\Python311\Lib\site-packages\OpenSSL\SSL.py", line 1814, in _raise_ssl_error
    raise ZeroReturnError()
OpenSSL.SSL.ZeroReturnError
2023-11-18 19:43:00,894 - INFO - SSL Connection closed!
2023-11-18 19:43:51,302 - INFO - Handshake was successful!
2023-11-18 19:43:51,318 - INFO - Master Key and IV were successfully sent.
2023-11-18 19:43:51,641 - INFO - Total Size of Data and Chunk Size were successfully sent.
2023-11-18 19:43:51,641 - INFO - Encrypted data were sent successfully.
2023-11-18 19:43:51,799 - ERROR - TLS handshake error: 
Traceback (most recent call last):
  File "c:\Users\Marios Stefanidis\Documents\GitHub\Diploma-Thesis\code\slarchive-server\encryption\ssl_con.py", line 146, in run
    rejection_message = self.ssl_socket.recv(4096)
                        ^^^^^^^^^^^^^^^^^^^^^^^^^^
  File "C:\Users\Marios Stefanidis\AppData\Local\Programs\Python\Python311\Lib\site-packages\OpenSSL\SSL.py", line 2076, in recv
    self._raise_ssl_error(self._ssl, result)
  File "C:\Users\Marios Stefanidis\AppData\Local\Programs\Python\Python311\Lib\site-packages\OpenSSL\SSL.py", line 1814, in _raise_ssl_error
    raise ZeroReturnError()
OpenSSL.SSL.ZeroReturnError
2023-11-18 19:43:51,802 - INFO - SSL Connection closed!
2023-11-18 19:45:54,001 - INFO - Handshake was successful!
2023-11-18 19:45:54,005 - INFO - Master Key and IV were successfully sent.
2023-11-18 19:45:54,263 - INFO - Total Size of Data and Chunk Size were successfully sent.
2023-11-18 19:45:54,264 - INFO - Encrypted data were sent successfully.
2023-11-18 19:45:54,427 - ERROR - TLS handshake error: 
Traceback (most recent call last):
  File "c:\Users\Marios Stefanidis\Documents\GitHub\Diploma-Thesis\code\slarchive-server\encryption\ssl_con.py", line 146, in run
    rejection_message = self.ssl_socket.recv(4096)
                        ^^^^^^^^^^^^^^^^^^^^^^^^^^
  File "C:\Users\Marios Stefanidis\AppData\Local\Programs\Python\Python311\Lib\site-packages\OpenSSL\SSL.py", line 2076, in recv
    self._raise_ssl_error(self._ssl, result)
  File "C:\Users\Marios Stefanidis\AppData\Local\Programs\Python\Python311\Lib\site-packages\OpenSSL\SSL.py", line 1814, in _raise_ssl_error
    raise ZeroReturnError()
OpenSSL.SSL.ZeroReturnError
2023-11-18 19:45:54,429 - INFO - SSL Connection closed!
2023-11-18 19:45:55,152 - INFO - Handshake was successful!
2023-11-18 19:45:55,167 - INFO - Master Key and IV were successfully sent.
2023-11-18 19:45:55,399 - INFO - Total Size of Data and Chunk Size were successfully sent.
2023-11-18 19:45:55,399 - INFO - Encrypted data were sent successfully.
2023-11-18 19:45:55,601 - ERROR - TLS handshake error: 
Traceback (most recent call last):
  File "c:\Users\Marios Stefanidis\Documents\GitHub\Diploma-Thesis\code\slarchive-server\encryption\ssl_con.py", line 146, in run
    rejection_message = self.ssl_socket.recv(4096)
                        ^^^^^^^^^^^^^^^^^^^^^^^^^^
  File "C:\Users\Marios Stefanidis\AppData\Local\Programs\Python\Python311\Lib\site-packages\OpenSSL\SSL.py", line 2076, in recv
    self._raise_ssl_error(self._ssl, result)
  File "C:\Users\Marios Stefanidis\AppData\Local\Programs\Python\Python311\Lib\site-packages\OpenSSL\SSL.py", line 1814, in _raise_ssl_error
    raise ZeroReturnError()
OpenSSL.SSL.ZeroReturnError
2023-11-18 19:45:55,605 - INFO - SSL Connection closed!
2023-11-18 19:46:07,053 - INFO - Handshake was successful!
2023-11-18 19:46:07,068 - INFO - Master Key and IV were successfully sent.
2023-11-18 19:46:07,298 - INFO - Total Size of Data and Chunk Size were successfully sent.
2023-11-18 19:46:07,314 - INFO - Encrypted data were sent successfully.
2023-11-18 19:46:07,481 - ERROR - TLS handshake error: 
Traceback (most recent call last):
  File "c:\Users\Marios Stefanidis\Documents\GitHub\Diploma-Thesis\code\slarchive-server\encryption\ssl_con.py", line 146, in run
    rejection_message = self.ssl_socket.recv(4096)
                        ^^^^^^^^^^^^^^^^^^^^^^^^^^
  File "C:\Users\Marios Stefanidis\AppData\Local\Programs\Python\Python311\Lib\site-packages\OpenSSL\SSL.py", line 2076, in recv
    self._raise_ssl_error(self._ssl, result)
  File "C:\Users\Marios Stefanidis\AppData\Local\Programs\Python\Python311\Lib\site-packages\OpenSSL\SSL.py", line 1814, in _raise_ssl_error
    raise ZeroReturnError()
OpenSSL.SSL.ZeroReturnError
2023-11-18 19:46:07,484 - INFO - SSL Connection closed!
2023-11-18 19:46:17,370 - INFO - Handshake was successful!
2023-11-18 19:46:17,389 - INFO - Master Key and IV were successfully sent.
2023-11-18 19:46:17,589 - INFO - Total Size of Data and Chunk Size were successfully sent.
2023-11-18 19:46:17,589 - INFO - Encrypted data were sent successfully.
2023-11-18 19:46:17,699 - ERROR - TLS handshake error: 
Traceback (most recent call last):
  File "c:\Users\Marios Stefanidis\Documents\GitHub\Diploma-Thesis\code\slarchive-server\encryption\ssl_con.py", line 146, in run
    rejection_message = self.ssl_socket.recv(4096)
                        ^^^^^^^^^^^^^^^^^^^^^^^^^^
  File "C:\Users\Marios Stefanidis\AppData\Local\Programs\Python\Python311\Lib\site-packages\OpenSSL\SSL.py", line 2076, in recv
    self._raise_ssl_error(self._ssl, result)
  File "C:\Users\Marios Stefanidis\AppData\Local\Programs\Python\Python311\Lib\site-packages\OpenSSL\SSL.py", line 1814, in _raise_ssl_error
    raise ZeroReturnError()
OpenSSL.SSL.ZeroReturnError
2023-11-18 19:46:17,702 - INFO - SSL Connection closed!
2023-11-28 21:50:47,864 - INFO - Handshake was successful!
2023-11-28 21:50:47,953 - INFO - Master Key and IV were successfully sent.
2023-11-28 21:50:48,225 - INFO - Total Size of Data and Chunk Size were successfully sent.
2023-11-28 21:50:48,225 - INFO - Encrypted data were sent successfully.
2023-11-28 21:50:48,513 - ERROR - TLS handshake error: 
Traceback (most recent call last):
  File "C:\Users\Marios Stefanidis\Documents\GitHub\Diploma-Thesis\code\slarchive-server\encryption\ssl_con.py", line 146, in run
    rejection_message = self.ssl_socket.recv(4096)
                        ^^^^^^^^^^^^^^^^^^^^^^^^^^
  File "C:\Users\Marios Stefanidis\AppData\Local\Programs\Python\Python311\Lib\site-packages\OpenSSL\SSL.py", line 2076, in recv
    self._raise_ssl_error(self._ssl, result)
  File "C:\Users\Marios Stefanidis\AppData\Local\Programs\Python\Python311\Lib\site-packages\OpenSSL\SSL.py", line 1814, in _raise_ssl_error
    raise ZeroReturnError()
OpenSSL.SSL.ZeroReturnError
2023-11-28 21:50:48,533 - INFO - SSL Connection closed!
2023-11-28 21:50:49,509 - INFO - Handshake was successful!
2023-11-28 21:50:49,524 - INFO - Master Key and IV were successfully sent.
2023-11-28 21:50:49,788 - INFO - Total Size of Data and Chunk Size were successfully sent.
2023-11-28 21:50:49,788 - INFO - Encrypted data were sent successfully.
2023-11-28 21:50:49,979 - ERROR - TLS handshake error: 
Traceback (most recent call last):
  File "C:\Users\Marios Stefanidis\Documents\GitHub\Diploma-Thesis\code\slarchive-server\encryption\ssl_con.py", line 146, in run
    rejection_message = self.ssl_socket.recv(4096)
                        ^^^^^^^^^^^^^^^^^^^^^^^^^^
  File "C:\Users\Marios Stefanidis\AppData\Local\Programs\Python\Python311\Lib\site-packages\OpenSSL\SSL.py", line 2076, in recv
    self._raise_ssl_error(self._ssl, result)
  File "C:\Users\Marios Stefanidis\AppData\Local\Programs\Python\Python311\Lib\site-packages\OpenSSL\SSL.py", line 1814, in _raise_ssl_error
    raise ZeroReturnError()
OpenSSL.SSL.ZeroReturnError
2023-11-28 21:50:49,979 - INFO - SSL Connection closed!
2023-11-28 21:50:50,865 - INFO - Handshake was successful!
2023-11-28 21:50:50,884 - INFO - Master Key and IV were successfully sent.
2023-11-28 21:50:51,145 - INFO - Total Size of Data and Chunk Size were successfully sent.
2023-11-28 21:50:51,145 - INFO - Encrypted data were sent successfully.
2023-11-28 21:50:51,296 - ERROR - TLS handshake error: 
Traceback (most recent call last):
  File "C:\Users\Marios Stefanidis\Documents\GitHub\Diploma-Thesis\code\slarchive-server\encryption\ssl_con.py", line 146, in run
    rejection_message = self.ssl_socket.recv(4096)
                        ^^^^^^^^^^^^^^^^^^^^^^^^^^
  File "C:\Users\Marios Stefanidis\AppData\Local\Programs\Python\Python311\Lib\site-packages\OpenSSL\SSL.py", line 2076, in recv
    self._raise_ssl_error(self._ssl, result)
  File "C:\Users\Marios Stefanidis\AppData\Local\Programs\Python\Python311\Lib\site-packages\OpenSSL\SSL.py", line 1814, in _raise_ssl_error
    raise ZeroReturnError()
OpenSSL.SSL.ZeroReturnError
2023-11-28 21:50:51,298 - INFO - SSL Connection closed!
2023-11-28 21:50:52,214 - INFO - Handshake was successful!
2023-11-28 21:50:52,227 - INFO - Master Key and IV were successfully sent.
2023-11-28 21:50:52,483 - INFO - Total Size of Data and Chunk Size were successfully sent.
2023-11-28 21:50:52,483 - INFO - Encrypted data were sent successfully.
2023-11-28 21:50:52,668 - ERROR - TLS handshake error: 
Traceback (most recent call last):
  File "C:\Users\Marios Stefanidis\Documents\GitHub\Diploma-Thesis\code\slarchive-server\encryption\ssl_con.py", line 146, in run
    rejection_message = self.ssl_socket.recv(4096)
                        ^^^^^^^^^^^^^^^^^^^^^^^^^^
  File "C:\Users\Marios Stefanidis\AppData\Local\Programs\Python\Python311\Lib\site-packages\OpenSSL\SSL.py", line 2076, in recv
    self._raise_ssl_error(self._ssl, result)
  File "C:\Users\Marios Stefanidis\AppData\Local\Programs\Python\Python311\Lib\site-packages\OpenSSL\SSL.py", line 1814, in _raise_ssl_error
    raise ZeroReturnError()
OpenSSL.SSL.ZeroReturnError
2023-11-28 21:50:52,670 - INFO - SSL Connection closed!
2023-11-28 21:50:53,602 - INFO - Handshake was successful!
2023-11-28 21:50:53,614 - INFO - Master Key and IV were successfully sent.
2023-11-28 21:50:53,903 - INFO - Total Size of Data and Chunk Size were successfully sent.
2023-11-28 21:50:53,903 - INFO - Encrypted data were sent successfully.
2023-11-28 21:50:54,074 - ERROR - TLS handshake error: 
Traceback (most recent call last):
  File "C:\Users\Marios Stefanidis\Documents\GitHub\Diploma-Thesis\code\slarchive-server\encryption\ssl_con.py", line 146, in run
    rejection_message = self.ssl_socket.recv(4096)
                        ^^^^^^^^^^^^^^^^^^^^^^^^^^
  File "C:\Users\Marios Stefanidis\AppData\Local\Programs\Python\Python311\Lib\site-packages\OpenSSL\SSL.py", line 2076, in recv
    self._raise_ssl_error(self._ssl, result)
  File "C:\Users\Marios Stefanidis\AppData\Local\Programs\Python\Python311\Lib\site-packages\OpenSSL\SSL.py", line 1814, in _raise_ssl_error
    raise ZeroReturnError()
OpenSSL.SSL.ZeroReturnError
2023-11-28 21:50:54,075 - INFO - SSL Connection closed!
2023-11-28 21:50:55,077 - INFO - Handshake was successful!
2023-11-28 21:50:55,103 - INFO - Master Key and IV were successfully sent.
2023-11-28 21:50:55,413 - INFO - Total Size of Data and Chunk Size were successfully sent.
2023-11-28 21:50:55,413 - INFO - Encrypted data were sent successfully.
2023-11-28 21:50:55,614 - ERROR - TLS handshake error: 
Traceback (most recent call last):
  File "C:\Users\Marios Stefanidis\Documents\GitHub\Diploma-Thesis\code\slarchive-server\encryption\ssl_con.py", line 146, in run
    rejection_message = self.ssl_socket.recv(4096)
                        ^^^^^^^^^^^^^^^^^^^^^^^^^^
  File "C:\Users\Marios Stefanidis\AppData\Local\Programs\Python\Python311\Lib\site-packages\OpenSSL\SSL.py", line 2076, in recv
    self._raise_ssl_error(self._ssl, result)
  File "C:\Users\Marios Stefanidis\AppData\Local\Programs\Python\Python311\Lib\site-packages\OpenSSL\SSL.py", line 1814, in _raise_ssl_error
    raise ZeroReturnError()
OpenSSL.SSL.ZeroReturnError
2023-11-28 21:50:55,614 - INFO - SSL Connection closed!
2023-11-28 21:50:56,543 - INFO - Handshake was successful!
2023-11-28 21:50:56,563 - INFO - Master Key and IV were successfully sent.
2023-11-28 21:50:56,903 - INFO - Total Size of Data and Chunk Size were successfully sent.
2023-11-28 21:50:56,905 - INFO - Encrypted data were sent successfully.
2023-11-28 21:50:57,094 - ERROR - TLS handshake error: 
Traceback (most recent call last):
  File "C:\Users\Marios Stefanidis\Documents\GitHub\Diploma-Thesis\code\slarchive-server\encryption\ssl_con.py", line 146, in run
    rejection_message = self.ssl_socket.recv(4096)
                        ^^^^^^^^^^^^^^^^^^^^^^^^^^
  File "C:\Users\Marios Stefanidis\AppData\Local\Programs\Python\Python311\Lib\site-packages\OpenSSL\SSL.py", line 2076, in recv
    self._raise_ssl_error(self._ssl, result)
  File "C:\Users\Marios Stefanidis\AppData\Local\Programs\Python\Python311\Lib\site-packages\OpenSSL\SSL.py", line 1814, in _raise_ssl_error
    raise ZeroReturnError()
OpenSSL.SSL.ZeroReturnError
2023-11-28 21:50:57,095 - INFO - SSL Connection closed!
2023-11-28 21:50:57,975 - INFO - Handshake was successful!
2023-11-28 21:50:57,993 - INFO - Master Key and IV were successfully sent.
2023-11-28 21:50:58,243 - INFO - Total Size of Data and Chunk Size were successfully sent.
2023-11-28 21:50:58,243 - INFO - Encrypted data were sent successfully.
2023-11-28 21:50:58,404 - ERROR - TLS handshake error: 
Traceback (most recent call last):
  File "C:\Users\Marios Stefanidis\Documents\GitHub\Diploma-Thesis\code\slarchive-server\encryption\ssl_con.py", line 146, in run
    rejection_message = self.ssl_socket.recv(4096)
                        ^^^^^^^^^^^^^^^^^^^^^^^^^^
  File "C:\Users\Marios Stefanidis\AppData\Local\Programs\Python\Python311\Lib\site-packages\OpenSSL\SSL.py", line 2076, in recv
    self._raise_ssl_error(self._ssl, result)
  File "C:\Users\Marios Stefanidis\AppData\Local\Programs\Python\Python311\Lib\site-packages\OpenSSL\SSL.py", line 1814, in _raise_ssl_error
    raise ZeroReturnError()
OpenSSL.SSL.ZeroReturnError
2023-11-28 21:50:58,408 - INFO - SSL Connection closed!
