2023-11-12 13:07:46,163 - ERROR - TLS handshake error: (10053, 'WSAECONNABORTED')
Traceback (most recent call last):
  File "C:\Users\Marios Stefanidis\Documents\GitHub\Diploma-Thesis\code\slarchive-server\encryption\ssl_con.py", line 147, in run
    self.establish_ssl_connection()
  File "C:\Users\Marios Stefanidis\Documents\GitHub\Diploma-Thesis\code\slarchive-server\encryption\ssl_con.py", line 38, in establish_ssl_connection
    self.ssl_socket.do_handshake()
  File "C:\Users\Marios Stefanidis\AppData\Local\Programs\Python\Python311\Lib\site-packages\OpenSSL\SSL.py", line 2202, in do_handshake
    self._raise_ssl_error(self._ssl, result)
  File "C:\Users\Marios Stefanidis\AppData\Local\Programs\Python\Python311\Lib\site-packages\OpenSSL\SSL.py", line 1827, in _raise_ssl_error
    raise SysCallError(errno, errorcode.get(errno))
OpenSSL.SSL.SysCallError: (10053, 'WSAECONNABORTED')
2023-11-12 13:07:46,739 - ERROR - TLS handshake error: (10053, 'WSAECONNABORTED')
Traceback (most recent call last):
  File "C:\Users\Marios Stefanidis\Documents\GitHub\Diploma-Thesis\code\slarchive-server\encryption\ssl_con.py", line 147, in run
    self.establish_ssl_connection()
  File "C:\Users\Marios Stefanidis\Documents\GitHub\Diploma-Thesis\code\slarchive-server\encryption\ssl_con.py", line 38, in establish_ssl_connection
    self.ssl_socket.do_handshake()
  File "C:\Users\Marios Stefanidis\AppData\Local\Programs\Python\Python311\Lib\site-packages\OpenSSL\SSL.py", line 2202, in do_handshake
    self._raise_ssl_error(self._ssl, result)
  File "C:\Users\Marios Stefanidis\AppData\Local\Programs\Python\Python311\Lib\site-packages\OpenSSL\SSL.py", line 1827, in _raise_ssl_error
    raise SysCallError(errno, errorcode.get(errno))
OpenSSL.SSL.SysCallError: (10053, 'WSAECONNABORTED')
2023-11-12 13:08:32,976 - ERROR - TLS handshake error: (10053, 'WSAECONNABORTED')
Traceback (most recent call last):
  File "C:\Users\Marios Stefanidis\Documents\GitHub\Diploma-Thesis\code\slarchive-server\encryption\ssl_con.py", line 147, in run
    self.establish_ssl_connection()
  File "C:\Users\Marios Stefanidis\Documents\GitHub\Diploma-Thesis\code\slarchive-server\encryption\ssl_con.py", line 38, in establish_ssl_connection
    self.ssl_socket.do_handshake()
  File "C:\Users\Marios Stefanidis\AppData\Local\Programs\Python\Python311\Lib\site-packages\OpenSSL\SSL.py", line 2202, in do_handshake
    self._raise_ssl_error(self._ssl, result)
  File "C:\Users\Marios Stefanidis\AppData\Local\Programs\Python\Python311\Lib\site-packages\OpenSSL\SSL.py", line 1827, in _raise_ssl_error
    raise SysCallError(errno, errorcode.get(errno))
OpenSSL.SSL.SysCallError: (10053, 'WSAECONNABORTED')
2023-11-12 13:08:33,548 - ERROR - TLS handshake error: (10053, 'WSAECONNABORTED')
Traceback (most recent call last):
  File "C:\Users\Marios Stefanidis\Documents\GitHub\Diploma-Thesis\code\slarchive-server\encryption\ssl_con.py", line 147, in run
    self.establish_ssl_connection()
  File "C:\Users\Marios Stefanidis\Documents\GitHub\Diploma-Thesis\code\slarchive-server\encryption\ssl_con.py", line 38, in establish_ssl_connection
    self.ssl_socket.do_handshake()
  File "C:\Users\Marios Stefanidis\AppData\Local\Programs\Python\Python311\Lib\site-packages\OpenSSL\SSL.py", line 2202, in do_handshake
    self._raise_ssl_error(self._ssl, result)
  File "C:\Users\Marios Stefanidis\AppData\Local\Programs\Python\Python311\Lib\site-packages\OpenSSL\SSL.py", line 1827, in _raise_ssl_error
    raise SysCallError(errno, errorcode.get(errno))
OpenSSL.SSL.SysCallError: (10053, 'WSAECONNABORTED')
2023-11-12 13:09:32,608 - ERROR - TLS handshake error: (10053, 'WSAECONNABORTED')
Traceback (most recent call last):
  File "C:\Users\Marios Stefanidis\Documents\GitHub\Diploma-Thesis\code\slarchive-server\encryption\ssl_con.py", line 147, in run
    self.establish_ssl_connection()
  File "C:\Users\Marios Stefanidis\Documents\GitHub\Diploma-Thesis\code\slarchive-server\encryption\ssl_con.py", line 38, in establish_ssl_connection
    self.ssl_socket.do_handshake()
  File "C:\Users\Marios Stefanidis\AppData\Local\Programs\Python\Python311\Lib\site-packages\OpenSSL\SSL.py", line 2202, in do_handshake
    self._raise_ssl_error(self._ssl, result)
  File "C:\Users\Marios Stefanidis\AppData\Local\Programs\Python\Python311\Lib\site-packages\OpenSSL\SSL.py", line 1827, in _raise_ssl_error
    raise SysCallError(errno, errorcode.get(errno))
OpenSSL.SSL.SysCallError: (10053, 'WSAECONNABORTED')
2023-11-12 13:09:33,210 - ERROR - TLS handshake error: (10053, 'WSAECONNABORTED')
Traceback (most recent call last):
  File "C:\Users\Marios Stefanidis\Documents\GitHub\Diploma-Thesis\code\slarchive-server\encryption\ssl_con.py", line 147, in run
    self.establish_ssl_connection()
  File "C:\Users\Marios Stefanidis\Documents\GitHub\Diploma-Thesis\code\slarchive-server\encryption\ssl_con.py", line 38, in establish_ssl_connection
    self.ssl_socket.do_handshake()
  File "C:\Users\Marios Stefanidis\AppData\Local\Programs\Python\Python311\Lib\site-packages\OpenSSL\SSL.py", line 2202, in do_handshake
    self._raise_ssl_error(self._ssl, result)
  File "C:\Users\Marios Stefanidis\AppData\Local\Programs\Python\Python311\Lib\site-packages\OpenSSL\SSL.py", line 1827, in _raise_ssl_error
    raise SysCallError(errno, errorcode.get(errno))
OpenSSL.SSL.SysCallError: (10053, 'WSAECONNABORTED')
2023-11-12 13:10:19,493 - ERROR - TLS handshake error: (10053, 'WSAECONNABORTED')
Traceback (most recent call last):
  File "C:\Users\Marios Stefanidis\Documents\GitHub\Diploma-Thesis\code\slarchive-server\encryption\ssl_con.py", line 147, in run
    self.establish_ssl_connection()
  File "C:\Users\Marios Stefanidis\Documents\GitHub\Diploma-Thesis\code\slarchive-server\encryption\ssl_con.py", line 38, in establish_ssl_connection
    self.ssl_socket.do_handshake()
  File "C:\Users\Marios Stefanidis\AppData\Local\Programs\Python\Python311\Lib\site-packages\OpenSSL\SSL.py", line 2202, in do_handshake
    self._raise_ssl_error(self._ssl, result)
  File "C:\Users\Marios Stefanidis\AppData\Local\Programs\Python\Python311\Lib\site-packages\OpenSSL\SSL.py", line 1827, in _raise_ssl_error
    raise SysCallError(errno, errorcode.get(errno))
OpenSSL.SSL.SysCallError: (10053, 'WSAECONNABORTED')
2023-11-12 13:10:20,076 - ERROR - TLS handshake error: (10053, 'WSAECONNABORTED')
Traceback (most recent call last):
  File "C:\Users\Marios Stefanidis\Documents\GitHub\Diploma-Thesis\code\slarchive-server\encryption\ssl_con.py", line 147, in run
    self.establish_ssl_connection()
  File "C:\Users\Marios Stefanidis\Documents\GitHub\Diploma-Thesis\code\slarchive-server\encryption\ssl_con.py", line 38, in establish_ssl_connection
    self.ssl_socket.do_handshake()
  File "C:\Users\Marios Stefanidis\AppData\Local\Programs\Python\Python311\Lib\site-packages\OpenSSL\SSL.py", line 2202, in do_handshake
    self._raise_ssl_error(self._ssl, result)
  File "C:\Users\Marios Stefanidis\AppData\Local\Programs\Python\Python311\Lib\site-packages\OpenSSL\SSL.py", line 1827, in _raise_ssl_error
    raise SysCallError(errno, errorcode.get(errno))
OpenSSL.SSL.SysCallError: (10053, 'WSAECONNABORTED')
2023-11-12 13:10:54,481 - ERROR - TLS handshake error: (10053, 'WSAECONNABORTED')
Traceback (most recent call last):
  File "C:\Users\Marios Stefanidis\Documents\GitHub\Diploma-Thesis\code\slarchive-server\encryption\ssl_con.py", line 147, in run
    self.establish_ssl_connection()
  File "C:\Users\Marios Stefanidis\Documents\GitHub\Diploma-Thesis\code\slarchive-server\encryption\ssl_con.py", line 38, in establish_ssl_connection
    self.ssl_socket.do_handshake()
  File "C:\Users\Marios Stefanidis\AppData\Local\Programs\Python\Python311\Lib\site-packages\OpenSSL\SSL.py", line 2202, in do_handshake
    self._raise_ssl_error(self._ssl, result)
  File "C:\Users\Marios Stefanidis\AppData\Local\Programs\Python\Python311\Lib\site-packages\OpenSSL\SSL.py", line 1827, in _raise_ssl_error
    raise SysCallError(errno, errorcode.get(errno))
OpenSSL.SSL.SysCallError: (10053, 'WSAECONNABORTED')
2023-11-12 13:10:55,064 - ERROR - TLS handshake error: (10053, 'WSAECONNABORTED')
Traceback (most recent call last):
  File "C:\Users\Marios Stefanidis\Documents\GitHub\Diploma-Thesis\code\slarchive-server\encryption\ssl_con.py", line 147, in run
    self.establish_ssl_connection()
  File "C:\Users\Marios Stefanidis\Documents\GitHub\Diploma-Thesis\code\slarchive-server\encryption\ssl_con.py", line 38, in establish_ssl_connection
    self.ssl_socket.do_handshake()
  File "C:\Users\Marios Stefanidis\AppData\Local\Programs\Python\Python311\Lib\site-packages\OpenSSL\SSL.py", line 2202, in do_handshake
    self._raise_ssl_error(self._ssl, result)
  File "C:\Users\Marios Stefanidis\AppData\Local\Programs\Python\Python311\Lib\site-packages\OpenSSL\SSL.py", line 1827, in _raise_ssl_error
    raise SysCallError(errno, errorcode.get(errno))
OpenSSL.SSL.SysCallError: (10053, 'WSAECONNABORTED')
2023-11-12 13:13:04,536 - INFO - Handshake was successful!
2023-11-12 13:13:04,548 - INFO - Master Key and IV were successfully sent.
2023-11-12 13:13:04,742 - INFO - Encryption process completed for source file: .\..\archive\2023\ZW\ITSC\EHE.D\ZW.ITSC.00.EHN.D.2023.295.
2023-11-12 13:13:04,742 - INFO - Total Size of Data and Chunk Size were successfully sent.
2023-11-12 13:13:04,742 - INFO - Encrypted data were sent successfully.
2023-11-12 13:13:04,742 - INFO - Filename encrypted and sent successfully.
2023-11-12 13:13:04,979 - ERROR - TLS handshake error: 
Traceback (most recent call last):
  File "C:\Users\Marios Stefanidis\Documents\GitHub\Diploma-Thesis\code\slarchive-server\encryption\ssl_con.py", line 153, in run
    rejection_message = self.ssl_socket.recv(4096)
                        ^^^^^^^^^^^^^^^^^^^^^^^^^^
  File "C:\Users\Marios Stefanidis\AppData\Local\Programs\Python\Python311\Lib\site-packages\OpenSSL\SSL.py", line 2076, in recv
    self._raise_ssl_error(self._ssl, result)
  File "C:\Users\Marios Stefanidis\AppData\Local\Programs\Python\Python311\Lib\site-packages\OpenSSL\SSL.py", line 1814, in _raise_ssl_error
    raise ZeroReturnError()
OpenSSL.SSL.ZeroReturnError
2023-11-12 13:13:04,982 - INFO - SLL Connection closed!
2023-11-12 13:13:05,598 - INFO - Handshake was successful!
2023-11-12 13:13:05,612 - INFO - Master Key and IV were successfully sent.
2023-11-12 13:13:05,831 - INFO - Encryption process completed for source file: .\..\archive\2023\ZW\ITSC\EHE.D\ZW.ITSC.00.EHN.D.2023.295.
2023-11-12 13:13:05,837 - INFO - Total Size of Data and Chunk Size were successfully sent.
2023-11-12 13:13:05,837 - INFO - Encrypted data were sent successfully.
2023-11-12 13:13:05,838 - INFO - Filename encrypted and sent successfully.
2023-11-12 13:13:06,007 - ERROR - TLS handshake error: 
Traceback (most recent call last):
  File "C:\Users\Marios Stefanidis\Documents\GitHub\Diploma-Thesis\code\slarchive-server\encryption\ssl_con.py", line 153, in run
    rejection_message = self.ssl_socket.recv(4096)
                        ^^^^^^^^^^^^^^^^^^^^^^^^^^
  File "C:\Users\Marios Stefanidis\AppData\Local\Programs\Python\Python311\Lib\site-packages\OpenSSL\SSL.py", line 2076, in recv
    self._raise_ssl_error(self._ssl, result)
  File "C:\Users\Marios Stefanidis\AppData\Local\Programs\Python\Python311\Lib\site-packages\OpenSSL\SSL.py", line 1814, in _raise_ssl_error
    raise ZeroReturnError()
OpenSSL.SSL.ZeroReturnError
2023-11-12 13:13:06,007 - INFO - SLL Connection closed!
2023-11-12 13:21:55,647 - ERROR - TLS handshake error: (10053, 'WSAECONNABORTED')
Traceback (most recent call last):
  File "C:\Users\Marios Stefanidis\Documents\GitHub\Diploma-Thesis\code\slarchive-server\encryption\ssl_con.py", line 147, in run
    self.establish_ssl_connection()
  File "C:\Users\Marios Stefanidis\Documents\GitHub\Diploma-Thesis\code\slarchive-server\encryption\ssl_con.py", line 38, in establish_ssl_connection
    self.ssl_socket.do_handshake()
  File "C:\Users\Marios Stefanidis\AppData\Local\Programs\Python\Python311\Lib\site-packages\OpenSSL\SSL.py", line 2202, in do_handshake
    self._raise_ssl_error(self._ssl, result)
  File "C:\Users\Marios Stefanidis\AppData\Local\Programs\Python\Python311\Lib\site-packages\OpenSSL\SSL.py", line 1827, in _raise_ssl_error
    raise SysCallError(errno, errorcode.get(errno))
OpenSSL.SSL.SysCallError: (10053, 'WSAECONNABORTED')
2023-11-12 13:21:56,217 - ERROR - TLS handshake error: (10053, 'WSAECONNABORTED')
Traceback (most recent call last):
  File "C:\Users\Marios Stefanidis\Documents\GitHub\Diploma-Thesis\code\slarchive-server\encryption\ssl_con.py", line 147, in run
    self.establish_ssl_connection()
  File "C:\Users\Marios Stefanidis\Documents\GitHub\Diploma-Thesis\code\slarchive-server\encryption\ssl_con.py", line 38, in establish_ssl_connection
    self.ssl_socket.do_handshake()
  File "C:\Users\Marios Stefanidis\AppData\Local\Programs\Python\Python311\Lib\site-packages\OpenSSL\SSL.py", line 2202, in do_handshake
    self._raise_ssl_error(self._ssl, result)
  File "C:\Users\Marios Stefanidis\AppData\Local\Programs\Python\Python311\Lib\site-packages\OpenSSL\SSL.py", line 1827, in _raise_ssl_error
    raise SysCallError(errno, errorcode.get(errno))
OpenSSL.SSL.SysCallError: (10053, 'WSAECONNABORTED')
2023-11-12 13:23:32,008 - ERROR - TLS handshake error: (10053, 'WSAECONNABORTED')
Traceback (most recent call last):
  File "C:\Users\Marios Stefanidis\Documents\GitHub\Diploma-Thesis\code\slarchive-server\encryption\ssl_con.py", line 147, in run
    self.establish_ssl_connection()
  File "C:\Users\Marios Stefanidis\Documents\GitHub\Diploma-Thesis\code\slarchive-server\encryption\ssl_con.py", line 38, in establish_ssl_connection
    self.ssl_socket.do_handshake()
  File "C:\Users\Marios Stefanidis\AppData\Local\Programs\Python\Python311\Lib\site-packages\OpenSSL\SSL.py", line 2202, in do_handshake
    self._raise_ssl_error(self._ssl, result)
  File "C:\Users\Marios Stefanidis\AppData\Local\Programs\Python\Python311\Lib\site-packages\OpenSSL\SSL.py", line 1827, in _raise_ssl_error
    raise SysCallError(errno, errorcode.get(errno))
OpenSSL.SSL.SysCallError: (10053, 'WSAECONNABORTED')
2023-11-12 13:23:32,581 - ERROR - TLS handshake error: (10053, 'WSAECONNABORTED')
Traceback (most recent call last):
  File "C:\Users\Marios Stefanidis\Documents\GitHub\Diploma-Thesis\code\slarchive-server\encryption\ssl_con.py", line 147, in run
    self.establish_ssl_connection()
  File "C:\Users\Marios Stefanidis\Documents\GitHub\Diploma-Thesis\code\slarchive-server\encryption\ssl_con.py", line 38, in establish_ssl_connection
    self.ssl_socket.do_handshake()
  File "C:\Users\Marios Stefanidis\AppData\Local\Programs\Python\Python311\Lib\site-packages\OpenSSL\SSL.py", line 2202, in do_handshake
    self._raise_ssl_error(self._ssl, result)
  File "C:\Users\Marios Stefanidis\AppData\Local\Programs\Python\Python311\Lib\site-packages\OpenSSL\SSL.py", line 1827, in _raise_ssl_error
    raise SysCallError(errno, errorcode.get(errno))
OpenSSL.SSL.SysCallError: (10053, 'WSAECONNABORTED')
2023-11-12 13:24:35,491 - ERROR - TLS handshake error: (10053, 'WSAECONNABORTED')
Traceback (most recent call last):
  File "C:\Users\Marios Stefanidis\Documents\GitHub\Diploma-Thesis\code\slarchive-server\encryption\ssl_con.py", line 147, in run
    self.establish_ssl_connection()
  File "C:\Users\Marios Stefanidis\Documents\GitHub\Diploma-Thesis\code\slarchive-server\encryption\ssl_con.py", line 38, in establish_ssl_connection
    self.ssl_socket.do_handshake()
  File "C:\Users\Marios Stefanidis\AppData\Local\Programs\Python\Python311\Lib\site-packages\OpenSSL\SSL.py", line 2202, in do_handshake
    self._raise_ssl_error(self._ssl, result)
  File "C:\Users\Marios Stefanidis\AppData\Local\Programs\Python\Python311\Lib\site-packages\OpenSSL\SSL.py", line 1827, in _raise_ssl_error
    raise SysCallError(errno, errorcode.get(errno))
OpenSSL.SSL.SysCallError: (10053, 'WSAECONNABORTED')
2023-11-12 13:24:35,492 - ERROR - Error during SSL socket shutdown: [('SSL routines', '', 'shutdown while in init')]
Traceback (most recent call last):
  File "C:\Users\Marios Stefanidis\Documents\GitHub\Diploma-Thesis\code\slarchive-server\encryption\ssl_con.py", line 169, in close
    self.ssl_socket.shutdown()
  File "C:\Users\Marios Stefanidis\AppData\Local\Programs\Python\Python311\Lib\site-packages\OpenSSL\SSL.py", line 2345, in shutdown
    self._raise_ssl_error(self._ssl, result)
  File "C:\Users\Marios Stefanidis\AppData\Local\Programs\Python\Python311\Lib\site-packages\OpenSSL\SSL.py", line 1843, in _raise_ssl_error
    _openssl_assert(
  File "C:\Users\Marios Stefanidis\AppData\Local\Programs\Python\Python311\Lib\site-packages\OpenSSL\_util.py", line 71, in openssl_assert
    exception_from_error_queue(error)
  File "C:\Users\Marios Stefanidis\AppData\Local\Programs\Python\Python311\Lib\site-packages\OpenSSL\_util.py", line 57, in exception_from_error_queue
    raise exception_type(errors)
OpenSSL.SSL.Error: [('SSL routines', '', 'shutdown while in init')]
2023-11-12 13:24:36,057 - ERROR - TLS handshake error: (10053, 'WSAECONNABORTED')
Traceback (most recent call last):
  File "C:\Users\Marios Stefanidis\Documents\GitHub\Diploma-Thesis\code\slarchive-server\encryption\ssl_con.py", line 147, in run
    self.establish_ssl_connection()
  File "C:\Users\Marios Stefanidis\Documents\GitHub\Diploma-Thesis\code\slarchive-server\encryption\ssl_con.py", line 38, in establish_ssl_connection
    self.ssl_socket.do_handshake()
  File "C:\Users\Marios Stefanidis\AppData\Local\Programs\Python\Python311\Lib\site-packages\OpenSSL\SSL.py", line 2202, in do_handshake
    self._raise_ssl_error(self._ssl, result)
  File "C:\Users\Marios Stefanidis\AppData\Local\Programs\Python\Python311\Lib\site-packages\OpenSSL\SSL.py", line 1827, in _raise_ssl_error
    raise SysCallError(errno, errorcode.get(errno))
OpenSSL.SSL.SysCallError: (10053, 'WSAECONNABORTED')
2023-11-12 13:24:36,057 - ERROR - Error during SSL socket shutdown: [('SSL routines', '', 'shutdown while in init')]
Traceback (most recent call last):
  File "C:\Users\Marios Stefanidis\Documents\GitHub\Diploma-Thesis\code\slarchive-server\encryption\ssl_con.py", line 169, in close
    self.ssl_socket.shutdown()
  File "C:\Users\Marios Stefanidis\AppData\Local\Programs\Python\Python311\Lib\site-packages\OpenSSL\SSL.py", line 2345, in shutdown
    self._raise_ssl_error(self._ssl, result)
  File "C:\Users\Marios Stefanidis\AppData\Local\Programs\Python\Python311\Lib\site-packages\OpenSSL\SSL.py", line 1843, in _raise_ssl_error
    _openssl_assert(
  File "C:\Users\Marios Stefanidis\AppData\Local\Programs\Python\Python311\Lib\site-packages\OpenSSL\_util.py", line 71, in openssl_assert
    exception_from_error_queue(error)
  File "C:\Users\Marios Stefanidis\AppData\Local\Programs\Python\Python311\Lib\site-packages\OpenSSL\_util.py", line 57, in exception_from_error_queue
    raise exception_type(errors)
OpenSSL.SSL.Error: [('SSL routines', '', 'shutdown while in init')]
2023-11-12 13:26:15,783 - ERROR - TLS handshake error: (10053, 'WSAECONNABORTED')
Traceback (most recent call last):
  File "C:\Users\Marios Stefanidis\Documents\GitHub\Diploma-Thesis\code\slarchive-server\encryption\ssl_con.py", line 147, in run
    self.establish_ssl_connection()
  File "C:\Users\Marios Stefanidis\Documents\GitHub\Diploma-Thesis\code\slarchive-server\encryption\ssl_con.py", line 38, in establish_ssl_connection
    self.ssl_socket.do_handshake()
  File "C:\Users\Marios Stefanidis\AppData\Local\Programs\Python\Python311\Lib\site-packages\OpenSSL\SSL.py", line 2202, in do_handshake
    self._raise_ssl_error(self._ssl, result)
  File "C:\Users\Marios Stefanidis\AppData\Local\Programs\Python\Python311\Lib\site-packages\OpenSSL\SSL.py", line 1827, in _raise_ssl_error
    raise SysCallError(errno, errorcode.get(errno))
OpenSSL.SSL.SysCallError: (10053, 'WSAECONNABORTED')
2023-11-12 13:26:16,344 - ERROR - TLS handshake error: (10053, 'WSAECONNABORTED')
Traceback (most recent call last):
  File "C:\Users\Marios Stefanidis\Documents\GitHub\Diploma-Thesis\code\slarchive-server\encryption\ssl_con.py", line 147, in run
    self.establish_ssl_connection()
  File "C:\Users\Marios Stefanidis\Documents\GitHub\Diploma-Thesis\code\slarchive-server\encryption\ssl_con.py", line 38, in establish_ssl_connection
    self.ssl_socket.do_handshake()
  File "C:\Users\Marios Stefanidis\AppData\Local\Programs\Python\Python311\Lib\site-packages\OpenSSL\SSL.py", line 2202, in do_handshake
    self._raise_ssl_error(self._ssl, result)
  File "C:\Users\Marios Stefanidis\AppData\Local\Programs\Python\Python311\Lib\site-packages\OpenSSL\SSL.py", line 1827, in _raise_ssl_error
    raise SysCallError(errno, errorcode.get(errno))
OpenSSL.SSL.SysCallError: (10053, 'WSAECONNABORTED')
2023-11-12 13:27:44,068 - ERROR - TLS handshake error: (10053, 'WSAECONNABORTED')
Traceback (most recent call last):
  File "C:\Users\Marios Stefanidis\Documents\GitHub\Diploma-Thesis\code\slarchive-server\encryption\ssl_con.py", line 147, in run
    self.establish_ssl_connection()
  File "C:\Users\Marios Stefanidis\Documents\GitHub\Diploma-Thesis\code\slarchive-server\encryption\ssl_con.py", line 38, in establish_ssl_connection
    self.ssl_socket.do_handshake()
  File "C:\Users\Marios Stefanidis\AppData\Local\Programs\Python\Python311\Lib\site-packages\OpenSSL\SSL.py", line 2202, in do_handshake
    self._raise_ssl_error(self._ssl, result)
  File "C:\Users\Marios Stefanidis\AppData\Local\Programs\Python\Python311\Lib\site-packages\OpenSSL\SSL.py", line 1827, in _raise_ssl_error
    raise SysCallError(errno, errorcode.get(errno))
OpenSSL.SSL.SysCallError: (10053, 'WSAECONNABORTED')
2023-11-12 13:27:44,068 - INFO - SSL Connection closed!
2023-11-12 13:27:44,621 - ERROR - TLS handshake error: (10053, 'WSAECONNABORTED')
Traceback (most recent call last):
  File "C:\Users\Marios Stefanidis\Documents\GitHub\Diploma-Thesis\code\slarchive-server\encryption\ssl_con.py", line 147, in run
    self.establish_ssl_connection()
  File "C:\Users\Marios Stefanidis\Documents\GitHub\Diploma-Thesis\code\slarchive-server\encryption\ssl_con.py", line 38, in establish_ssl_connection
    self.ssl_socket.do_handshake()
  File "C:\Users\Marios Stefanidis\AppData\Local\Programs\Python\Python311\Lib\site-packages\OpenSSL\SSL.py", line 2202, in do_handshake
    self._raise_ssl_error(self._ssl, result)
  File "C:\Users\Marios Stefanidis\AppData\Local\Programs\Python\Python311\Lib\site-packages\OpenSSL\SSL.py", line 1827, in _raise_ssl_error
    raise SysCallError(errno, errorcode.get(errno))
OpenSSL.SSL.SysCallError: (10053, 'WSAECONNABORTED')
2023-11-12 13:27:44,621 - INFO - SSL Connection closed!
2023-11-12 13:38:32,680 - ERROR - TLS handshake error: (10053, 'WSAECONNABORTED')
Traceback (most recent call last):
  File "C:\Users\Marios Stefanidis\Documents\GitHub\Diploma-Thesis\code\slarchive-server\encryption\ssl_con.py", line 147, in run
    self.establish_ssl_connection()
  File "C:\Users\Marios Stefanidis\Documents\GitHub\Diploma-Thesis\code\slarchive-server\encryption\ssl_con.py", line 38, in establish_ssl_connection
    self.ssl_socket.do_handshake()
  File "C:\Users\Marios Stefanidis\AppData\Local\Programs\Python\Python311\Lib\site-packages\OpenSSL\SSL.py", line 2202, in do_handshake
    self._raise_ssl_error(self._ssl, result)
  File "C:\Users\Marios Stefanidis\AppData\Local\Programs\Python\Python311\Lib\site-packages\OpenSSL\SSL.py", line 1827, in _raise_ssl_error
    raise SysCallError(errno, errorcode.get(errno))
OpenSSL.SSL.SysCallError: (10053, 'WSAECONNABORTED')
2023-11-12 13:38:32,681 - INFO - SSL Connection closed!
2023-11-12 13:38:33,267 - ERROR - TLS handshake error: (10053, 'WSAECONNABORTED')
Traceback (most recent call last):
  File "C:\Users\Marios Stefanidis\Documents\GitHub\Diploma-Thesis\code\slarchive-server\encryption\ssl_con.py", line 147, in run
    self.establish_ssl_connection()
  File "C:\Users\Marios Stefanidis\Documents\GitHub\Diploma-Thesis\code\slarchive-server\encryption\ssl_con.py", line 38, in establish_ssl_connection
    self.ssl_socket.do_handshake()
  File "C:\Users\Marios Stefanidis\AppData\Local\Programs\Python\Python311\Lib\site-packages\OpenSSL\SSL.py", line 2202, in do_handshake
    self._raise_ssl_error(self._ssl, result)
  File "C:\Users\Marios Stefanidis\AppData\Local\Programs\Python\Python311\Lib\site-packages\OpenSSL\SSL.py", line 1827, in _raise_ssl_error
    raise SysCallError(errno, errorcode.get(errno))
OpenSSL.SSL.SysCallError: (10053, 'WSAECONNABORTED')
2023-11-12 13:38:33,267 - INFO - SSL Connection closed!
2023-11-12 13:39:19,883 - INFO - Handshake was successful!
2023-11-12 13:39:19,894 - INFO - Master Key and IV were successfully sent.
2023-11-12 13:39:20,100 - INFO - Encryption process completed for source file: .\..\archive\2023\ZW\ITSC\EHE.D\ZW.ITSC.00.EHN.D.2023.295.
2023-11-12 13:39:20,102 - INFO - Total Size of Data and Chunk Size were successfully sent.
2023-11-12 13:39:20,102 - INFO - Encrypted data were sent successfully.
2023-11-12 13:39:20,103 - INFO - Filename encrypted and sent successfully.
2023-11-12 13:39:20,337 - ERROR - TLS handshake error: 
Traceback (most recent call last):
  File "C:\Users\Marios Stefanidis\Documents\GitHub\Diploma-Thesis\code\slarchive-server\encryption\ssl_con.py", line 153, in run
    rejection_message = self.ssl_socket.recv(4096)
                        ^^^^^^^^^^^^^^^^^^^^^^^^^^
  File "C:\Users\Marios Stefanidis\AppData\Local\Programs\Python\Python311\Lib\site-packages\OpenSSL\SSL.py", line 2076, in recv
    self._raise_ssl_error(self._ssl, result)
  File "C:\Users\Marios Stefanidis\AppData\Local\Programs\Python\Python311\Lib\site-packages\OpenSSL\SSL.py", line 1814, in _raise_ssl_error
    raise ZeroReturnError()
OpenSSL.SSL.ZeroReturnError
2023-11-12 13:39:20,338 - INFO - SSL Connection closed!
2023-11-12 13:39:21,097 - INFO - Handshake was successful!
2023-11-12 13:39:21,108 - INFO - Master Key and IV were successfully sent.
2023-11-12 13:39:21,305 - INFO - Encryption process completed for source file: .\..\archive\2023\ZW\ITSC\EHE.D\ZW.ITSC.00.EHN.D.2023.295.
2023-11-12 13:39:21,307 - INFO - Total Size of Data and Chunk Size were successfully sent.
2023-11-12 13:39:21,308 - INFO - Encrypted data were sent successfully.
2023-11-12 13:39:21,309 - INFO - Filename encrypted and sent successfully.
2023-11-12 13:39:21,482 - ERROR - TLS handshake error: 
Traceback (most recent call last):
  File "C:\Users\Marios Stefanidis\Documents\GitHub\Diploma-Thesis\code\slarchive-server\encryption\ssl_con.py", line 153, in run
    rejection_message = self.ssl_socket.recv(4096)
                        ^^^^^^^^^^^^^^^^^^^^^^^^^^
  File "C:\Users\Marios Stefanidis\AppData\Local\Programs\Python\Python311\Lib\site-packages\OpenSSL\SSL.py", line 2076, in recv
    self._raise_ssl_error(self._ssl, result)
  File "C:\Users\Marios Stefanidis\AppData\Local\Programs\Python\Python311\Lib\site-packages\OpenSSL\SSL.py", line 1814, in _raise_ssl_error
    raise ZeroReturnError()
OpenSSL.SSL.ZeroReturnError
2023-11-12 13:39:21,484 - INFO - SSL Connection closed!
2023-11-12 18:44:57,727 - INFO - Handshake was successful!
2023-11-12 18:44:57,755 - INFO - Master Key and IV were successfully sent.
2023-11-12 18:44:58,007 - INFO - Encryption process completed for source file: .\..\archive\2023\ZW\ITSC\EHN.D\ZW.ITSC.00.EHN.D.2023.295.
2023-11-12 18:44:58,007 - INFO - Total Size of Data and Chunk Size were successfully sent.
2023-11-12 18:44:58,007 - INFO - Encrypted data were sent successfully.
2023-11-12 18:44:58,007 - INFO - Filename encrypted and sent successfully.
2023-11-12 18:44:58,277 - ERROR - TLS handshake error: 
Traceback (most recent call last):
  File "C:\Users\Marios Stefanidis\Documents\GitHub\Diploma-Thesis\code\slarchive-server\encryption\ssl_con.py", line 153, in run
    rejection_message = self.ssl_socket.recv(4096)
                        ^^^^^^^^^^^^^^^^^^^^^^^^^^
  File "C:\Users\Marios Stefanidis\AppData\Local\Programs\Python\Python311\Lib\site-packages\OpenSSL\SSL.py", line 2076, in recv
    self._raise_ssl_error(self._ssl, result)
  File "C:\Users\Marios Stefanidis\AppData\Local\Programs\Python\Python311\Lib\site-packages\OpenSSL\SSL.py", line 1814, in _raise_ssl_error
    raise ZeroReturnError()
OpenSSL.SSL.ZeroReturnError
2023-11-12 18:44:58,278 - INFO - SSL Connection closed!
2023-11-12 18:45:01,060 - ERROR - TLS handshake error: (10054, 'WSAECONNRESET')
Traceback (most recent call last):
  File "C:\Users\Marios Stefanidis\Documents\GitHub\Diploma-Thesis\code\slarchive-server\encryption\ssl_con.py", line 147, in run
    self.establish_ssl_connection()
  File "C:\Users\Marios Stefanidis\Documents\GitHub\Diploma-Thesis\code\slarchive-server\encryption\ssl_con.py", line 38, in establish_ssl_connection
    self.ssl_socket.do_handshake()
  File "C:\Users\Marios Stefanidis\AppData\Local\Programs\Python\Python311\Lib\site-packages\OpenSSL\SSL.py", line 2202, in do_handshake
    self._raise_ssl_error(self._ssl, result)
  File "C:\Users\Marios Stefanidis\AppData\Local\Programs\Python\Python311\Lib\site-packages\OpenSSL\SSL.py", line 1827, in _raise_ssl_error
    raise SysCallError(errno, errorcode.get(errno))
OpenSSL.SSL.SysCallError: (10054, 'WSAECONNRESET')
2023-11-12 18:45:01,060 - INFO - SSL Connection closed!
2023-11-12 18:45:03,946 - ERROR - An error occurred: [WinError 10061] No connection could be made because the target machine actively refused it
Traceback (most recent call last):
  File "C:\Users\Marios Stefanidis\Documents\GitHub\Diploma-Thesis\code\slarchive-server\encryption\ssl_con.py", line 146, in run
    self.connect()
  File "C:\Users\Marios Stefanidis\Documents\GitHub\Diploma-Thesis\code\slarchive-server\encryption\ssl_con.py", line 26, in connect
    self.client_socket.connect(('127.0.0.1', 8443)) # Connect to the server
    ^^^^^^^^^^^^^^^^^^^^^^^^^^^^^^^^^^^^^^^^^^^^^^^
ConnectionRefusedError: [WinError 10061] No connection could be made because the target machine actively refused it
2023-11-12 18:45:03,947 - INFO - SSL Connection closed!
2023-11-12 18:48:30,378 - INFO - Handshake was successful!
2023-11-12 18:48:30,399 - INFO - Master Key and IV were successfully sent.
2023-11-12 18:48:30,632 - INFO - Encryption process completed for source file: .\..\archive\2023\ZW\ITSC\EHE.D\ZW.ITSC.00.EHN.D.2023.295.
2023-11-12 18:48:30,632 - INFO - Total Size of Data and Chunk Size were successfully sent.
2023-11-12 18:48:30,632 - INFO - Encrypted data were sent successfully.
2023-11-12 18:48:30,632 - INFO - Filename encrypted and sent successfully.
2023-11-12 18:48:30,941 - ERROR - TLS handshake error: 
Traceback (most recent call last):
  File "C:\Users\Marios Stefanidis\Documents\GitHub\Diploma-Thesis\code\slarchive-server\encryption\ssl_con.py", line 153, in run
    rejection_message = self.ssl_socket.recv(4096)
                        ^^^^^^^^^^^^^^^^^^^^^^^^^^
  File "C:\Users\Marios Stefanidis\AppData\Local\Programs\Python\Python311\Lib\site-packages\OpenSSL\SSL.py", line 2076, in recv
    self._raise_ssl_error(self._ssl, result)
  File "C:\Users\Marios Stefanidis\AppData\Local\Programs\Python\Python311\Lib\site-packages\OpenSSL\SSL.py", line 1814, in _raise_ssl_error
    raise ZeroReturnError()
OpenSSL.SSL.ZeroReturnError
2023-11-12 18:48:30,941 - INFO - SSL Connection closed!
2023-11-12 18:48:31,749 - INFO - Handshake was successful!
2023-11-12 18:48:31,764 - INFO - Master Key and IV were successfully sent.
2023-11-12 18:48:31,965 - INFO - Encryption process completed for source file: .\..\archive\2023\ZW\ITSC\EHE.D\ZW.ITSC.00.EHN.D.2023.295.
2023-11-12 18:48:31,965 - INFO - Total Size of Data and Chunk Size were successfully sent.
2023-11-12 18:48:31,965 - INFO - Encrypted data were sent successfully.
2023-11-12 18:48:31,965 - INFO - Filename encrypted and sent successfully.
2023-11-12 18:48:32,342 - ERROR - TLS handshake error: 
Traceback (most recent call last):
  File "C:\Users\Marios Stefanidis\Documents\GitHub\Diploma-Thesis\code\slarchive-server\encryption\ssl_con.py", line 153, in run
    rejection_message = self.ssl_socket.recv(4096)
                        ^^^^^^^^^^^^^^^^^^^^^^^^^^
  File "C:\Users\Marios Stefanidis\AppData\Local\Programs\Python\Python311\Lib\site-packages\OpenSSL\SSL.py", line 2076, in recv
    self._raise_ssl_error(self._ssl, result)
  File "C:\Users\Marios Stefanidis\AppData\Local\Programs\Python\Python311\Lib\site-packages\OpenSSL\SSL.py", line 1814, in _raise_ssl_error
    raise ZeroReturnError()
OpenSSL.SSL.ZeroReturnError
2023-11-12 18:48:32,342 - INFO - SSL Connection closed!
2023-11-13 21:57:40,765 - INFO - Handshake was successful!
2023-11-13 21:57:40,828 - INFO - Master Key and IV were successfully sent.
2023-11-13 21:57:41,237 - INFO - Encryption process completed for source file: .\..\archive\2023\ZW\ITSC\EHE.D\ZW.ITSC.00.EHE.D.2023.316.
2023-11-13 21:57:41,237 - INFO - Total Size of Data and Chunk Size were successfully sent.
2023-11-13 21:57:41,237 - INFO - Encrypted data were sent successfully.
2023-11-13 21:57:41,237 - INFO - Filename encrypted and sent successfully.
2023-11-13 21:57:41,474 - ERROR - TLS handshake error: 
Traceback (most recent call last):
  File "C:\Users\Marios Stefanidis\Documents\GitHub\Diploma-Thesis\code\slarchive-server\encryption\ssl_con.py", line 153, in run
    rejection_message = self.ssl_socket.recv(4096)
                        ^^^^^^^^^^^^^^^^^^^^^^^^^^
  File "C:\Users\Marios Stefanidis\AppData\Local\Programs\Python\Python311\Lib\site-packages\OpenSSL\SSL.py", line 2076, in recv
    self._raise_ssl_error(self._ssl, result)
  File "C:\Users\Marios Stefanidis\AppData\Local\Programs\Python\Python311\Lib\site-packages\OpenSSL\SSL.py", line 1814, in _raise_ssl_error
    raise ZeroReturnError()
OpenSSL.SSL.ZeroReturnError
2023-11-13 21:57:41,490 - INFO - SSL Connection closed!
2023-11-13 21:57:42,065 - INFO - Handshake was successful!
2023-11-13 21:57:42,065 - INFO - Master Key and IV were successfully sent.
2023-11-13 21:57:42,238 - INFO - Encryption process completed for source file: .\..\archive\2023\ZW\ITSC\EHE.D\ZW.ITSC.00.EHE.D.2023.316.
2023-11-13 21:57:42,238 - INFO - Total Size of Data and Chunk Size were successfully sent.
2023-11-13 21:57:42,254 - INFO - Encrypted data were sent successfully.
2023-11-13 21:57:42,254 - INFO - Filename encrypted and sent successfully.
2023-11-13 21:57:42,387 - ERROR - TLS handshake error: 
Traceback (most recent call last):
  File "C:\Users\Marios Stefanidis\Documents\GitHub\Diploma-Thesis\code\slarchive-server\encryption\ssl_con.py", line 153, in run
    rejection_message = self.ssl_socket.recv(4096)
                        ^^^^^^^^^^^^^^^^^^^^^^^^^^
  File "C:\Users\Marios Stefanidis\AppData\Local\Programs\Python\Python311\Lib\site-packages\OpenSSL\SSL.py", line 2076, in recv
    self._raise_ssl_error(self._ssl, result)
  File "C:\Users\Marios Stefanidis\AppData\Local\Programs\Python\Python311\Lib\site-packages\OpenSSL\SSL.py", line 1814, in _raise_ssl_error
    raise ZeroReturnError()
OpenSSL.SSL.ZeroReturnError
2023-11-13 21:57:42,387 - INFO - SSL Connection closed!
2023-11-13 21:57:42,936 - INFO - Handshake was successful!
2023-11-13 21:57:42,936 - INFO - Master Key and IV were successfully sent.
2023-11-13 21:57:43,124 - INFO - Encryption process completed for source file: .\..\archive\2023\ZW\ITSC\EHN.D\ZW.ITSC.00.EHN.D.2023.316.
2023-11-13 21:57:43,124 - INFO - Total Size of Data and Chunk Size were successfully sent.
2023-11-13 21:57:43,124 - INFO - Encrypted data were sent successfully.
2023-11-13 21:57:43,124 - INFO - Filename encrypted and sent successfully.
2023-11-13 21:57:43,249 - ERROR - TLS handshake error: 
Traceback (most recent call last):
  File "C:\Users\Marios Stefanidis\Documents\GitHub\Diploma-Thesis\code\slarchive-server\encryption\ssl_con.py", line 153, in run
    rejection_message = self.ssl_socket.recv(4096)
                        ^^^^^^^^^^^^^^^^^^^^^^^^^^
  File "C:\Users\Marios Stefanidis\AppData\Local\Programs\Python\Python311\Lib\site-packages\OpenSSL\SSL.py", line 2076, in recv
    self._raise_ssl_error(self._ssl, result)
  File "C:\Users\Marios Stefanidis\AppData\Local\Programs\Python\Python311\Lib\site-packages\OpenSSL\SSL.py", line 1814, in _raise_ssl_error
    raise ZeroReturnError()
OpenSSL.SSL.ZeroReturnError
2023-11-13 21:57:43,249 - INFO - SSL Connection closed!
2023-11-13 21:57:43,831 - INFO - Handshake was successful!
2023-11-13 21:57:43,846 - INFO - Master Key and IV were successfully sent.
2023-11-13 21:57:44,026 - INFO - Encryption process completed for source file: .\..\archive\2023\ZW\ITSC\EHZ.D\ZW.ITSC.00.EHZ.D.2023.316.
2023-11-13 21:57:44,026 - INFO - Total Size of Data and Chunk Size were successfully sent.
2023-11-13 21:57:44,026 - INFO - Encrypted data were sent successfully.
2023-11-13 21:57:44,026 - INFO - Filename encrypted and sent successfully.
2023-11-13 21:57:44,171 - ERROR - TLS handshake error: 
Traceback (most recent call last):
  File "C:\Users\Marios Stefanidis\Documents\GitHub\Diploma-Thesis\code\slarchive-server\encryption\ssl_con.py", line 153, in run
    rejection_message = self.ssl_socket.recv(4096)
                        ^^^^^^^^^^^^^^^^^^^^^^^^^^
  File "C:\Users\Marios Stefanidis\AppData\Local\Programs\Python\Python311\Lib\site-packages\OpenSSL\SSL.py", line 2076, in recv
    self._raise_ssl_error(self._ssl, result)
  File "C:\Users\Marios Stefanidis\AppData\Local\Programs\Python\Python311\Lib\site-packages\OpenSSL\SSL.py", line 1814, in _raise_ssl_error
    raise ZeroReturnError()
OpenSSL.SSL.ZeroReturnError
2023-11-13 21:57:44,171 - INFO - SSL Connection closed!
2023-11-18 11:46:33,814 - INFO - Handshake was successful!
2023-11-18 11:46:33,838 - INFO - Master Key and IV were successfully sent.
2023-11-18 11:46:34,092 - INFO - Encryption process completed for source file: .\..\archive\2023\HP\UPR\HHE.D\HP.UPR..HHE.D.2023.322.
2023-11-18 11:46:34,092 - INFO - Total Size of Data and Chunk Size were successfully sent.
2023-11-18 11:46:34,092 - INFO - Encrypted data were sent successfully.
2023-11-18 11:46:34,321 - ERROR - TLS handshake error: 
Traceback (most recent call last):
  File "C:\Users\Marios Stefanidis\Documents\GitHub\Diploma-Thesis\code\slarchive-server\encryption\ssl_con.py", line 147, in run
    rejection_message = self.ssl_socket.recv(4096)
                        ^^^^^^^^^^^^^^^^^^^^^^^^^^
  File "C:\Users\Marios Stefanidis\AppData\Local\Programs\Python\Python311\Lib\site-packages\OpenSSL\SSL.py", line 2076, in recv
    self._raise_ssl_error(self._ssl, result)
  File "C:\Users\Marios Stefanidis\AppData\Local\Programs\Python\Python311\Lib\site-packages\OpenSSL\SSL.py", line 1814, in _raise_ssl_error
    raise ZeroReturnError()
OpenSSL.SSL.ZeroReturnError
2023-11-18 11:46:34,321 - INFO - SSL Connection closed!
2023-11-18 11:46:42,300 - INFO - Handshake was successful!
2023-11-18 11:46:42,312 - INFO - Master Key and IV were successfully sent.
2023-11-18 11:46:42,503 - INFO - Encryption process completed for source file: .\..\archive\2023\HP\UPR\HHN.D\HP.UPR..HHN.D.2023.322.
2023-11-18 11:46:42,503 - INFO - Total Size of Data and Chunk Size were successfully sent.
2023-11-18 11:46:42,503 - INFO - Encrypted data were sent successfully.
2023-11-18 11:46:42,637 - ERROR - TLS handshake error: 
Traceback (most recent call last):
  File "C:\Users\Marios Stefanidis\Documents\GitHub\Diploma-Thesis\code\slarchive-server\encryption\ssl_con.py", line 147, in run
    rejection_message = self.ssl_socket.recv(4096)
                        ^^^^^^^^^^^^^^^^^^^^^^^^^^
  File "C:\Users\Marios Stefanidis\AppData\Local\Programs\Python\Python311\Lib\site-packages\OpenSSL\SSL.py", line 2076, in recv
    self._raise_ssl_error(self._ssl, result)
  File "C:\Users\Marios Stefanidis\AppData\Local\Programs\Python\Python311\Lib\site-packages\OpenSSL\SSL.py", line 1814, in _raise_ssl_error
    raise ZeroReturnError()
OpenSSL.SSL.ZeroReturnError
2023-11-18 11:46:42,637 - INFO - SSL Connection closed!
2023-11-18 11:46:48,177 - INFO - Handshake was successful!
2023-11-18 11:46:48,193 - INFO - Master Key and IV were successfully sent.
2023-11-18 11:46:48,387 - INFO - Encryption process completed for source file: .\..\archive\2023\HP\UPR\HHZ.D\HP.UPR..HHZ.D.2023.322.
2023-11-18 11:46:48,387 - INFO - Total Size of Data and Chunk Size were successfully sent.
2023-11-18 11:46:48,402 - INFO - Encrypted data were sent successfully.
2023-11-18 11:46:48,612 - ERROR - TLS handshake error: 
Traceback (most recent call last):
  File "C:\Users\Marios Stefanidis\Documents\GitHub\Diploma-Thesis\code\slarchive-server\encryption\ssl_con.py", line 147, in run
    rejection_message = self.ssl_socket.recv(4096)
                        ^^^^^^^^^^^^^^^^^^^^^^^^^^
  File "C:\Users\Marios Stefanidis\AppData\Local\Programs\Python\Python311\Lib\site-packages\OpenSSL\SSL.py", line 2076, in recv
    self._raise_ssl_error(self._ssl, result)
  File "C:\Users\Marios Stefanidis\AppData\Local\Programs\Python\Python311\Lib\site-packages\OpenSSL\SSL.py", line 1814, in _raise_ssl_error
    raise ZeroReturnError()
OpenSSL.SSL.ZeroReturnError
2023-11-18 11:46:48,613 - INFO - SSL Connection closed!
2023-11-18 11:46:52,431 - INFO - Handshake was successful!
2023-11-18 11:46:52,457 - INFO - Master Key and IV were successfully sent.
2023-11-18 11:46:52,659 - INFO - Encryption process completed for source file: .\..\archive\2023\HP\UPR\HNE.D\HP.UPR..HNE.D.2023.322.
2023-11-18 11:46:52,674 - INFO - Total Size of Data and Chunk Size were successfully sent.
2023-11-18 11:46:52,675 - INFO - Encrypted data were sent successfully.
2023-11-18 11:46:52,820 - ERROR - TLS handshake error: 
Traceback (most recent call last):
  File "C:\Users\Marios Stefanidis\Documents\GitHub\Diploma-Thesis\code\slarchive-server\encryption\ssl_con.py", line 147, in run
    rejection_message = self.ssl_socket.recv(4096)
                        ^^^^^^^^^^^^^^^^^^^^^^^^^^
  File "C:\Users\Marios Stefanidis\AppData\Local\Programs\Python\Python311\Lib\site-packages\OpenSSL\SSL.py", line 2076, in recv
    self._raise_ssl_error(self._ssl, result)
  File "C:\Users\Marios Stefanidis\AppData\Local\Programs\Python\Python311\Lib\site-packages\OpenSSL\SSL.py", line 1814, in _raise_ssl_error
    raise ZeroReturnError()
OpenSSL.SSL.ZeroReturnError
2023-11-18 11:46:52,820 - INFO - SSL Connection closed!
2023-11-18 11:47:08,900 - INFO - Handshake was successful!
2023-11-18 11:47:08,900 - INFO - Master Key and IV were successfully sent.
2023-11-18 11:47:09,097 - INFO - Encryption process completed for source file: .\..\archive\2023\HP\UPR\HNN.D\HP.UPR..HNN.D.2023.322.
2023-11-18 11:47:09,097 - INFO - Total Size of Data and Chunk Size were successfully sent.
2023-11-18 11:47:09,097 - INFO - Encrypted data were sent successfully.
2023-11-18 11:47:09,242 - ERROR - TLS handshake error: 
Traceback (most recent call last):
  File "C:\Users\Marios Stefanidis\Documents\GitHub\Diploma-Thesis\code\slarchive-server\encryption\ssl_con.py", line 147, in run
    rejection_message = self.ssl_socket.recv(4096)
                        ^^^^^^^^^^^^^^^^^^^^^^^^^^
  File "C:\Users\Marios Stefanidis\AppData\Local\Programs\Python\Python311\Lib\site-packages\OpenSSL\SSL.py", line 2076, in recv
    self._raise_ssl_error(self._ssl, result)
  File "C:\Users\Marios Stefanidis\AppData\Local\Programs\Python\Python311\Lib\site-packages\OpenSSL\SSL.py", line 1814, in _raise_ssl_error
    raise ZeroReturnError()
OpenSSL.SSL.ZeroReturnError
2023-11-18 11:47:09,242 - INFO - SSL Connection closed!
2023-11-18 11:47:12,136 - INFO - Handshake was successful!
2023-11-18 11:47:12,152 - INFO - Master Key and IV were successfully sent.
2023-11-18 11:47:12,338 - INFO - Encryption process completed for source file: .\..\archive\2023\HP\UPR\HNZ.D\HP.UPR..HNZ.D.2023.322.
2023-11-18 11:47:12,338 - INFO - Total Size of Data and Chunk Size were successfully sent.
2023-11-18 11:47:12,338 - INFO - Encrypted data were sent successfully.
2023-11-18 11:47:12,492 - ERROR - TLS handshake error: 
Traceback (most recent call last):
  File "C:\Users\Marios Stefanidis\Documents\GitHub\Diploma-Thesis\code\slarchive-server\encryption\ssl_con.py", line 147, in run
    rejection_message = self.ssl_socket.recv(4096)
                        ^^^^^^^^^^^^^^^^^^^^^^^^^^
  File "C:\Users\Marios Stefanidis\AppData\Local\Programs\Python\Python311\Lib\site-packages\OpenSSL\SSL.py", line 2076, in recv
    self._raise_ssl_error(self._ssl, result)
  File "C:\Users\Marios Stefanidis\AppData\Local\Programs\Python\Python311\Lib\site-packages\OpenSSL\SSL.py", line 1814, in _raise_ssl_error
    raise ZeroReturnError()
OpenSSL.SSL.ZeroReturnError
2023-11-18 11:47:12,492 - INFO - SSL Connection closed!
2023-11-18 11:47:16,395 - INFO - Handshake was successful!
2023-11-18 11:47:16,395 - INFO - Master Key and IV were successfully sent.
2023-11-18 11:47:16,610 - INFO - Encryption process completed for source file: .\..\archive\2023\HP\UPR\HNN.D\HP.UPR..HNN.D.2023.322.
2023-11-18 11:47:16,610 - INFO - Total Size of Data and Chunk Size were successfully sent.
2023-11-18 11:47:16,610 - INFO - Encrypted data were sent successfully.
2023-11-18 11:47:16,757 - ERROR - TLS handshake error: 
Traceback (most recent call last):
  File "C:\Users\Marios Stefanidis\Documents\GitHub\Diploma-Thesis\code\slarchive-server\encryption\ssl_con.py", line 147, in run
    rejection_message = self.ssl_socket.recv(4096)
                        ^^^^^^^^^^^^^^^^^^^^^^^^^^
  File "C:\Users\Marios Stefanidis\AppData\Local\Programs\Python\Python311\Lib\site-packages\OpenSSL\SSL.py", line 2076, in recv
    self._raise_ssl_error(self._ssl, result)
  File "C:\Users\Marios Stefanidis\AppData\Local\Programs\Python\Python311\Lib\site-packages\OpenSSL\SSL.py", line 1814, in _raise_ssl_error
    raise ZeroReturnError()
OpenSSL.SSL.ZeroReturnError
2023-11-18 11:47:16,757 - INFO - SSL Connection closed!
2023-11-18 11:47:17,697 - INFO - Handshake was successful!
2023-11-18 11:47:17,705 - INFO - Master Key and IV were successfully sent.
2023-11-18 11:47:17,903 - INFO - Encryption process completed for source file: .\..\archive\2023\HP\UPR\HNE.D\HP.UPR..HNE.D.2023.322.
2023-11-18 11:47:17,903 - INFO - Total Size of Data and Chunk Size were successfully sent.
2023-11-18 11:47:17,903 - INFO - Encrypted data were sent successfully.
2023-11-18 11:47:18,038 - ERROR - TLS handshake error: 
Traceback (most recent call last):
  File "C:\Users\Marios Stefanidis\Documents\GitHub\Diploma-Thesis\code\slarchive-server\encryption\ssl_con.py", line 147, in run
    rejection_message = self.ssl_socket.recv(4096)
                        ^^^^^^^^^^^^^^^^^^^^^^^^^^
  File "C:\Users\Marios Stefanidis\AppData\Local\Programs\Python\Python311\Lib\site-packages\OpenSSL\SSL.py", line 2076, in recv
    self._raise_ssl_error(self._ssl, result)
  File "C:\Users\Marios Stefanidis\AppData\Local\Programs\Python\Python311\Lib\site-packages\OpenSSL\SSL.py", line 1814, in _raise_ssl_error
    raise ZeroReturnError()
OpenSSL.SSL.ZeroReturnError
2023-11-18 11:47:18,038 - INFO - SSL Connection closed!
2023-11-18 11:47:27,747 - INFO - Handshake was successful!
2023-11-18 11:47:27,774 - INFO - Master Key and IV were successfully sent.
2023-11-18 11:47:28,110 - INFO - Encryption process completed for source file: .\..\archive\2023\HP\UPR\HHE.D\HP.UPR..HHE.D.2023.322.
2023-11-18 11:47:28,110 - INFO - Total Size of Data and Chunk Size were successfully sent.
2023-11-18 11:47:28,110 - INFO - Encrypted data were sent successfully.
2023-11-18 11:47:28,299 - ERROR - TLS handshake error: 
Traceback (most recent call last):
  File "C:\Users\Marios Stefanidis\Documents\GitHub\Diploma-Thesis\code\slarchive-server\encryption\ssl_con.py", line 147, in run
    rejection_message = self.ssl_socket.recv(4096)
                        ^^^^^^^^^^^^^^^^^^^^^^^^^^
  File "C:\Users\Marios Stefanidis\AppData\Local\Programs\Python\Python311\Lib\site-packages\OpenSSL\SSL.py", line 2076, in recv
    self._raise_ssl_error(self._ssl, result)
  File "C:\Users\Marios Stefanidis\AppData\Local\Programs\Python\Python311\Lib\site-packages\OpenSSL\SSL.py", line 1814, in _raise_ssl_error
    raise ZeroReturnError()
OpenSSL.SSL.ZeroReturnError
2023-11-18 11:47:28,301 - INFO - SSL Connection closed!
2023-11-18 11:47:33,687 - INFO - Handshake was successful!
2023-11-18 11:47:33,703 - INFO - Master Key and IV were successfully sent.
2023-11-18 11:47:33,969 - INFO - Encryption process completed for source file: .\..\archive\2023\HP\UPR\HHE.D\HP.UPR..HHE.D.2023.322.
2023-11-18 11:47:33,969 - INFO - Total Size of Data and Chunk Size were successfully sent.
2023-11-18 11:47:33,969 - INFO - Encrypted data were sent successfully.
2023-11-18 11:47:34,111 - ERROR - TLS handshake error: 
Traceback (most recent call last):
  File "C:\Users\Marios Stefanidis\Documents\GitHub\Diploma-Thesis\code\slarchive-server\encryption\ssl_con.py", line 147, in run
    rejection_message = self.ssl_socket.recv(4096)
                        ^^^^^^^^^^^^^^^^^^^^^^^^^^
  File "C:\Users\Marios Stefanidis\AppData\Local\Programs\Python\Python311\Lib\site-packages\OpenSSL\SSL.py", line 2076, in recv
    self._raise_ssl_error(self._ssl, result)
  File "C:\Users\Marios Stefanidis\AppData\Local\Programs\Python\Python311\Lib\site-packages\OpenSSL\SSL.py", line 1814, in _raise_ssl_error
    raise ZeroReturnError()
OpenSSL.SSL.ZeroReturnError
2023-11-18 11:47:34,112 - INFO - SSL Connection closed!
2023-11-18 11:47:34,892 - INFO - Handshake was successful!
2023-11-18 11:47:34,908 - INFO - Master Key and IV were successfully sent.
2023-11-18 11:47:35,088 - INFO - Encryption process completed for source file: .\..\archive\2023\HP\UPR\HNN.D\HP.UPR..HNN.D.2023.322.
2023-11-18 11:47:35,088 - INFO - Total Size of Data and Chunk Size were successfully sent.
2023-11-18 11:47:35,088 - INFO - Encrypted data were sent successfully.
2023-11-18 11:47:35,208 - ERROR - TLS handshake error: 
Traceback (most recent call last):
  File "C:\Users\Marios Stefanidis\Documents\GitHub\Diploma-Thesis\code\slarchive-server\encryption\ssl_con.py", line 147, in run
    rejection_message = self.ssl_socket.recv(4096)
                        ^^^^^^^^^^^^^^^^^^^^^^^^^^
  File "C:\Users\Marios Stefanidis\AppData\Local\Programs\Python\Python311\Lib\site-packages\OpenSSL\SSL.py", line 2076, in recv
    self._raise_ssl_error(self._ssl, result)
  File "C:\Users\Marios Stefanidis\AppData\Local\Programs\Python\Python311\Lib\site-packages\OpenSSL\SSL.py", line 1814, in _raise_ssl_error
    raise ZeroReturnError()
OpenSSL.SSL.ZeroReturnError
2023-11-18 11:47:35,208 - INFO - SSL Connection closed!
2023-11-18 11:47:36,006 - ERROR - TLS handshake error: (10053, 'WSAECONNABORTED')
Traceback (most recent call last):
  File "C:\Users\Marios Stefanidis\Documents\GitHub\Diploma-Thesis\code\slarchive-server\encryption\ssl_con.py", line 141, in run
    self.establish_ssl_connection()
  File "C:\Users\Marios Stefanidis\Documents\GitHub\Diploma-Thesis\code\slarchive-server\encryption\ssl_con.py", line 38, in establish_ssl_connection
    self.ssl_socket.do_handshake()
  File "C:\Users\Marios Stefanidis\AppData\Local\Programs\Python\Python311\Lib\site-packages\OpenSSL\SSL.py", line 2202, in do_handshake
    self._raise_ssl_error(self._ssl, result)
  File "C:\Users\Marios Stefanidis\AppData\Local\Programs\Python\Python311\Lib\site-packages\OpenSSL\SSL.py", line 1827, in _raise_ssl_error
    raise SysCallError(errno, errorcode.get(errno))
OpenSSL.SSL.SysCallError: (10053, 'WSAECONNABORTED')
2023-11-18 11:47:36,006 - INFO - SSL Connection closed!
2023-11-18 11:47:36,753 - ERROR - TLS handshake error: (10053, 'WSAECONNABORTED')
Traceback (most recent call last):
  File "C:\Users\Marios Stefanidis\Documents\GitHub\Diploma-Thesis\code\slarchive-server\encryption\ssl_con.py", line 141, in run
    self.establish_ssl_connection()
  File "C:\Users\Marios Stefanidis\Documents\GitHub\Diploma-Thesis\code\slarchive-server\encryption\ssl_con.py", line 38, in establish_ssl_connection
    self.ssl_socket.do_handshake()
  File "C:\Users\Marios Stefanidis\AppData\Local\Programs\Python\Python311\Lib\site-packages\OpenSSL\SSL.py", line 2202, in do_handshake
    self._raise_ssl_error(self._ssl, result)
  File "C:\Users\Marios Stefanidis\AppData\Local\Programs\Python\Python311\Lib\site-packages\OpenSSL\SSL.py", line 1827, in _raise_ssl_error
    raise SysCallError(errno, errorcode.get(errno))
OpenSSL.SSL.SysCallError: (10053, 'WSAECONNABORTED')
2023-11-18 11:47:36,753 - INFO - SSL Connection closed!
2023-11-18 11:47:37,515 - ERROR - TLS handshake error: (10053, 'WSAECONNABORTED')
Traceback (most recent call last):
  File "C:\Users\Marios Stefanidis\Documents\GitHub\Diploma-Thesis\code\slarchive-server\encryption\ssl_con.py", line 141, in run
    self.establish_ssl_connection()
  File "C:\Users\Marios Stefanidis\Documents\GitHub\Diploma-Thesis\code\slarchive-server\encryption\ssl_con.py", line 38, in establish_ssl_connection
    self.ssl_socket.do_handshake()
  File "C:\Users\Marios Stefanidis\AppData\Local\Programs\Python\Python311\Lib\site-packages\OpenSSL\SSL.py", line 2202, in do_handshake
    self._raise_ssl_error(self._ssl, result)
  File "C:\Users\Marios Stefanidis\AppData\Local\Programs\Python\Python311\Lib\site-packages\OpenSSL\SSL.py", line 1827, in _raise_ssl_error
    raise SysCallError(errno, errorcode.get(errno))
OpenSSL.SSL.SysCallError: (10053, 'WSAECONNABORTED')
2023-11-18 11:47:37,515 - INFO - SSL Connection closed!
2023-11-18 11:47:38,161 - ERROR - TLS handshake error: (10053, 'WSAECONNABORTED')
Traceback (most recent call last):
  File "C:\Users\Marios Stefanidis\Documents\GitHub\Diploma-Thesis\code\slarchive-server\encryption\ssl_con.py", line 141, in run
    self.establish_ssl_connection()
  File "C:\Users\Marios Stefanidis\Documents\GitHub\Diploma-Thesis\code\slarchive-server\encryption\ssl_con.py", line 38, in establish_ssl_connection
    self.ssl_socket.do_handshake()
  File "C:\Users\Marios Stefanidis\AppData\Local\Programs\Python\Python311\Lib\site-packages\OpenSSL\SSL.py", line 2202, in do_handshake
    self._raise_ssl_error(self._ssl, result)
  File "C:\Users\Marios Stefanidis\AppData\Local\Programs\Python\Python311\Lib\site-packages\OpenSSL\SSL.py", line 1827, in _raise_ssl_error
    raise SysCallError(errno, errorcode.get(errno))
OpenSSL.SSL.SysCallError: (10053, 'WSAECONNABORTED')
2023-11-18 11:47:38,161 - INFO - SSL Connection closed!
