2023-11-12 13:07:46,163 - ERROR - TLS handshake error: (10053, 'WSAECONNABORTED')
Traceback (most recent call last):
  File "C:\Users\Marios Stefanidis\Documents\GitHub\Diploma-Thesis\code\slarchive-server\encryption\ssl_con.py", line 147, in run
    self.establish_ssl_connection()
  File "C:\Users\Marios Stefanidis\Documents\GitHub\Diploma-Thesis\code\slarchive-server\encryption\ssl_con.py", line 38, in establish_ssl_connection
    self.ssl_socket.do_handshake()
  File "C:\Users\Marios Stefanidis\AppData\Local\Programs\Python\Python311\Lib\site-packages\OpenSSL\SSL.py", line 2202, in do_handshake
    self._raise_ssl_error(self._ssl, result)
  File "C:\Users\Marios Stefanidis\AppData\Local\Programs\Python\Python311\Lib\site-packages\OpenSSL\SSL.py", line 1827, in _raise_ssl_error
    raise SysCallError(errno, errorcode.get(errno))
OpenSSL.SSL.SysCallError: (10053, 'WSAECONNABORTED')
2023-11-12 13:07:46,739 - ERROR - TLS handshake error: (10053, 'WSAECONNABORTED')
Traceback (most recent call last):
  File "C:\Users\Marios Stefanidis\Documents\GitHub\Diploma-Thesis\code\slarchive-server\encryption\ssl_con.py", line 147, in run
    self.establish_ssl_connection()
  File "C:\Users\Marios Stefanidis\Documents\GitHub\Diploma-Thesis\code\slarchive-server\encryption\ssl_con.py", line 38, in establish_ssl_connection
    self.ssl_socket.do_handshake()
  File "C:\Users\Marios Stefanidis\AppData\Local\Programs\Python\Python311\Lib\site-packages\OpenSSL\SSL.py", line 2202, in do_handshake
    self._raise_ssl_error(self._ssl, result)
  File "C:\Users\Marios Stefanidis\AppData\Local\Programs\Python\Python311\Lib\site-packages\OpenSSL\SSL.py", line 1827, in _raise_ssl_error
    raise SysCallError(errno, errorcode.get(errno))
OpenSSL.SSL.SysCallError: (10053, 'WSAECONNABORTED')
2023-11-12 13:08:32,976 - ERROR - TLS handshake error: (10053, 'WSAECONNABORTED')
Traceback (most recent call last):
  File "C:\Users\Marios Stefanidis\Documents\GitHub\Diploma-Thesis\code\slarchive-server\encryption\ssl_con.py", line 147, in run
    self.establish_ssl_connection()
  File "C:\Users\Marios Stefanidis\Documents\GitHub\Diploma-Thesis\code\slarchive-server\encryption\ssl_con.py", line 38, in establish_ssl_connection
    self.ssl_socket.do_handshake()
  File "C:\Users\Marios Stefanidis\AppData\Local\Programs\Python\Python311\Lib\site-packages\OpenSSL\SSL.py", line 2202, in do_handshake
    self._raise_ssl_error(self._ssl, result)
  File "C:\Users\Marios Stefanidis\AppData\Local\Programs\Python\Python311\Lib\site-packages\OpenSSL\SSL.py", line 1827, in _raise_ssl_error
    raise SysCallError(errno, errorcode.get(errno))
OpenSSL.SSL.SysCallError: (10053, 'WSAECONNABORTED')
2023-11-12 13:08:33,548 - ERROR - TLS handshake error: (10053, 'WSAECONNABORTED')
Traceback (most recent call last):
  File "C:\Users\Marios Stefanidis\Documents\GitHub\Diploma-Thesis\code\slarchive-server\encryption\ssl_con.py", line 147, in run
    self.establish_ssl_connection()
  File "C:\Users\Marios Stefanidis\Documents\GitHub\Diploma-Thesis\code\slarchive-server\encryption\ssl_con.py", line 38, in establish_ssl_connection
    self.ssl_socket.do_handshake()
  File "C:\Users\Marios Stefanidis\AppData\Local\Programs\Python\Python311\Lib\site-packages\OpenSSL\SSL.py", line 2202, in do_handshake
    self._raise_ssl_error(self._ssl, result)
  File "C:\Users\Marios Stefanidis\AppData\Local\Programs\Python\Python311\Lib\site-packages\OpenSSL\SSL.py", line 1827, in _raise_ssl_error
    raise SysCallError(errno, errorcode.get(errno))
OpenSSL.SSL.SysCallError: (10053, 'WSAECONNABORTED')
2023-11-12 13:09:32,608 - ERROR - TLS handshake error: (10053, 'WSAECONNABORTED')
Traceback (most recent call last):
  File "C:\Users\Marios Stefanidis\Documents\GitHub\Diploma-Thesis\code\slarchive-server\encryption\ssl_con.py", line 147, in run
    self.establish_ssl_connection()
  File "C:\Users\Marios Stefanidis\Documents\GitHub\Diploma-Thesis\code\slarchive-server\encryption\ssl_con.py", line 38, in establish_ssl_connection
    self.ssl_socket.do_handshake()
  File "C:\Users\Marios Stefanidis\AppData\Local\Programs\Python\Python311\Lib\site-packages\OpenSSL\SSL.py", line 2202, in do_handshake
    self._raise_ssl_error(self._ssl, result)
  File "C:\Users\Marios Stefanidis\AppData\Local\Programs\Python\Python311\Lib\site-packages\OpenSSL\SSL.py", line 1827, in _raise_ssl_error
    raise SysCallError(errno, errorcode.get(errno))
OpenSSL.SSL.SysCallError: (10053, 'WSAECONNABORTED')
2023-11-12 13:09:33,210 - ERROR - TLS handshake error: (10053, 'WSAECONNABORTED')
Traceback (most recent call last):
  File "C:\Users\Marios Stefanidis\Documents\GitHub\Diploma-Thesis\code\slarchive-server\encryption\ssl_con.py", line 147, in run
    self.establish_ssl_connection()
  File "C:\Users\Marios Stefanidis\Documents\GitHub\Diploma-Thesis\code\slarchive-server\encryption\ssl_con.py", line 38, in establish_ssl_connection
    self.ssl_socket.do_handshake()
  File "C:\Users\Marios Stefanidis\AppData\Local\Programs\Python\Python311\Lib\site-packages\OpenSSL\SSL.py", line 2202, in do_handshake
    self._raise_ssl_error(self._ssl, result)
  File "C:\Users\Marios Stefanidis\AppData\Local\Programs\Python\Python311\Lib\site-packages\OpenSSL\SSL.py", line 1827, in _raise_ssl_error
    raise SysCallError(errno, errorcode.get(errno))
OpenSSL.SSL.SysCallError: (10053, 'WSAECONNABORTED')
2023-11-12 13:10:19,493 - ERROR - TLS handshake error: (10053, 'WSAECONNABORTED')
Traceback (most recent call last):
  File "C:\Users\Marios Stefanidis\Documents\GitHub\Diploma-Thesis\code\slarchive-server\encryption\ssl_con.py", line 147, in run
    self.establish_ssl_connection()
  File "C:\Users\Marios Stefanidis\Documents\GitHub\Diploma-Thesis\code\slarchive-server\encryption\ssl_con.py", line 38, in establish_ssl_connection
    self.ssl_socket.do_handshake()
  File "C:\Users\Marios Stefanidis\AppData\Local\Programs\Python\Python311\Lib\site-packages\OpenSSL\SSL.py", line 2202, in do_handshake
    self._raise_ssl_error(self._ssl, result)
  File "C:\Users\Marios Stefanidis\AppData\Local\Programs\Python\Python311\Lib\site-packages\OpenSSL\SSL.py", line 1827, in _raise_ssl_error
    raise SysCallError(errno, errorcode.get(errno))
OpenSSL.SSL.SysCallError: (10053, 'WSAECONNABORTED')
2023-11-12 13:10:20,076 - ERROR - TLS handshake error: (10053, 'WSAECONNABORTED')
Traceback (most recent call last):
  File "C:\Users\Marios Stefanidis\Documents\GitHub\Diploma-Thesis\code\slarchive-server\encryption\ssl_con.py", line 147, in run
    self.establish_ssl_connection()
  File "C:\Users\Marios Stefanidis\Documents\GitHub\Diploma-Thesis\code\slarchive-server\encryption\ssl_con.py", line 38, in establish_ssl_connection
    self.ssl_socket.do_handshake()
  File "C:\Users\Marios Stefanidis\AppData\Local\Programs\Python\Python311\Lib\site-packages\OpenSSL\SSL.py", line 2202, in do_handshake
    self._raise_ssl_error(self._ssl, result)
  File "C:\Users\Marios Stefanidis\AppData\Local\Programs\Python\Python311\Lib\site-packages\OpenSSL\SSL.py", line 1827, in _raise_ssl_error
    raise SysCallError(errno, errorcode.get(errno))
OpenSSL.SSL.SysCallError: (10053, 'WSAECONNABORTED')
2023-11-12 13:10:54,481 - ERROR - TLS handshake error: (10053, 'WSAECONNABORTED')
Traceback (most recent call last):
  File "C:\Users\Marios Stefanidis\Documents\GitHub\Diploma-Thesis\code\slarchive-server\encryption\ssl_con.py", line 147, in run
    self.establish_ssl_connection()
  File "C:\Users\Marios Stefanidis\Documents\GitHub\Diploma-Thesis\code\slarchive-server\encryption\ssl_con.py", line 38, in establish_ssl_connection
    self.ssl_socket.do_handshake()
  File "C:\Users\Marios Stefanidis\AppData\Local\Programs\Python\Python311\Lib\site-packages\OpenSSL\SSL.py", line 2202, in do_handshake
    self._raise_ssl_error(self._ssl, result)
  File "C:\Users\Marios Stefanidis\AppData\Local\Programs\Python\Python311\Lib\site-packages\OpenSSL\SSL.py", line 1827, in _raise_ssl_error
    raise SysCallError(errno, errorcode.get(errno))
OpenSSL.SSL.SysCallError: (10053, 'WSAECONNABORTED')
2023-11-12 13:10:55,064 - ERROR - TLS handshake error: (10053, 'WSAECONNABORTED')
Traceback (most recent call last):
  File "C:\Users\Marios Stefanidis\Documents\GitHub\Diploma-Thesis\code\slarchive-server\encryption\ssl_con.py", line 147, in run
    self.establish_ssl_connection()
  File "C:\Users\Marios Stefanidis\Documents\GitHub\Diploma-Thesis\code\slarchive-server\encryption\ssl_con.py", line 38, in establish_ssl_connection
    self.ssl_socket.do_handshake()
  File "C:\Users\Marios Stefanidis\AppData\Local\Programs\Python\Python311\Lib\site-packages\OpenSSL\SSL.py", line 2202, in do_handshake
    self._raise_ssl_error(self._ssl, result)
  File "C:\Users\Marios Stefanidis\AppData\Local\Programs\Python\Python311\Lib\site-packages\OpenSSL\SSL.py", line 1827, in _raise_ssl_error
    raise SysCallError(errno, errorcode.get(errno))
OpenSSL.SSL.SysCallError: (10053, 'WSAECONNABORTED')
2023-11-12 13:13:04,536 - INFO - Handshake was successful!
2023-11-12 13:13:04,548 - INFO - Master Key and IV were successfully sent.
2023-11-12 13:13:04,742 - INFO - Encryption process completed for source file: .\..\archive\2023\ZW\ITSC\EHE.D\ZW.ITSC.00.EHN.D.2023.295.
2023-11-12 13:13:04,742 - INFO - Total Size of Data and Chunk Size were successfully sent.
2023-11-12 13:13:04,742 - INFO - Encrypted data were sent successfully.
2023-11-12 13:13:04,742 - INFO - Filename encrypted and sent successfully.
2023-11-12 13:13:04,979 - ERROR - TLS handshake error: 
Traceback (most recent call last):
  File "C:\Users\Marios Stefanidis\Documents\GitHub\Diploma-Thesis\code\slarchive-server\encryption\ssl_con.py", line 153, in run
    rejection_message = self.ssl_socket.recv(4096)
                        ^^^^^^^^^^^^^^^^^^^^^^^^^^
  File "C:\Users\Marios Stefanidis\AppData\Local\Programs\Python\Python311\Lib\site-packages\OpenSSL\SSL.py", line 2076, in recv
    self._raise_ssl_error(self._ssl, result)
  File "C:\Users\Marios Stefanidis\AppData\Local\Programs\Python\Python311\Lib\site-packages\OpenSSL\SSL.py", line 1814, in _raise_ssl_error
    raise ZeroReturnError()
OpenSSL.SSL.ZeroReturnError
2023-11-12 13:13:04,982 - INFO - SLL Connection closed!
2023-11-12 13:13:05,598 - INFO - Handshake was successful!
2023-11-12 13:13:05,612 - INFO - Master Key and IV were successfully sent.
2023-11-12 13:13:05,831 - INFO - Encryption process completed for source file: .\..\archive\2023\ZW\ITSC\EHE.D\ZW.ITSC.00.EHN.D.2023.295.
2023-11-12 13:13:05,837 - INFO - Total Size of Data and Chunk Size were successfully sent.
2023-11-12 13:13:05,837 - INFO - Encrypted data were sent successfully.
2023-11-12 13:13:05,838 - INFO - Filename encrypted and sent successfully.
2023-11-12 13:13:06,007 - ERROR - TLS handshake error: 
Traceback (most recent call last):
  File "C:\Users\Marios Stefanidis\Documents\GitHub\Diploma-Thesis\code\slarchive-server\encryption\ssl_con.py", line 153, in run
    rejection_message = self.ssl_socket.recv(4096)
                        ^^^^^^^^^^^^^^^^^^^^^^^^^^
  File "C:\Users\Marios Stefanidis\AppData\Local\Programs\Python\Python311\Lib\site-packages\OpenSSL\SSL.py", line 2076, in recv
    self._raise_ssl_error(self._ssl, result)
  File "C:\Users\Marios Stefanidis\AppData\Local\Programs\Python\Python311\Lib\site-packages\OpenSSL\SSL.py", line 1814, in _raise_ssl_error
    raise ZeroReturnError()
OpenSSL.SSL.ZeroReturnError
2023-11-12 13:13:06,007 - INFO - SLL Connection closed!
2023-11-12 13:21:55,647 - ERROR - TLS handshake error: (10053, 'WSAECONNABORTED')
Traceback (most recent call last):
  File "C:\Users\Marios Stefanidis\Documents\GitHub\Diploma-Thesis\code\slarchive-server\encryption\ssl_con.py", line 147, in run
    self.establish_ssl_connection()
  File "C:\Users\Marios Stefanidis\Documents\GitHub\Diploma-Thesis\code\slarchive-server\encryption\ssl_con.py", line 38, in establish_ssl_connection
    self.ssl_socket.do_handshake()
  File "C:\Users\Marios Stefanidis\AppData\Local\Programs\Python\Python311\Lib\site-packages\OpenSSL\SSL.py", line 2202, in do_handshake
    self._raise_ssl_error(self._ssl, result)
  File "C:\Users\Marios Stefanidis\AppData\Local\Programs\Python\Python311\Lib\site-packages\OpenSSL\SSL.py", line 1827, in _raise_ssl_error
    raise SysCallError(errno, errorcode.get(errno))
OpenSSL.SSL.SysCallError: (10053, 'WSAECONNABORTED')
2023-11-12 13:21:56,217 - ERROR - TLS handshake error: (10053, 'WSAECONNABORTED')
Traceback (most recent call last):
  File "C:\Users\Marios Stefanidis\Documents\GitHub\Diploma-Thesis\code\slarchive-server\encryption\ssl_con.py", line 147, in run
    self.establish_ssl_connection()
  File "C:\Users\Marios Stefanidis\Documents\GitHub\Diploma-Thesis\code\slarchive-server\encryption\ssl_con.py", line 38, in establish_ssl_connection
    self.ssl_socket.do_handshake()
  File "C:\Users\Marios Stefanidis\AppData\Local\Programs\Python\Python311\Lib\site-packages\OpenSSL\SSL.py", line 2202, in do_handshake
    self._raise_ssl_error(self._ssl, result)
  File "C:\Users\Marios Stefanidis\AppData\Local\Programs\Python\Python311\Lib\site-packages\OpenSSL\SSL.py", line 1827, in _raise_ssl_error
    raise SysCallError(errno, errorcode.get(errno))
OpenSSL.SSL.SysCallError: (10053, 'WSAECONNABORTED')
2023-11-12 13:23:32,008 - ERROR - TLS handshake error: (10053, 'WSAECONNABORTED')
Traceback (most recent call last):
  File "C:\Users\Marios Stefanidis\Documents\GitHub\Diploma-Thesis\code\slarchive-server\encryption\ssl_con.py", line 147, in run
    self.establish_ssl_connection()
  File "C:\Users\Marios Stefanidis\Documents\GitHub\Diploma-Thesis\code\slarchive-server\encryption\ssl_con.py", line 38, in establish_ssl_connection
    self.ssl_socket.do_handshake()
  File "C:\Users\Marios Stefanidis\AppData\Local\Programs\Python\Python311\Lib\site-packages\OpenSSL\SSL.py", line 2202, in do_handshake
    self._raise_ssl_error(self._ssl, result)
  File "C:\Users\Marios Stefanidis\AppData\Local\Programs\Python\Python311\Lib\site-packages\OpenSSL\SSL.py", line 1827, in _raise_ssl_error
    raise SysCallError(errno, errorcode.get(errno))
OpenSSL.SSL.SysCallError: (10053, 'WSAECONNABORTED')
2023-11-12 13:23:32,581 - ERROR - TLS handshake error: (10053, 'WSAECONNABORTED')
Traceback (most recent call last):
  File "C:\Users\Marios Stefanidis\Documents\GitHub\Diploma-Thesis\code\slarchive-server\encryption\ssl_con.py", line 147, in run
    self.establish_ssl_connection()
  File "C:\Users\Marios Stefanidis\Documents\GitHub\Diploma-Thesis\code\slarchive-server\encryption\ssl_con.py", line 38, in establish_ssl_connection
    self.ssl_socket.do_handshake()
  File "C:\Users\Marios Stefanidis\AppData\Local\Programs\Python\Python311\Lib\site-packages\OpenSSL\SSL.py", line 2202, in do_handshake
    self._raise_ssl_error(self._ssl, result)
  File "C:\Users\Marios Stefanidis\AppData\Local\Programs\Python\Python311\Lib\site-packages\OpenSSL\SSL.py", line 1827, in _raise_ssl_error
    raise SysCallError(errno, errorcode.get(errno))
OpenSSL.SSL.SysCallError: (10053, 'WSAECONNABORTED')
2023-11-12 13:24:35,491 - ERROR - TLS handshake error: (10053, 'WSAECONNABORTED')
Traceback (most recent call last):
  File "C:\Users\Marios Stefanidis\Documents\GitHub\Diploma-Thesis\code\slarchive-server\encryption\ssl_con.py", line 147, in run
    self.establish_ssl_connection()
  File "C:\Users\Marios Stefanidis\Documents\GitHub\Diploma-Thesis\code\slarchive-server\encryption\ssl_con.py", line 38, in establish_ssl_connection
    self.ssl_socket.do_handshake()
  File "C:\Users\Marios Stefanidis\AppData\Local\Programs\Python\Python311\Lib\site-packages\OpenSSL\SSL.py", line 2202, in do_handshake
    self._raise_ssl_error(self._ssl, result)
  File "C:\Users\Marios Stefanidis\AppData\Local\Programs\Python\Python311\Lib\site-packages\OpenSSL\SSL.py", line 1827, in _raise_ssl_error
    raise SysCallError(errno, errorcode.get(errno))
OpenSSL.SSL.SysCallError: (10053, 'WSAECONNABORTED')
2023-11-12 13:24:35,492 - ERROR - Error during SSL socket shutdown: [('SSL routines', '', 'shutdown while in init')]
Traceback (most recent call last):
  File "C:\Users\Marios Stefanidis\Documents\GitHub\Diploma-Thesis\code\slarchive-server\encryption\ssl_con.py", line 169, in close
    self.ssl_socket.shutdown()
  File "C:\Users\Marios Stefanidis\AppData\Local\Programs\Python\Python311\Lib\site-packages\OpenSSL\SSL.py", line 2345, in shutdown
    self._raise_ssl_error(self._ssl, result)
  File "C:\Users\Marios Stefanidis\AppData\Local\Programs\Python\Python311\Lib\site-packages\OpenSSL\SSL.py", line 1843, in _raise_ssl_error
    _openssl_assert(
  File "C:\Users\Marios Stefanidis\AppData\Local\Programs\Python\Python311\Lib\site-packages\OpenSSL\_util.py", line 71, in openssl_assert
    exception_from_error_queue(error)
  File "C:\Users\Marios Stefanidis\AppData\Local\Programs\Python\Python311\Lib\site-packages\OpenSSL\_util.py", line 57, in exception_from_error_queue
    raise exception_type(errors)
OpenSSL.SSL.Error: [('SSL routines', '', 'shutdown while in init')]
2023-11-12 13:24:36,057 - ERROR - TLS handshake error: (10053, 'WSAECONNABORTED')
Traceback (most recent call last):
  File "C:\Users\Marios Stefanidis\Documents\GitHub\Diploma-Thesis\code\slarchive-server\encryption\ssl_con.py", line 147, in run
    self.establish_ssl_connection()
  File "C:\Users\Marios Stefanidis\Documents\GitHub\Diploma-Thesis\code\slarchive-server\encryption\ssl_con.py", line 38, in establish_ssl_connection
    self.ssl_socket.do_handshake()
  File "C:\Users\Marios Stefanidis\AppData\Local\Programs\Python\Python311\Lib\site-packages\OpenSSL\SSL.py", line 2202, in do_handshake
    self._raise_ssl_error(self._ssl, result)
  File "C:\Users\Marios Stefanidis\AppData\Local\Programs\Python\Python311\Lib\site-packages\OpenSSL\SSL.py", line 1827, in _raise_ssl_error
    raise SysCallError(errno, errorcode.get(errno))
OpenSSL.SSL.SysCallError: (10053, 'WSAECONNABORTED')
2023-11-12 13:24:36,057 - ERROR - Error during SSL socket shutdown: [('SSL routines', '', 'shutdown while in init')]
Traceback (most recent call last):
  File "C:\Users\Marios Stefanidis\Documents\GitHub\Diploma-Thesis\code\slarchive-server\encryption\ssl_con.py", line 169, in close
    self.ssl_socket.shutdown()
  File "C:\Users\Marios Stefanidis\AppData\Local\Programs\Python\Python311\Lib\site-packages\OpenSSL\SSL.py", line 2345, in shutdown
    self._raise_ssl_error(self._ssl, result)
  File "C:\Users\Marios Stefanidis\AppData\Local\Programs\Python\Python311\Lib\site-packages\OpenSSL\SSL.py", line 1843, in _raise_ssl_error
    _openssl_assert(
  File "C:\Users\Marios Stefanidis\AppData\Local\Programs\Python\Python311\Lib\site-packages\OpenSSL\_util.py", line 71, in openssl_assert
    exception_from_error_queue(error)
  File "C:\Users\Marios Stefanidis\AppData\Local\Programs\Python\Python311\Lib\site-packages\OpenSSL\_util.py", line 57, in exception_from_error_queue
    raise exception_type(errors)
OpenSSL.SSL.Error: [('SSL routines', '', 'shutdown while in init')]
2023-11-12 13:26:15,783 - ERROR - TLS handshake error: (10053, 'WSAECONNABORTED')
Traceback (most recent call last):
  File "C:\Users\Marios Stefanidis\Documents\GitHub\Diploma-Thesis\code\slarchive-server\encryption\ssl_con.py", line 147, in run
    self.establish_ssl_connection()
  File "C:\Users\Marios Stefanidis\Documents\GitHub\Diploma-Thesis\code\slarchive-server\encryption\ssl_con.py", line 38, in establish_ssl_connection
    self.ssl_socket.do_handshake()
  File "C:\Users\Marios Stefanidis\AppData\Local\Programs\Python\Python311\Lib\site-packages\OpenSSL\SSL.py", line 2202, in do_handshake
    self._raise_ssl_error(self._ssl, result)
  File "C:\Users\Marios Stefanidis\AppData\Local\Programs\Python\Python311\Lib\site-packages\OpenSSL\SSL.py", line 1827, in _raise_ssl_error
    raise SysCallError(errno, errorcode.get(errno))
OpenSSL.SSL.SysCallError: (10053, 'WSAECONNABORTED')
2023-11-12 13:26:16,344 - ERROR - TLS handshake error: (10053, 'WSAECONNABORTED')
Traceback (most recent call last):
  File "C:\Users\Marios Stefanidis\Documents\GitHub\Diploma-Thesis\code\slarchive-server\encryption\ssl_con.py", line 147, in run
    self.establish_ssl_connection()
  File "C:\Users\Marios Stefanidis\Documents\GitHub\Diploma-Thesis\code\slarchive-server\encryption\ssl_con.py", line 38, in establish_ssl_connection
    self.ssl_socket.do_handshake()
  File "C:\Users\Marios Stefanidis\AppData\Local\Programs\Python\Python311\Lib\site-packages\OpenSSL\SSL.py", line 2202, in do_handshake
    self._raise_ssl_error(self._ssl, result)
  File "C:\Users\Marios Stefanidis\AppData\Local\Programs\Python\Python311\Lib\site-packages\OpenSSL\SSL.py", line 1827, in _raise_ssl_error
    raise SysCallError(errno, errorcode.get(errno))
OpenSSL.SSL.SysCallError: (10053, 'WSAECONNABORTED')
2023-11-12 13:27:44,068 - ERROR - TLS handshake error: (10053, 'WSAECONNABORTED')
Traceback (most recent call last):
  File "C:\Users\Marios Stefanidis\Documents\GitHub\Diploma-Thesis\code\slarchive-server\encryption\ssl_con.py", line 147, in run
    self.establish_ssl_connection()
  File "C:\Users\Marios Stefanidis\Documents\GitHub\Diploma-Thesis\code\slarchive-server\encryption\ssl_con.py", line 38, in establish_ssl_connection
    self.ssl_socket.do_handshake()
  File "C:\Users\Marios Stefanidis\AppData\Local\Programs\Python\Python311\Lib\site-packages\OpenSSL\SSL.py", line 2202, in do_handshake
    self._raise_ssl_error(self._ssl, result)
  File "C:\Users\Marios Stefanidis\AppData\Local\Programs\Python\Python311\Lib\site-packages\OpenSSL\SSL.py", line 1827, in _raise_ssl_error
    raise SysCallError(errno, errorcode.get(errno))
OpenSSL.SSL.SysCallError: (10053, 'WSAECONNABORTED')
2023-11-12 13:27:44,068 - INFO - SSL Connection closed!
2023-11-12 13:27:44,621 - ERROR - TLS handshake error: (10053, 'WSAECONNABORTED')
Traceback (most recent call last):
  File "C:\Users\Marios Stefanidis\Documents\GitHub\Diploma-Thesis\code\slarchive-server\encryption\ssl_con.py", line 147, in run
    self.establish_ssl_connection()
  File "C:\Users\Marios Stefanidis\Documents\GitHub\Diploma-Thesis\code\slarchive-server\encryption\ssl_con.py", line 38, in establish_ssl_connection
    self.ssl_socket.do_handshake()
  File "C:\Users\Marios Stefanidis\AppData\Local\Programs\Python\Python311\Lib\site-packages\OpenSSL\SSL.py", line 2202, in do_handshake
    self._raise_ssl_error(self._ssl, result)
  File "C:\Users\Marios Stefanidis\AppData\Local\Programs\Python\Python311\Lib\site-packages\OpenSSL\SSL.py", line 1827, in _raise_ssl_error
    raise SysCallError(errno, errorcode.get(errno))
OpenSSL.SSL.SysCallError: (10053, 'WSAECONNABORTED')
2023-11-12 13:27:44,621 - INFO - SSL Connection closed!
2023-11-12 13:38:32,680 - ERROR - TLS handshake error: (10053, 'WSAECONNABORTED')
Traceback (most recent call last):
  File "C:\Users\Marios Stefanidis\Documents\GitHub\Diploma-Thesis\code\slarchive-server\encryption\ssl_con.py", line 147, in run
    self.establish_ssl_connection()
  File "C:\Users\Marios Stefanidis\Documents\GitHub\Diploma-Thesis\code\slarchive-server\encryption\ssl_con.py", line 38, in establish_ssl_connection
    self.ssl_socket.do_handshake()
  File "C:\Users\Marios Stefanidis\AppData\Local\Programs\Python\Python311\Lib\site-packages\OpenSSL\SSL.py", line 2202, in do_handshake
    self._raise_ssl_error(self._ssl, result)
  File "C:\Users\Marios Stefanidis\AppData\Local\Programs\Python\Python311\Lib\site-packages\OpenSSL\SSL.py", line 1827, in _raise_ssl_error
    raise SysCallError(errno, errorcode.get(errno))
OpenSSL.SSL.SysCallError: (10053, 'WSAECONNABORTED')
2023-11-12 13:38:32,681 - INFO - SSL Connection closed!
2023-11-12 13:38:33,267 - ERROR - TLS handshake error: (10053, 'WSAECONNABORTED')
Traceback (most recent call last):
  File "C:\Users\Marios Stefanidis\Documents\GitHub\Diploma-Thesis\code\slarchive-server\encryption\ssl_con.py", line 147, in run
    self.establish_ssl_connection()
  File "C:\Users\Marios Stefanidis\Documents\GitHub\Diploma-Thesis\code\slarchive-server\encryption\ssl_con.py", line 38, in establish_ssl_connection
    self.ssl_socket.do_handshake()
  File "C:\Users\Marios Stefanidis\AppData\Local\Programs\Python\Python311\Lib\site-packages\OpenSSL\SSL.py", line 2202, in do_handshake
    self._raise_ssl_error(self._ssl, result)
  File "C:\Users\Marios Stefanidis\AppData\Local\Programs\Python\Python311\Lib\site-packages\OpenSSL\SSL.py", line 1827, in _raise_ssl_error
    raise SysCallError(errno, errorcode.get(errno))
OpenSSL.SSL.SysCallError: (10053, 'WSAECONNABORTED')
2023-11-12 13:38:33,267 - INFO - SSL Connection closed!
2023-11-12 13:39:19,883 - INFO - Handshake was successful!
2023-11-12 13:39:19,894 - INFO - Master Key and IV were successfully sent.
2023-11-12 13:39:20,100 - INFO - Encryption process completed for source file: .\..\archive\2023\ZW\ITSC\EHE.D\ZW.ITSC.00.EHN.D.2023.295.
2023-11-12 13:39:20,102 - INFO - Total Size of Data and Chunk Size were successfully sent.
2023-11-12 13:39:20,102 - INFO - Encrypted data were sent successfully.
2023-11-12 13:39:20,103 - INFO - Filename encrypted and sent successfully.
2023-11-12 13:39:20,337 - ERROR - TLS handshake error: 
Traceback (most recent call last):
  File "C:\Users\Marios Stefanidis\Documents\GitHub\Diploma-Thesis\code\slarchive-server\encryption\ssl_con.py", line 153, in run
    rejection_message = self.ssl_socket.recv(4096)
                        ^^^^^^^^^^^^^^^^^^^^^^^^^^
  File "C:\Users\Marios Stefanidis\AppData\Local\Programs\Python\Python311\Lib\site-packages\OpenSSL\SSL.py", line 2076, in recv
    self._raise_ssl_error(self._ssl, result)
  File "C:\Users\Marios Stefanidis\AppData\Local\Programs\Python\Python311\Lib\site-packages\OpenSSL\SSL.py", line 1814, in _raise_ssl_error
    raise ZeroReturnError()
OpenSSL.SSL.ZeroReturnError
2023-11-12 13:39:20,338 - INFO - SSL Connection closed!
2023-11-12 13:39:21,097 - INFO - Handshake was successful!
2023-11-12 13:39:21,108 - INFO - Master Key and IV were successfully sent.
2023-11-12 13:39:21,305 - INFO - Encryption process completed for source file: .\..\archive\2023\ZW\ITSC\EHE.D\ZW.ITSC.00.EHN.D.2023.295.
2023-11-12 13:39:21,307 - INFO - Total Size of Data and Chunk Size were successfully sent.
2023-11-12 13:39:21,308 - INFO - Encrypted data were sent successfully.
2023-11-12 13:39:21,309 - INFO - Filename encrypted and sent successfully.
2023-11-12 13:39:21,482 - ERROR - TLS handshake error: 
Traceback (most recent call last):
  File "C:\Users\Marios Stefanidis\Documents\GitHub\Diploma-Thesis\code\slarchive-server\encryption\ssl_con.py", line 153, in run
    rejection_message = self.ssl_socket.recv(4096)
                        ^^^^^^^^^^^^^^^^^^^^^^^^^^
  File "C:\Users\Marios Stefanidis\AppData\Local\Programs\Python\Python311\Lib\site-packages\OpenSSL\SSL.py", line 2076, in recv
    self._raise_ssl_error(self._ssl, result)
  File "C:\Users\Marios Stefanidis\AppData\Local\Programs\Python\Python311\Lib\site-packages\OpenSSL\SSL.py", line 1814, in _raise_ssl_error
    raise ZeroReturnError()
OpenSSL.SSL.ZeroReturnError
2023-11-12 13:39:21,484 - INFO - SSL Connection closed!
2023-11-12 18:44:57,727 - INFO - Handshake was successful!
2023-11-12 18:44:57,755 - INFO - Master Key and IV were successfully sent.
2023-11-12 18:44:58,007 - INFO - Encryption process completed for source file: .\..\archive\2023\ZW\ITSC\EHN.D\ZW.ITSC.00.EHN.D.2023.295.
2023-11-12 18:44:58,007 - INFO - Total Size of Data and Chunk Size were successfully sent.
2023-11-12 18:44:58,007 - INFO - Encrypted data were sent successfully.
2023-11-12 18:44:58,007 - INFO - Filename encrypted and sent successfully.
2023-11-12 18:44:58,277 - ERROR - TLS handshake error: 
Traceback (most recent call last):
  File "C:\Users\Marios Stefanidis\Documents\GitHub\Diploma-Thesis\code\slarchive-server\encryption\ssl_con.py", line 153, in run
    rejection_message = self.ssl_socket.recv(4096)
                        ^^^^^^^^^^^^^^^^^^^^^^^^^^
  File "C:\Users\Marios Stefanidis\AppData\Local\Programs\Python\Python311\Lib\site-packages\OpenSSL\SSL.py", line 2076, in recv
    self._raise_ssl_error(self._ssl, result)
  File "C:\Users\Marios Stefanidis\AppData\Local\Programs\Python\Python311\Lib\site-packages\OpenSSL\SSL.py", line 1814, in _raise_ssl_error
    raise ZeroReturnError()
OpenSSL.SSL.ZeroReturnError
2023-11-12 18:44:58,278 - INFO - SSL Connection closed!
2023-11-12 18:45:01,060 - ERROR - TLS handshake error: (10054, 'WSAECONNRESET')
Traceback (most recent call last):
  File "C:\Users\Marios Stefanidis\Documents\GitHub\Diploma-Thesis\code\slarchive-server\encryption\ssl_con.py", line 147, in run
    self.establish_ssl_connection()
  File "C:\Users\Marios Stefanidis\Documents\GitHub\Diploma-Thesis\code\slarchive-server\encryption\ssl_con.py", line 38, in establish_ssl_connection
    self.ssl_socket.do_handshake()
  File "C:\Users\Marios Stefanidis\AppData\Local\Programs\Python\Python311\Lib\site-packages\OpenSSL\SSL.py", line 2202, in do_handshake
    self._raise_ssl_error(self._ssl, result)
  File "C:\Users\Marios Stefanidis\AppData\Local\Programs\Python\Python311\Lib\site-packages\OpenSSL\SSL.py", line 1827, in _raise_ssl_error
    raise SysCallError(errno, errorcode.get(errno))
OpenSSL.SSL.SysCallError: (10054, 'WSAECONNRESET')
2023-11-12 18:45:01,060 - INFO - SSL Connection closed!
2023-11-12 18:45:03,946 - ERROR - An error occurred: [WinError 10061] No connection could be made because the target machine actively refused it
Traceback (most recent call last):
  File "C:\Users\Marios Stefanidis\Documents\GitHub\Diploma-Thesis\code\slarchive-server\encryption\ssl_con.py", line 146, in run
    self.connect()
  File "C:\Users\Marios Stefanidis\Documents\GitHub\Diploma-Thesis\code\slarchive-server\encryption\ssl_con.py", line 26, in connect
    self.client_socket.connect(('127.0.0.1', 8443)) # Connect to the server
    ^^^^^^^^^^^^^^^^^^^^^^^^^^^^^^^^^^^^^^^^^^^^^^^
ConnectionRefusedError: [WinError 10061] No connection could be made because the target machine actively refused it
2023-11-12 18:45:03,947 - INFO - SSL Connection closed!
2023-11-12 18:48:30,378 - INFO - Handshake was successful!
2023-11-12 18:48:30,399 - INFO - Master Key and IV were successfully sent.
2023-11-12 18:48:30,632 - INFO - Encryption process completed for source file: .\..\archive\2023\ZW\ITSC\EHE.D\ZW.ITSC.00.EHN.D.2023.295.
2023-11-12 18:48:30,632 - INFO - Total Size of Data and Chunk Size were successfully sent.
2023-11-12 18:48:30,632 - INFO - Encrypted data were sent successfully.
2023-11-12 18:48:30,632 - INFO - Filename encrypted and sent successfully.
2023-11-12 18:48:30,941 - ERROR - TLS handshake error: 
Traceback (most recent call last):
  File "C:\Users\Marios Stefanidis\Documents\GitHub\Diploma-Thesis\code\slarchive-server\encryption\ssl_con.py", line 153, in run
    rejection_message = self.ssl_socket.recv(4096)
                        ^^^^^^^^^^^^^^^^^^^^^^^^^^
  File "C:\Users\Marios Stefanidis\AppData\Local\Programs\Python\Python311\Lib\site-packages\OpenSSL\SSL.py", line 2076, in recv
    self._raise_ssl_error(self._ssl, result)
  File "C:\Users\Marios Stefanidis\AppData\Local\Programs\Python\Python311\Lib\site-packages\OpenSSL\SSL.py", line 1814, in _raise_ssl_error
    raise ZeroReturnError()
OpenSSL.SSL.ZeroReturnError
2023-11-12 18:48:30,941 - INFO - SSL Connection closed!
2023-11-12 18:48:31,749 - INFO - Handshake was successful!
2023-11-12 18:48:31,764 - INFO - Master Key and IV were successfully sent.
2023-11-12 18:48:31,965 - INFO - Encryption process completed for source file: .\..\archive\2023\ZW\ITSC\EHE.D\ZW.ITSC.00.EHN.D.2023.295.
2023-11-12 18:48:31,965 - INFO - Total Size of Data and Chunk Size were successfully sent.
2023-11-12 18:48:31,965 - INFO - Encrypted data were sent successfully.
2023-11-12 18:48:31,965 - INFO - Filename encrypted and sent successfully.
2023-11-12 18:48:32,342 - ERROR - TLS handshake error: 
Traceback (most recent call last):
  File "C:\Users\Marios Stefanidis\Documents\GitHub\Diploma-Thesis\code\slarchive-server\encryption\ssl_con.py", line 153, in run
    rejection_message = self.ssl_socket.recv(4096)
                        ^^^^^^^^^^^^^^^^^^^^^^^^^^
  File "C:\Users\Marios Stefanidis\AppData\Local\Programs\Python\Python311\Lib\site-packages\OpenSSL\SSL.py", line 2076, in recv
    self._raise_ssl_error(self._ssl, result)
  File "C:\Users\Marios Stefanidis\AppData\Local\Programs\Python\Python311\Lib\site-packages\OpenSSL\SSL.py", line 1814, in _raise_ssl_error
    raise ZeroReturnError()
OpenSSL.SSL.ZeroReturnError
2023-11-12 18:48:32,342 - INFO - SSL Connection closed!
2023-11-13 21:57:40,765 - INFO - Handshake was successful!
2023-11-13 21:57:40,828 - INFO - Master Key and IV were successfully sent.
2023-11-13 21:57:41,237 - INFO - Encryption process completed for source file: .\..\archive\2023\ZW\ITSC\EHE.D\ZW.ITSC.00.EHE.D.2023.316.
2023-11-13 21:57:41,237 - INFO - Total Size of Data and Chunk Size were successfully sent.
2023-11-13 21:57:41,237 - INFO - Encrypted data were sent successfully.
2023-11-13 21:57:41,237 - INFO - Filename encrypted and sent successfully.
2023-11-13 21:57:41,474 - ERROR - TLS handshake error: 
Traceback (most recent call last):
  File "C:\Users\Marios Stefanidis\Documents\GitHub\Diploma-Thesis\code\slarchive-server\encryption\ssl_con.py", line 153, in run
    rejection_message = self.ssl_socket.recv(4096)
                        ^^^^^^^^^^^^^^^^^^^^^^^^^^
  File "C:\Users\Marios Stefanidis\AppData\Local\Programs\Python\Python311\Lib\site-packages\OpenSSL\SSL.py", line 2076, in recv
    self._raise_ssl_error(self._ssl, result)
  File "C:\Users\Marios Stefanidis\AppData\Local\Programs\Python\Python311\Lib\site-packages\OpenSSL\SSL.py", line 1814, in _raise_ssl_error
    raise ZeroReturnError()
OpenSSL.SSL.ZeroReturnError
2023-11-13 21:57:41,490 - INFO - SSL Connection closed!
2023-11-13 21:57:42,065 - INFO - Handshake was successful!
2023-11-13 21:57:42,065 - INFO - Master Key and IV were successfully sent.
2023-11-13 21:57:42,238 - INFO - Encryption process completed for source file: .\..\archive\2023\ZW\ITSC\EHE.D\ZW.ITSC.00.EHE.D.2023.316.
2023-11-13 21:57:42,238 - INFO - Total Size of Data and Chunk Size were successfully sent.
2023-11-13 21:57:42,254 - INFO - Encrypted data were sent successfully.
2023-11-13 21:57:42,254 - INFO - Filename encrypted and sent successfully.
2023-11-13 21:57:42,387 - ERROR - TLS handshake error: 
Traceback (most recent call last):
  File "C:\Users\Marios Stefanidis\Documents\GitHub\Diploma-Thesis\code\slarchive-server\encryption\ssl_con.py", line 153, in run
    rejection_message = self.ssl_socket.recv(4096)
                        ^^^^^^^^^^^^^^^^^^^^^^^^^^
  File "C:\Users\Marios Stefanidis\AppData\Local\Programs\Python\Python311\Lib\site-packages\OpenSSL\SSL.py", line 2076, in recv
    self._raise_ssl_error(self._ssl, result)
  File "C:\Users\Marios Stefanidis\AppData\Local\Programs\Python\Python311\Lib\site-packages\OpenSSL\SSL.py", line 1814, in _raise_ssl_error
    raise ZeroReturnError()
OpenSSL.SSL.ZeroReturnError
2023-11-13 21:57:42,387 - INFO - SSL Connection closed!
2023-11-13 21:57:42,936 - INFO - Handshake was successful!
2023-11-13 21:57:42,936 - INFO - Master Key and IV were successfully sent.
2023-11-13 21:57:43,124 - INFO - Encryption process completed for source file: .\..\archive\2023\ZW\ITSC\EHN.D\ZW.ITSC.00.EHN.D.2023.316.
2023-11-13 21:57:43,124 - INFO - Total Size of Data and Chunk Size were successfully sent.
2023-11-13 21:57:43,124 - INFO - Encrypted data were sent successfully.
2023-11-13 21:57:43,124 - INFO - Filename encrypted and sent successfully.
2023-11-13 21:57:43,249 - ERROR - TLS handshake error: 
Traceback (most recent call last):
  File "C:\Users\Marios Stefanidis\Documents\GitHub\Diploma-Thesis\code\slarchive-server\encryption\ssl_con.py", line 153, in run
    rejection_message = self.ssl_socket.recv(4096)
                        ^^^^^^^^^^^^^^^^^^^^^^^^^^
  File "C:\Users\Marios Stefanidis\AppData\Local\Programs\Python\Python311\Lib\site-packages\OpenSSL\SSL.py", line 2076, in recv
    self._raise_ssl_error(self._ssl, result)
  File "C:\Users\Marios Stefanidis\AppData\Local\Programs\Python\Python311\Lib\site-packages\OpenSSL\SSL.py", line 1814, in _raise_ssl_error
    raise ZeroReturnError()
OpenSSL.SSL.ZeroReturnError
2023-11-13 21:57:43,249 - INFO - SSL Connection closed!
2023-11-13 21:57:43,831 - INFO - Handshake was successful!
2023-11-13 21:57:43,846 - INFO - Master Key and IV were successfully sent.
2023-11-13 21:57:44,026 - INFO - Encryption process completed for source file: .\..\archive\2023\ZW\ITSC\EHZ.D\ZW.ITSC.00.EHZ.D.2023.316.
2023-11-13 21:57:44,026 - INFO - Total Size of Data and Chunk Size were successfully sent.
2023-11-13 21:57:44,026 - INFO - Encrypted data were sent successfully.
2023-11-13 21:57:44,026 - INFO - Filename encrypted and sent successfully.
2023-11-13 21:57:44,171 - ERROR - TLS handshake error: 
Traceback (most recent call last):
  File "C:\Users\Marios Stefanidis\Documents\GitHub\Diploma-Thesis\code\slarchive-server\encryption\ssl_con.py", line 153, in run
    rejection_message = self.ssl_socket.recv(4096)
                        ^^^^^^^^^^^^^^^^^^^^^^^^^^
  File "C:\Users\Marios Stefanidis\AppData\Local\Programs\Python\Python311\Lib\site-packages\OpenSSL\SSL.py", line 2076, in recv
    self._raise_ssl_error(self._ssl, result)
  File "C:\Users\Marios Stefanidis\AppData\Local\Programs\Python\Python311\Lib\site-packages\OpenSSL\SSL.py", line 1814, in _raise_ssl_error
    raise ZeroReturnError()
OpenSSL.SSL.ZeroReturnError
2023-11-13 21:57:44,171 - INFO - SSL Connection closed!
2023-11-14 22:52:47,541 - ERROR - TLS handshake error: (10054, 'WSAECONNRESET')
Traceback (most recent call last):
  File "C:\Users\Marios Stefanidis\Documents\GitHub\Diploma-Thesis\code\slarchive-server\encryption\ssl_con.py", line 147, in run
    self.establish_ssl_connection()
  File "C:\Users\Marios Stefanidis\Documents\GitHub\Diploma-Thesis\code\slarchive-server\encryption\ssl_con.py", line 38, in establish_ssl_connection
    self.ssl_socket.do_handshake()
  File "C:\Users\Marios Stefanidis\AppData\Local\Programs\Python\Python311\Lib\site-packages\OpenSSL\SSL.py", line 2202, in do_handshake
    self._raise_ssl_error(self._ssl, result)
  File "C:\Users\Marios Stefanidis\AppData\Local\Programs\Python\Python311\Lib\site-packages\OpenSSL\SSL.py", line 1827, in _raise_ssl_error
    raise SysCallError(errno, errorcode.get(errno))
OpenSSL.SSL.SysCallError: (10054, 'WSAECONNRESET')
2023-11-14 22:52:47,543 - INFO - SSL Connection closed!
2023-11-14 22:52:50,344 - ERROR - An error occurred: [WinError 10061] No connection could be made because the target machine actively refused it
Traceback (most recent call last):
  File "C:\Users\Marios Stefanidis\Documents\GitHub\Diploma-Thesis\code\slarchive-server\encryption\ssl_con.py", line 146, in run
    self.connect()
  File "C:\Users\Marios Stefanidis\Documents\GitHub\Diploma-Thesis\code\slarchive-server\encryption\ssl_con.py", line 26, in connect
    self.client_socket.connect(('127.0.0.1', 8443)) # Connect to the server
    ^^^^^^^^^^^^^^^^^^^^^^^^^^^^^^^^^^^^^^^^^^^^^^^
ConnectionRefusedError: [WinError 10061] No connection could be made because the target machine actively refused it
2023-11-14 22:52:50,344 - INFO - SSL Connection closed!
2023-11-14 22:52:52,989 - ERROR - An error occurred: [WinError 10061] No connection could be made because the target machine actively refused it
Traceback (most recent call last):
  File "C:\Users\Marios Stefanidis\Documents\GitHub\Diploma-Thesis\code\slarchive-server\encryption\ssl_con.py", line 146, in run
    self.connect()
  File "C:\Users\Marios Stefanidis\Documents\GitHub\Diploma-Thesis\code\slarchive-server\encryption\ssl_con.py", line 26, in connect
    self.client_socket.connect(('127.0.0.1', 8443)) # Connect to the server
    ^^^^^^^^^^^^^^^^^^^^^^^^^^^^^^^^^^^^^^^^^^^^^^^
ConnectionRefusedError: [WinError 10061] No connection could be made because the target machine actively refused it
2023-11-14 22:52:52,990 - INFO - SSL Connection closed!
2023-11-14 22:52:55,714 - ERROR - An error occurred: [WinError 10061] No connection could be made because the target machine actively refused it
Traceback (most recent call last):
  File "C:\Users\Marios Stefanidis\Documents\GitHub\Diploma-Thesis\code\slarchive-server\encryption\ssl_con.py", line 146, in run
    self.connect()
  File "C:\Users\Marios Stefanidis\Documents\GitHub\Diploma-Thesis\code\slarchive-server\encryption\ssl_con.py", line 26, in connect
    self.client_socket.connect(('127.0.0.1', 8443)) # Connect to the server
    ^^^^^^^^^^^^^^^^^^^^^^^^^^^^^^^^^^^^^^^^^^^^^^^
ConnectionRefusedError: [WinError 10061] No connection could be made because the target machine actively refused it
2023-11-14 22:52:55,715 - INFO - SSL Connection closed!
2023-11-14 22:56:58,636 - ERROR - TLS handshake error: (10054, 'WSAECONNRESET')
Traceback (most recent call last):
  File "C:\Users\Marios Stefanidis\Documents\GitHub\Diploma-Thesis\code\slarchive-server\encryption\ssl_con.py", line 147, in run
    self.establish_ssl_connection()
  File "C:\Users\Marios Stefanidis\Documents\GitHub\Diploma-Thesis\code\slarchive-server\encryption\ssl_con.py", line 38, in establish_ssl_connection
    self.ssl_socket.do_handshake()
  File "C:\Users\Marios Stefanidis\AppData\Local\Programs\Python\Python311\Lib\site-packages\OpenSSL\SSL.py", line 2202, in do_handshake
    self._raise_ssl_error(self._ssl, result)
  File "C:\Users\Marios Stefanidis\AppData\Local\Programs\Python\Python311\Lib\site-packages\OpenSSL\SSL.py", line 1827, in _raise_ssl_error
    raise SysCallError(errno, errorcode.get(errno))
OpenSSL.SSL.SysCallError: (10054, 'WSAECONNRESET')
2023-11-14 22:56:58,638 - INFO - SSL Connection closed!
2023-11-14 22:57:01,362 - ERROR - An error occurred: [WinError 10061] No connection could be made because the target machine actively refused it
Traceback (most recent call last):
  File "C:\Users\Marios Stefanidis\Documents\GitHub\Diploma-Thesis\code\slarchive-server\encryption\ssl_con.py", line 146, in run
    self.connect()
  File "C:\Users\Marios Stefanidis\Documents\GitHub\Diploma-Thesis\code\slarchive-server\encryption\ssl_con.py", line 26, in connect
    self.client_socket.connect(('127.0.0.1', 8443)) # Connect to the server
    ^^^^^^^^^^^^^^^^^^^^^^^^^^^^^^^^^^^^^^^^^^^^^^^
ConnectionRefusedError: [WinError 10061] No connection could be made because the target machine actively refused it
2023-11-14 22:57:01,362 - INFO - SSL Connection closed!
2023-11-14 22:57:04,103 - ERROR - An error occurred: [WinError 10061] No connection could be made because the target machine actively refused it
Traceback (most recent call last):
  File "C:\Users\Marios Stefanidis\Documents\GitHub\Diploma-Thesis\code\slarchive-server\encryption\ssl_con.py", line 146, in run
    self.connect()
  File "C:\Users\Marios Stefanidis\Documents\GitHub\Diploma-Thesis\code\slarchive-server\encryption\ssl_con.py", line 26, in connect
    self.client_socket.connect(('127.0.0.1', 8443)) # Connect to the server
    ^^^^^^^^^^^^^^^^^^^^^^^^^^^^^^^^^^^^^^^^^^^^^^^
ConnectionRefusedError: [WinError 10061] No connection could be made because the target machine actively refused it
2023-11-14 22:57:04,105 - INFO - SSL Connection closed!
2023-11-14 22:57:06,811 - ERROR - An error occurred: [WinError 10061] No connection could be made because the target machine actively refused it
Traceback (most recent call last):
  File "C:\Users\Marios Stefanidis\Documents\GitHub\Diploma-Thesis\code\slarchive-server\encryption\ssl_con.py", line 146, in run
    self.connect()
  File "C:\Users\Marios Stefanidis\Documents\GitHub\Diploma-Thesis\code\slarchive-server\encryption\ssl_con.py", line 26, in connect
    self.client_socket.connect(('127.0.0.1', 8443)) # Connect to the server
    ^^^^^^^^^^^^^^^^^^^^^^^^^^^^^^^^^^^^^^^^^^^^^^^
ConnectionRefusedError: [WinError 10061] No connection could be made because the target machine actively refused it
2023-11-14 22:57:06,811 - INFO - SSL Connection closed!
2023-11-14 22:59:17,456 - ERROR - TLS handshake error: (10054, 'WSAECONNRESET')
Traceback (most recent call last):
  File "C:\Users\Marios Stefanidis\Documents\GitHub\Diploma-Thesis\code\slarchive-server\encryption\ssl_con.py", line 147, in run
    self.establish_ssl_connection()
  File "C:\Users\Marios Stefanidis\Documents\GitHub\Diploma-Thesis\code\slarchive-server\encryption\ssl_con.py", line 38, in establish_ssl_connection
    self.ssl_socket.do_handshake()
  File "C:\Users\Marios Stefanidis\AppData\Local\Programs\Python\Python311\Lib\site-packages\OpenSSL\SSL.py", line 2202, in do_handshake
    self._raise_ssl_error(self._ssl, result)
  File "C:\Users\Marios Stefanidis\AppData\Local\Programs\Python\Python311\Lib\site-packages\OpenSSL\SSL.py", line 1827, in _raise_ssl_error
    raise SysCallError(errno, errorcode.get(errno))
OpenSSL.SSL.SysCallError: (10054, 'WSAECONNRESET')
2023-11-14 22:59:17,457 - INFO - SSL Connection closed!
2023-11-14 22:59:20,126 - ERROR - An error occurred: [WinError 10061] No connection could be made because the target machine actively refused it
Traceback (most recent call last):
  File "C:\Users\Marios Stefanidis\Documents\GitHub\Diploma-Thesis\code\slarchive-server\encryption\ssl_con.py", line 146, in run
    self.connect()
  File "C:\Users\Marios Stefanidis\Documents\GitHub\Diploma-Thesis\code\slarchive-server\encryption\ssl_con.py", line 26, in connect
    self.client_socket.connect(('127.0.0.1', 8443)) # Connect to the server
    ^^^^^^^^^^^^^^^^^^^^^^^^^^^^^^^^^^^^^^^^^^^^^^^
ConnectionRefusedError: [WinError 10061] No connection could be made because the target machine actively refused it
2023-11-14 22:59:20,127 - INFO - SSL Connection closed!
2023-11-14 22:59:22,960 - ERROR - An error occurred: [WinError 10061] No connection could be made because the target machine actively refused it
Traceback (most recent call last):
  File "C:\Users\Marios Stefanidis\Documents\GitHub\Diploma-Thesis\code\slarchive-server\encryption\ssl_con.py", line 146, in run
    self.connect()
  File "C:\Users\Marios Stefanidis\Documents\GitHub\Diploma-Thesis\code\slarchive-server\encryption\ssl_con.py", line 26, in connect
    self.client_socket.connect(('127.0.0.1', 8443)) # Connect to the server
    ^^^^^^^^^^^^^^^^^^^^^^^^^^^^^^^^^^^^^^^^^^^^^^^
ConnectionRefusedError: [WinError 10061] No connection could be made because the target machine actively refused it
2023-11-14 22:59:22,960 - INFO - SSL Connection closed!
2023-11-14 22:59:25,751 - ERROR - An error occurred: [WinError 10061] No connection could be made because the target machine actively refused it
Traceback (most recent call last):
  File "C:\Users\Marios Stefanidis\Documents\GitHub\Diploma-Thesis\code\slarchive-server\encryption\ssl_con.py", line 146, in run
    self.connect()
  File "C:\Users\Marios Stefanidis\Documents\GitHub\Diploma-Thesis\code\slarchive-server\encryption\ssl_con.py", line 26, in connect
    self.client_socket.connect(('127.0.0.1', 8443)) # Connect to the server
    ^^^^^^^^^^^^^^^^^^^^^^^^^^^^^^^^^^^^^^^^^^^^^^^
ConnectionRefusedError: [WinError 10061] No connection could be made because the target machine actively refused it
2023-11-14 22:59:25,751 - INFO - SSL Connection closed!
2023-11-14 23:01:00,109 - ERROR - TLS handshake error: (10054, 'WSAECONNRESET')
Traceback (most recent call last):
  File "C:\Users\Marios Stefanidis\Documents\GitHub\Diploma-Thesis\code\slarchive-server\encryption\ssl_con.py", line 147, in run
    self.establish_ssl_connection()
  File "C:\Users\Marios Stefanidis\Documents\GitHub\Diploma-Thesis\code\slarchive-server\encryption\ssl_con.py", line 38, in establish_ssl_connection
    self.ssl_socket.do_handshake()
  File "C:\Users\Marios Stefanidis\AppData\Local\Programs\Python\Python311\Lib\site-packages\OpenSSL\SSL.py", line 2202, in do_handshake
    self._raise_ssl_error(self._ssl, result)
  File "C:\Users\Marios Stefanidis\AppData\Local\Programs\Python\Python311\Lib\site-packages\OpenSSL\SSL.py", line 1827, in _raise_ssl_error
    raise SysCallError(errno, errorcode.get(errno))
OpenSSL.SSL.SysCallError: (10054, 'WSAECONNRESET')
2023-11-14 23:01:00,110 - INFO - SSL Connection closed!
2023-11-14 23:01:02,873 - ERROR - An error occurred: [WinError 10061] No connection could be made because the target machine actively refused it
Traceback (most recent call last):
  File "C:\Users\Marios Stefanidis\Documents\GitHub\Diploma-Thesis\code\slarchive-server\encryption\ssl_con.py", line 146, in run
    self.connect()
  File "C:\Users\Marios Stefanidis\Documents\GitHub\Diploma-Thesis\code\slarchive-server\encryption\ssl_con.py", line 26, in connect
    self.client_socket.connect(('127.0.0.1', 8443)) # Connect to the server
    ^^^^^^^^^^^^^^^^^^^^^^^^^^^^^^^^^^^^^^^^^^^^^^^
ConnectionRefusedError: [WinError 10061] No connection could be made because the target machine actively refused it
2023-11-14 23:01:02,874 - INFO - SSL Connection closed!
2023-11-14 23:01:05,613 - ERROR - An error occurred: [WinError 10061] No connection could be made because the target machine actively refused it
Traceback (most recent call last):
  File "C:\Users\Marios Stefanidis\Documents\GitHub\Diploma-Thesis\code\slarchive-server\encryption\ssl_con.py", line 146, in run
    self.connect()
  File "C:\Users\Marios Stefanidis\Documents\GitHub\Diploma-Thesis\code\slarchive-server\encryption\ssl_con.py", line 26, in connect
    self.client_socket.connect(('127.0.0.1', 8443)) # Connect to the server
    ^^^^^^^^^^^^^^^^^^^^^^^^^^^^^^^^^^^^^^^^^^^^^^^
ConnectionRefusedError: [WinError 10061] No connection could be made because the target machine actively refused it
2023-11-14 23:01:05,613 - INFO - SSL Connection closed!
2023-11-14 23:01:08,402 - ERROR - An error occurred: [WinError 10061] No connection could be made because the target machine actively refused it
Traceback (most recent call last):
  File "C:\Users\Marios Stefanidis\Documents\GitHub\Diploma-Thesis\code\slarchive-server\encryption\ssl_con.py", line 146, in run
    self.connect()
  File "C:\Users\Marios Stefanidis\Documents\GitHub\Diploma-Thesis\code\slarchive-server\encryption\ssl_con.py", line 26, in connect
    self.client_socket.connect(('127.0.0.1', 8443)) # Connect to the server
    ^^^^^^^^^^^^^^^^^^^^^^^^^^^^^^^^^^^^^^^^^^^^^^^
ConnectionRefusedError: [WinError 10061] No connection could be made because the target machine actively refused it
2023-11-14 23:01:08,404 - INFO - SSL Connection closed!
2023-11-14 23:03:35,102 - ERROR - TLS handshake error: (10054, 'WSAECONNRESET')
Traceback (most recent call last):
  File "C:\Users\Marios Stefanidis\Documents\GitHub\Diploma-Thesis\code\slarchive-server\encryption\ssl_con.py", line 147, in run
    self.establish_ssl_connection()
  File "C:\Users\Marios Stefanidis\Documents\GitHub\Diploma-Thesis\code\slarchive-server\encryption\ssl_con.py", line 38, in establish_ssl_connection
    self.ssl_socket.do_handshake()
  File "C:\Users\Marios Stefanidis\AppData\Local\Programs\Python\Python311\Lib\site-packages\OpenSSL\SSL.py", line 2202, in do_handshake
    self._raise_ssl_error(self._ssl, result)
  File "C:\Users\Marios Stefanidis\AppData\Local\Programs\Python\Python311\Lib\site-packages\OpenSSL\SSL.py", line 1827, in _raise_ssl_error
    raise SysCallError(errno, errorcode.get(errno))
OpenSSL.SSL.SysCallError: (10054, 'WSAECONNRESET')
2023-11-14 23:03:35,105 - INFO - SSL Connection closed!
2023-11-14 23:03:37,828 - ERROR - An error occurred: [WinError 10061] No connection could be made because the target machine actively refused it
Traceback (most recent call last):
  File "C:\Users\Marios Stefanidis\Documents\GitHub\Diploma-Thesis\code\slarchive-server\encryption\ssl_con.py", line 146, in run
    self.connect()
  File "C:\Users\Marios Stefanidis\Documents\GitHub\Diploma-Thesis\code\slarchive-server\encryption\ssl_con.py", line 26, in connect
    self.client_socket.connect(('127.0.0.1', 8443)) # Connect to the server
    ^^^^^^^^^^^^^^^^^^^^^^^^^^^^^^^^^^^^^^^^^^^^^^^
ConnectionRefusedError: [WinError 10061] No connection could be made because the target machine actively refused it
2023-11-14 23:03:37,828 - INFO - SSL Connection closed!
2023-11-14 23:03:40,537 - ERROR - An error occurred: [WinError 10061] No connection could be made because the target machine actively refused it
Traceback (most recent call last):
  File "C:\Users\Marios Stefanidis\Documents\GitHub\Diploma-Thesis\code\slarchive-server\encryption\ssl_con.py", line 146, in run
    self.connect()
  File "C:\Users\Marios Stefanidis\Documents\GitHub\Diploma-Thesis\code\slarchive-server\encryption\ssl_con.py", line 26, in connect
    self.client_socket.connect(('127.0.0.1', 8443)) # Connect to the server
    ^^^^^^^^^^^^^^^^^^^^^^^^^^^^^^^^^^^^^^^^^^^^^^^
ConnectionRefusedError: [WinError 10061] No connection could be made because the target machine actively refused it
2023-11-14 23:03:40,539 - INFO - SSL Connection closed!
2023-11-14 23:03:43,395 - ERROR - An error occurred: [WinError 10061] No connection could be made because the target machine actively refused it
Traceback (most recent call last):
  File "C:\Users\Marios Stefanidis\Documents\GitHub\Diploma-Thesis\code\slarchive-server\encryption\ssl_con.py", line 146, in run
    self.connect()
  File "C:\Users\Marios Stefanidis\Documents\GitHub\Diploma-Thesis\code\slarchive-server\encryption\ssl_con.py", line 26, in connect
    self.client_socket.connect(('127.0.0.1', 8443)) # Connect to the server
    ^^^^^^^^^^^^^^^^^^^^^^^^^^^^^^^^^^^^^^^^^^^^^^^
ConnectionRefusedError: [WinError 10061] No connection could be made because the target machine actively refused it
2023-11-14 23:03:43,395 - INFO - SSL Connection closed!
2023-11-14 23:10:35,014 - ERROR - TLS handshake error: (10054, 'WSAECONNRESET')
Traceback (most recent call last):
  File "C:\Users\Marios Stefanidis\Documents\GitHub\Diploma-Thesis\code\slarchive-server\encryption\ssl_con.py", line 147, in run
    self.establish_ssl_connection()
  File "C:\Users\Marios Stefanidis\Documents\GitHub\Diploma-Thesis\code\slarchive-server\encryption\ssl_con.py", line 38, in establish_ssl_connection
    self.ssl_socket.do_handshake()
  File "C:\Users\Marios Stefanidis\AppData\Local\Programs\Python\Python311\Lib\site-packages\OpenSSL\SSL.py", line 2202, in do_handshake
    self._raise_ssl_error(self._ssl, result)
  File "C:\Users\Marios Stefanidis\AppData\Local\Programs\Python\Python311\Lib\site-packages\OpenSSL\SSL.py", line 1827, in _raise_ssl_error
    raise SysCallError(errno, errorcode.get(errno))
OpenSSL.SSL.SysCallError: (10054, 'WSAECONNRESET')
2023-11-14 23:10:35,023 - INFO - SSL Connection closed!
2023-11-14 23:11:42,475 - ERROR - TLS handshake error: (10054, 'WSAECONNRESET')
Traceback (most recent call last):
  File "C:\Users\Marios Stefanidis\Documents\GitHub\Diploma-Thesis\code\slarchive-server\encryption\ssl_con.py", line 147, in run
    self.establish_ssl_connection()
  File "C:\Users\Marios Stefanidis\Documents\GitHub\Diploma-Thesis\code\slarchive-server\encryption\ssl_con.py", line 38, in establish_ssl_connection
    self.ssl_socket.do_handshake()
  File "C:\Users\Marios Stefanidis\AppData\Local\Programs\Python\Python311\Lib\site-packages\OpenSSL\SSL.py", line 2202, in do_handshake
    self._raise_ssl_error(self._ssl, result)
  File "C:\Users\Marios Stefanidis\AppData\Local\Programs\Python\Python311\Lib\site-packages\OpenSSL\SSL.py", line 1827, in _raise_ssl_error
    raise SysCallError(errno, errorcode.get(errno))
OpenSSL.SSL.SysCallError: (10054, 'WSAECONNRESET')
2023-11-14 23:11:42,475 - INFO - SSL Connection closed!
2023-11-14 23:11:45,094 - ERROR - An error occurred: [WinError 10061] No connection could be made because the target machine actively refused it
Traceback (most recent call last):
  File "C:\Users\Marios Stefanidis\Documents\GitHub\Diploma-Thesis\code\slarchive-server\encryption\ssl_con.py", line 146, in run
    self.connect()
  File "C:\Users\Marios Stefanidis\Documents\GitHub\Diploma-Thesis\code\slarchive-server\encryption\ssl_con.py", line 26, in connect
    self.client_socket.connect(('127.0.0.1', 8443)) # Connect to the server
    ^^^^^^^^^^^^^^^^^^^^^^^^^^^^^^^^^^^^^^^^^^^^^^^
ConnectionRefusedError: [WinError 10061] No connection could be made because the target machine actively refused it
2023-11-14 23:11:45,095 - INFO - SSL Connection closed!
2023-11-14 23:11:47,945 - ERROR - An error occurred: [WinError 10061] No connection could be made because the target machine actively refused it
Traceback (most recent call last):
  File "C:\Users\Marios Stefanidis\Documents\GitHub\Diploma-Thesis\code\slarchive-server\encryption\ssl_con.py", line 146, in run
    self.connect()
  File "C:\Users\Marios Stefanidis\Documents\GitHub\Diploma-Thesis\code\slarchive-server\encryption\ssl_con.py", line 26, in connect
    self.client_socket.connect(('127.0.0.1', 8443)) # Connect to the server
    ^^^^^^^^^^^^^^^^^^^^^^^^^^^^^^^^^^^^^^^^^^^^^^^
ConnectionRefusedError: [WinError 10061] No connection could be made because the target machine actively refused it
2023-11-14 23:11:47,945 - INFO - SSL Connection closed!
2023-11-14 23:11:50,676 - ERROR - An error occurred: [WinError 10061] No connection could be made because the target machine actively refused it
Traceback (most recent call last):
  File "C:\Users\Marios Stefanidis\Documents\GitHub\Diploma-Thesis\code\slarchive-server\encryption\ssl_con.py", line 146, in run
    self.connect()
  File "C:\Users\Marios Stefanidis\Documents\GitHub\Diploma-Thesis\code\slarchive-server\encryption\ssl_con.py", line 26, in connect
    self.client_socket.connect(('127.0.0.1', 8443)) # Connect to the server
    ^^^^^^^^^^^^^^^^^^^^^^^^^^^^^^^^^^^^^^^^^^^^^^^
ConnectionRefusedError: [WinError 10061] No connection could be made because the target machine actively refused it
2023-11-14 23:11:50,676 - INFO - SSL Connection closed!
2023-11-15 00:13:53,014 - ERROR - TLS handshake error: (10054, 'WSAECONNRESET')
Traceback (most recent call last):
  File "C:\Users\Marios Stefanidis\Documents\GitHub\Diploma-Thesis\code\slarchive-server\encryption\ssl_con.py", line 147, in run
    self.establish_ssl_connection()
  File "C:\Users\Marios Stefanidis\Documents\GitHub\Diploma-Thesis\code\slarchive-server\encryption\ssl_con.py", line 38, in establish_ssl_connection
    self.ssl_socket.do_handshake()
  File "C:\Users\Marios Stefanidis\AppData\Local\Programs\Python\Python311\Lib\site-packages\OpenSSL\SSL.py", line 2202, in do_handshake
    self._raise_ssl_error(self._ssl, result)
  File "C:\Users\Marios Stefanidis\AppData\Local\Programs\Python\Python311\Lib\site-packages\OpenSSL\SSL.py", line 1827, in _raise_ssl_error
    raise SysCallError(errno, errorcode.get(errno))
OpenSSL.SSL.SysCallError: (10054, 'WSAECONNRESET')
2023-11-15 00:13:53,014 - INFO - SSL Connection closed!
2023-11-15 00:17:15,595 - ERROR - TLS handshake error: (10054, 'WSAECONNRESET')
Traceback (most recent call last):
  File "C:\Users\Marios Stefanidis\Documents\GitHub\Diploma-Thesis\code\slarchive-server\encryption\ssl_con.py", line 147, in run
    self.establish_ssl_connection()
  File "C:\Users\Marios Stefanidis\Documents\GitHub\Diploma-Thesis\code\slarchive-server\encryption\ssl_con.py", line 38, in establish_ssl_connection
    self.ssl_socket.do_handshake()
  File "C:\Users\Marios Stefanidis\AppData\Local\Programs\Python\Python311\Lib\site-packages\OpenSSL\SSL.py", line 2202, in do_handshake
    self._raise_ssl_error(self._ssl, result)
  File "C:\Users\Marios Stefanidis\AppData\Local\Programs\Python\Python311\Lib\site-packages\OpenSSL\SSL.py", line 1827, in _raise_ssl_error
    raise SysCallError(errno, errorcode.get(errno))
OpenSSL.SSL.SysCallError: (10054, 'WSAECONNRESET')
2023-11-15 00:17:15,597 - INFO - SSL Connection closed!
2023-11-15 00:21:20,117 - ERROR - TLS handshake error: (10054, 'WSAECONNRESET')
Traceback (most recent call last):
  File "C:\Users\Marios Stefanidis\Documents\GitHub\Diploma-Thesis\code\slarchive-server\encryption\ssl_con.py", line 147, in run
    self.establish_ssl_connection()
  File "C:\Users\Marios Stefanidis\Documents\GitHub\Diploma-Thesis\code\slarchive-server\encryption\ssl_con.py", line 38, in establish_ssl_connection
    self.ssl_socket.do_handshake()
  File "C:\Users\Marios Stefanidis\AppData\Local\Programs\Python\Python311\Lib\site-packages\OpenSSL\SSL.py", line 2202, in do_handshake
    self._raise_ssl_error(self._ssl, result)
  File "C:\Users\Marios Stefanidis\AppData\Local\Programs\Python\Python311\Lib\site-packages\OpenSSL\SSL.py", line 1827, in _raise_ssl_error
    raise SysCallError(errno, errorcode.get(errno))
OpenSSL.SSL.SysCallError: (10054, 'WSAECONNRESET')
2023-11-15 00:21:20,118 - INFO - SSL Connection closed!
2023-11-15 00:21:22,698 - ERROR - An error occurred: [WinError 10061] No connection could be made because the target machine actively refused it
Traceback (most recent call last):
  File "C:\Users\Marios Stefanidis\Documents\GitHub\Diploma-Thesis\code\slarchive-server\encryption\ssl_con.py", line 146, in run
    self.connect()
  File "C:\Users\Marios Stefanidis\Documents\GitHub\Diploma-Thesis\code\slarchive-server\encryption\ssl_con.py", line 26, in connect
    self.client_socket.connect(('127.0.0.1', 8443)) # Connect to the server
    ^^^^^^^^^^^^^^^^^^^^^^^^^^^^^^^^^^^^^^^^^^^^^^^
ConnectionRefusedError: [WinError 10061] No connection could be made because the target machine actively refused it
2023-11-15 00:21:22,699 - INFO - SSL Connection closed!
2023-11-15 00:21:25,362 - ERROR - An error occurred: [WinError 10061] No connection could be made because the target machine actively refused it
Traceback (most recent call last):
  File "C:\Users\Marios Stefanidis\Documents\GitHub\Diploma-Thesis\code\slarchive-server\encryption\ssl_con.py", line 146, in run
    self.connect()
  File "C:\Users\Marios Stefanidis\Documents\GitHub\Diploma-Thesis\code\slarchive-server\encryption\ssl_con.py", line 26, in connect
    self.client_socket.connect(('127.0.0.1', 8443)) # Connect to the server
    ^^^^^^^^^^^^^^^^^^^^^^^^^^^^^^^^^^^^^^^^^^^^^^^
ConnectionRefusedError: [WinError 10061] No connection could be made because the target machine actively refused it
2023-11-15 00:21:25,362 - INFO - SSL Connection closed!
2023-11-15 00:21:28,007 - ERROR - An error occurred: [WinError 10061] No connection could be made because the target machine actively refused it
Traceback (most recent call last):
  File "C:\Users\Marios Stefanidis\Documents\GitHub\Diploma-Thesis\code\slarchive-server\encryption\ssl_con.py", line 146, in run
    self.connect()
  File "C:\Users\Marios Stefanidis\Documents\GitHub\Diploma-Thesis\code\slarchive-server\encryption\ssl_con.py", line 26, in connect
    self.client_socket.connect(('127.0.0.1', 8443)) # Connect to the server
    ^^^^^^^^^^^^^^^^^^^^^^^^^^^^^^^^^^^^^^^^^^^^^^^
ConnectionRefusedError: [WinError 10061] No connection could be made because the target machine actively refused it
2023-11-15 00:21:28,008 - INFO - SSL Connection closed!
2023-11-15 00:30:02,487 - ERROR - TLS handshake error: (10054, 'WSAECONNRESET')
Traceback (most recent call last):
  File "C:\Users\Marios Stefanidis\Documents\GitHub\Diploma-Thesis\code\slarchive-server\encryption\ssl_con.py", line 147, in run
    self.establish_ssl_connection()
  File "C:\Users\Marios Stefanidis\Documents\GitHub\Diploma-Thesis\code\slarchive-server\encryption\ssl_con.py", line 38, in establish_ssl_connection
    self.ssl_socket.do_handshake()
  File "C:\Users\Marios Stefanidis\AppData\Local\Programs\Python\Python311\Lib\site-packages\OpenSSL\SSL.py", line 2202, in do_handshake
    self._raise_ssl_error(self._ssl, result)
  File "C:\Users\Marios Stefanidis\AppData\Local\Programs\Python\Python311\Lib\site-packages\OpenSSL\SSL.py", line 1827, in _raise_ssl_error
    raise SysCallError(errno, errorcode.get(errno))
OpenSSL.SSL.SysCallError: (10054, 'WSAECONNRESET')
2023-11-15 00:30:02,490 - INFO - SSL Connection closed!
2023-11-15 17:24:07,312 - INFO - Handshake was successful!
2023-11-15 17:24:07,337 - INFO - Master Key and IV were successfully sent.
2023-11-15 17:24:07,563 - INFO - Encryption process completed for source file: .\..\archive\2023\ZW\ITSC\EHE.D\ZW.ITSC.00.EHE.D.2023.316.
2023-11-15 17:24:07,565 - INFO - Total Size of Data and Chunk Size were successfully sent.
2023-11-15 17:24:07,565 - INFO - Encrypted data were sent successfully.
2023-11-15 17:24:07,566 - INFO - Filename encrypted and sent successfully.
2023-11-15 17:24:07,779 - ERROR - TLS handshake error: 
Traceback (most recent call last):
  File "C:\Users\Marios Stefanidis\Documents\GitHub\Diploma-Thesis\code\slarchive-server\encryption\ssl_con.py", line 153, in run
    rejection_message = self.ssl_socket.recv(4096)
                        ^^^^^^^^^^^^^^^^^^^^^^^^^^
  File "C:\Users\Marios Stefanidis\AppData\Local\Programs\Python\Python311\Lib\site-packages\OpenSSL\SSL.py", line 2076, in recv
    self._raise_ssl_error(self._ssl, result)
  File "C:\Users\Marios Stefanidis\AppData\Local\Programs\Python\Python311\Lib\site-packages\OpenSSL\SSL.py", line 1814, in _raise_ssl_error
    raise ZeroReturnError()
OpenSSL.SSL.ZeroReturnError
2023-11-15 17:24:07,782 - INFO - SSL Connection closed!
2023-11-15 17:24:08,479 - INFO - Handshake was successful!
2023-11-15 17:24:08,494 - INFO - Master Key and IV were successfully sent.
2023-11-15 17:24:08,685 - INFO - Encryption process completed for source file: .\..\archive\2023\ZW\ITSC\EHE.D\ZW.ITSC.00.EHE.D.2023.316.
2023-11-15 17:24:08,687 - INFO - Total Size of Data and Chunk Size were successfully sent.
2023-11-15 17:24:08,687 - INFO - Encrypted data were sent successfully.
2023-11-15 17:24:08,688 - INFO - Filename encrypted and sent successfully.
2023-11-15 17:24:08,816 - ERROR - TLS handshake error: 
Traceback (most recent call last):
  File "C:\Users\Marios Stefanidis\Documents\GitHub\Diploma-Thesis\code\slarchive-server\encryption\ssl_con.py", line 153, in run
    rejection_message = self.ssl_socket.recv(4096)
                        ^^^^^^^^^^^^^^^^^^^^^^^^^^
  File "C:\Users\Marios Stefanidis\AppData\Local\Programs\Python\Python311\Lib\site-packages\OpenSSL\SSL.py", line 2076, in recv
    self._raise_ssl_error(self._ssl, result)
  File "C:\Users\Marios Stefanidis\AppData\Local\Programs\Python\Python311\Lib\site-packages\OpenSSL\SSL.py", line 1814, in _raise_ssl_error
    raise ZeroReturnError()
OpenSSL.SSL.ZeroReturnError
2023-11-15 17:24:08,818 - INFO - SSL Connection closed!
2023-11-15 17:24:09,558 - INFO - Handshake was successful!
2023-11-15 17:24:09,573 - INFO - Master Key and IV were successfully sent.
2023-11-15 17:24:09,760 - INFO - Encryption process completed for source file: .\..\archive\2023\ZW\ITSC\EHN.D\ZW.ITSC.00.EHN.D.2023.316.
2023-11-15 17:24:09,761 - INFO - Total Size of Data and Chunk Size were successfully sent.
2023-11-15 17:24:09,763 - INFO - Encrypted data were sent successfully.
2023-11-15 17:24:09,764 - INFO - Filename encrypted and sent successfully.
2023-11-15 17:24:09,887 - ERROR - TLS handshake error: 
Traceback (most recent call last):
  File "C:\Users\Marios Stefanidis\Documents\GitHub\Diploma-Thesis\code\slarchive-server\encryption\ssl_con.py", line 153, in run
    rejection_message = self.ssl_socket.recv(4096)
                        ^^^^^^^^^^^^^^^^^^^^^^^^^^
  File "C:\Users\Marios Stefanidis\AppData\Local\Programs\Python\Python311\Lib\site-packages\OpenSSL\SSL.py", line 2076, in recv
    self._raise_ssl_error(self._ssl, result)
  File "C:\Users\Marios Stefanidis\AppData\Local\Programs\Python\Python311\Lib\site-packages\OpenSSL\SSL.py", line 1814, in _raise_ssl_error
    raise ZeroReturnError()
OpenSSL.SSL.ZeroReturnError
2023-11-15 17:24:09,889 - INFO - SSL Connection closed!
2023-11-15 17:24:10,608 - INFO - Handshake was successful!
2023-11-15 17:24:10,623 - INFO - Master Key and IV were successfully sent.
2023-11-15 17:24:10,835 - INFO - Encryption process completed for source file: .\..\archive\2023\ZW\ITSC\EHZ.D\ZW.ITSC.00.EHZ.D.2023.316.
2023-11-15 17:24:10,836 - INFO - Total Size of Data and Chunk Size were successfully sent.
2023-11-15 17:24:10,836 - INFO - Encrypted data were sent successfully.
2023-11-15 17:24:10,838 - INFO - Filename encrypted and sent successfully.
2023-11-15 17:24:10,982 - ERROR - TLS handshake error: 
Traceback (most recent call last):
  File "C:\Users\Marios Stefanidis\Documents\GitHub\Diploma-Thesis\code\slarchive-server\encryption\ssl_con.py", line 153, in run
    rejection_message = self.ssl_socket.recv(4096)
                        ^^^^^^^^^^^^^^^^^^^^^^^^^^
  File "C:\Users\Marios Stefanidis\AppData\Local\Programs\Python\Python311\Lib\site-packages\OpenSSL\SSL.py", line 2076, in recv
    self._raise_ssl_error(self._ssl, result)
  File "C:\Users\Marios Stefanidis\AppData\Local\Programs\Python\Python311\Lib\site-packages\OpenSSL\SSL.py", line 1814, in _raise_ssl_error
    raise ZeroReturnError()
OpenSSL.SSL.ZeroReturnError
2023-11-15 17:24:10,984 - INFO - SSL Connection closed!
2023-11-15 17:37:06,162 - INFO - Handshake was successful!
2023-11-15 17:37:06,173 - INFO - Master Key and IV were successfully sent.
2023-11-15 17:37:06,396 - INFO - Encryption process completed for source file: .\..\archive\2023\ZW\ITSC\EHE.D\ZW.ITSC.00.EHE.D.2023.316.
2023-11-15 17:37:06,398 - INFO - Total Size of Data and Chunk Size were successfully sent.
2023-11-15 17:37:06,398 - INFO - Encrypted data were sent successfully.
2023-11-15 17:37:06,399 - INFO - Filename encrypted and sent successfully.
2023-11-15 17:37:06,620 - ERROR - TLS handshake error: 
Traceback (most recent call last):
  File "C:\Users\Marios Stefanidis\Documents\GitHub\Diploma-Thesis\code\slarchive-server\encryption\ssl_con.py", line 153, in run
    rejection_message = self.ssl_socket.recv(4096)
                        ^^^^^^^^^^^^^^^^^^^^^^^^^^
  File "C:\Users\Marios Stefanidis\AppData\Local\Programs\Python\Python311\Lib\site-packages\OpenSSL\SSL.py", line 2076, in recv
    self._raise_ssl_error(self._ssl, result)
  File "C:\Users\Marios Stefanidis\AppData\Local\Programs\Python\Python311\Lib\site-packages\OpenSSL\SSL.py", line 1814, in _raise_ssl_error
    raise ZeroReturnError()
OpenSSL.SSL.ZeroReturnError
2023-11-15 17:37:06,621 - INFO - SSL Connection closed!
2023-11-15 17:37:07,241 - INFO - Handshake was successful!
2023-11-15 17:37:07,252 - INFO - Master Key and IV were successfully sent.
2023-11-15 17:37:07,587 - INFO - Encryption process completed for source file: .\..\archive\2023\ZW\ITSC\EHN.D\ZW.ITSC.00.EHN.D.2023.316.
2023-11-15 17:37:07,589 - INFO - Total Size of Data and Chunk Size were successfully sent.
2023-11-15 17:37:07,589 - INFO - Encrypted data were sent successfully.
2023-11-15 17:37:07,590 - INFO - Filename encrypted and sent successfully.
2023-11-15 17:37:07,723 - ERROR - TLS handshake error: 
Traceback (most recent call last):
  File "C:\Users\Marios Stefanidis\Documents\GitHub\Diploma-Thesis\code\slarchive-server\encryption\ssl_con.py", line 153, in run
    rejection_message = self.ssl_socket.recv(4096)
                        ^^^^^^^^^^^^^^^^^^^^^^^^^^
  File "C:\Users\Marios Stefanidis\AppData\Local\Programs\Python\Python311\Lib\site-packages\OpenSSL\SSL.py", line 2076, in recv
    self._raise_ssl_error(self._ssl, result)
  File "C:\Users\Marios Stefanidis\AppData\Local\Programs\Python\Python311\Lib\site-packages\OpenSSL\SSL.py", line 1814, in _raise_ssl_error
    raise ZeroReturnError()
OpenSSL.SSL.ZeroReturnError
2023-11-15 17:37:07,725 - INFO - SSL Connection closed!
2023-11-15 17:37:08,345 - INFO - Handshake was successful!
2023-11-15 17:37:08,359 - INFO - Master Key and IV were successfully sent.
2023-11-15 17:37:08,556 - INFO - Encryption process completed for source file: .\..\archive\2023\ZW\ITSC\EHZ.D\ZW.ITSC.00.EHZ.D.2023.316.
2023-11-15 17:37:08,557 - INFO - Total Size of Data and Chunk Size were successfully sent.
2023-11-15 17:37:08,558 - INFO - Encrypted data were sent successfully.
2023-11-15 17:37:08,558 - INFO - Filename encrypted and sent successfully.
2023-11-15 17:37:08,701 - ERROR - TLS handshake error: 
Traceback (most recent call last):
  File "C:\Users\Marios Stefanidis\Documents\GitHub\Diploma-Thesis\code\slarchive-server\encryption\ssl_con.py", line 153, in run
    rejection_message = self.ssl_socket.recv(4096)
                        ^^^^^^^^^^^^^^^^^^^^^^^^^^
  File "C:\Users\Marios Stefanidis\AppData\Local\Programs\Python\Python311\Lib\site-packages\OpenSSL\SSL.py", line 2076, in recv
    self._raise_ssl_error(self._ssl, result)
  File "C:\Users\Marios Stefanidis\AppData\Local\Programs\Python\Python311\Lib\site-packages\OpenSSL\SSL.py", line 1814, in _raise_ssl_error
    raise ZeroReturnError()
OpenSSL.SSL.ZeroReturnError
2023-11-15 17:37:08,703 - INFO - SSL Connection closed!
2023-11-15 18:05:31,433 - INFO - Handshake was successful!
2023-11-15 18:05:31,448 - INFO - Master Key and IV were successfully sent.
2023-11-15 18:05:31,650 - INFO - Encryption process completed for source file: .\..\archive\2023\HP\UPR\HHZ.D\HP.UPR..HHZ.D.2023.319.
2023-11-15 18:05:31,652 - INFO - Total Size of Data and Chunk Size were successfully sent.
2023-11-15 18:05:31,652 - INFO - Encrypted data were sent successfully.
2023-11-15 18:05:31,653 - INFO - Filename encrypted and sent successfully.
2023-11-15 18:05:31,777 - ERROR - TLS handshake error: 
Traceback (most recent call last):
  File "C:\Users\Marios Stefanidis\Documents\GitHub\Diploma-Thesis\code\slarchive-server\encryption\ssl_con.py", line 153, in run
    rejection_message = self.ssl_socket.recv(4096)
                        ^^^^^^^^^^^^^^^^^^^^^^^^^^
  File "C:\Users\Marios Stefanidis\AppData\Local\Programs\Python\Python311\Lib\site-packages\OpenSSL\SSL.py", line 2076, in recv
    self._raise_ssl_error(self._ssl, result)
  File "C:\Users\Marios Stefanidis\AppData\Local\Programs\Python\Python311\Lib\site-packages\OpenSSL\SSL.py", line 1814, in _raise_ssl_error
    raise ZeroReturnError()
OpenSSL.SSL.ZeroReturnError
2023-11-15 18:05:31,779 - INFO - SSL Connection closed!
2023-11-15 18:06:08,048 - INFO - Handshake was successful!
2023-11-15 18:06:08,063 - INFO - Master Key and IV were successfully sent.
2023-11-15 18:06:08,274 - INFO - Encryption process completed for source file: .\..\archive\2023\HP\UPR\HHZ.D\HP.UPR..HHZ.D.2023.319.
2023-11-15 18:06:08,276 - INFO - Total Size of Data and Chunk Size were successfully sent.
2023-11-15 18:06:08,276 - INFO - Encrypted data were sent successfully.
2023-11-15 18:06:08,277 - INFO - Filename encrypted and sent successfully.
2023-11-15 18:06:08,413 - ERROR - TLS handshake error: 
Traceback (most recent call last):
  File "C:\Users\Marios Stefanidis\Documents\GitHub\Diploma-Thesis\code\slarchive-server\encryption\ssl_con.py", line 153, in run
    rejection_message = self.ssl_socket.recv(4096)
                        ^^^^^^^^^^^^^^^^^^^^^^^^^^
  File "C:\Users\Marios Stefanidis\AppData\Local\Programs\Python\Python311\Lib\site-packages\OpenSSL\SSL.py", line 2076, in recv
    self._raise_ssl_error(self._ssl, result)
  File "C:\Users\Marios Stefanidis\AppData\Local\Programs\Python\Python311\Lib\site-packages\OpenSSL\SSL.py", line 1814, in _raise_ssl_error
    raise ZeroReturnError()
OpenSSL.SSL.ZeroReturnError
2023-11-15 18:06:08,415 - INFO - SSL Connection closed!
2023-11-15 18:06:30,014 - INFO - Handshake was successful!
2023-11-15 18:06:30,035 - INFO - Master Key and IV were successfully sent.
2023-11-15 18:06:30,557 - INFO - Encryption process completed for source file: .\..\archive\2023\HP\UPR\HHZ.D\HP.UPR..HHZ.D.2023.319.
2023-11-15 18:06:30,560 - INFO - Total Size of Data and Chunk Size were successfully sent.
2023-11-15 18:06:30,561 - INFO - Encrypted data were sent successfully.
2023-11-15 18:06:30,563 - INFO - Filename encrypted and sent successfully.
2023-11-15 18:06:30,826 - ERROR - TLS handshake error: 
Traceback (most recent call last):
  File "C:\Users\Marios Stefanidis\Documents\GitHub\Diploma-Thesis\code\slarchive-server\encryption\ssl_con.py", line 153, in run
    rejection_message = self.ssl_socket.recv(4096)
                        ^^^^^^^^^^^^^^^^^^^^^^^^^^
  File "C:\Users\Marios Stefanidis\AppData\Local\Programs\Python\Python311\Lib\site-packages\OpenSSL\SSL.py", line 2076, in recv
    self._raise_ssl_error(self._ssl, result)
  File "C:\Users\Marios Stefanidis\AppData\Local\Programs\Python\Python311\Lib\site-packages\OpenSSL\SSL.py", line 1814, in _raise_ssl_error
    raise ZeroReturnError()
OpenSSL.SSL.ZeroReturnError
2023-11-15 18:06:30,829 - INFO - SSL Connection closed!
2023-11-15 18:08:50,398 - INFO - Handshake was successful!
2023-11-15 18:08:50,410 - INFO - Master Key and IV were successfully sent.
2023-11-15 18:08:50,613 - INFO - Encryption process completed for source file: .\..\archive\2023\HP\UPR\HHZ.D\HP.UPR..HHZ.D.2023.319.
2023-11-15 18:08:50,614 - INFO - Total Size of Data and Chunk Size were successfully sent.
2023-11-15 18:08:50,615 - INFO - Encrypted data were sent successfully.
2023-11-15 18:08:50,616 - INFO - Filename encrypted and sent successfully.
2023-11-15 18:08:50,749 - ERROR - TLS handshake error: 
Traceback (most recent call last):
  File "C:\Users\Marios Stefanidis\Documents\GitHub\Diploma-Thesis\code\slarchive-server\encryption\ssl_con.py", line 153, in run
    rejection_message = self.ssl_socket.recv(4096)
                        ^^^^^^^^^^^^^^^^^^^^^^^^^^
  File "C:\Users\Marios Stefanidis\AppData\Local\Programs\Python\Python311\Lib\site-packages\OpenSSL\SSL.py", line 2076, in recv
    self._raise_ssl_error(self._ssl, result)
  File "C:\Users\Marios Stefanidis\AppData\Local\Programs\Python\Python311\Lib\site-packages\OpenSSL\SSL.py", line 1814, in _raise_ssl_error
    raise ZeroReturnError()
OpenSSL.SSL.ZeroReturnError
2023-11-15 18:08:50,750 - INFO - SSL Connection closed!
2023-11-15 18:09:32,536 - INFO - Handshake was successful!
2023-11-15 18:09:32,558 - INFO - Master Key and IV were successfully sent.
2023-11-15 18:09:32,783 - INFO - Encryption process completed for source file: .\..\archive\2023\HP\UPR\HHZ.D\HP.UPR..HHZ.D.2023.319.
2023-11-15 18:09:32,784 - INFO - Total Size of Data and Chunk Size were successfully sent.
2023-11-15 18:09:32,784 - INFO - Encrypted data were sent successfully.
2023-11-15 18:09:32,785 - INFO - Filename encrypted and sent successfully.
2023-11-15 18:09:32,921 - ERROR - TLS handshake error: 
Traceback (most recent call last):
  File "C:\Users\Marios Stefanidis\Documents\GitHub\Diploma-Thesis\code\slarchive-server\encryption\ssl_con.py", line 153, in run
    rejection_message = self.ssl_socket.recv(4096)
                        ^^^^^^^^^^^^^^^^^^^^^^^^^^
  File "C:\Users\Marios Stefanidis\AppData\Local\Programs\Python\Python311\Lib\site-packages\OpenSSL\SSL.py", line 2076, in recv
    self._raise_ssl_error(self._ssl, result)
  File "C:\Users\Marios Stefanidis\AppData\Local\Programs\Python\Python311\Lib\site-packages\OpenSSL\SSL.py", line 1814, in _raise_ssl_error
    raise ZeroReturnError()
OpenSSL.SSL.ZeroReturnError
2023-11-15 18:09:32,924 - INFO - SSL Connection closed!
2023-11-15 18:10:56,405 - INFO - Handshake was successful!
2023-11-15 18:10:56,422 - INFO - Master Key and IV were successfully sent.
2023-11-15 18:10:56,752 - INFO - Encryption process completed for source file: .\..\archive\2023\HP\UPR\HHZ.D\HP.UPR..HHZ.D.2023.319.
2023-11-15 18:10:56,755 - INFO - Total Size of Data and Chunk Size were successfully sent.
2023-11-15 18:10:56,755 - INFO - Encrypted data were sent successfully.
2023-11-15 18:10:56,756 - INFO - Filename encrypted and sent successfully.
2023-11-15 18:10:57,013 - ERROR - TLS handshake error: 
Traceback (most recent call last):
  File "C:\Users\Marios Stefanidis\Documents\GitHub\Diploma-Thesis\code\slarchive-server\encryption\ssl_con.py", line 153, in run
    rejection_message = self.ssl_socket.recv(4096)
                        ^^^^^^^^^^^^^^^^^^^^^^^^^^
  File "C:\Users\Marios Stefanidis\AppData\Local\Programs\Python\Python311\Lib\site-packages\OpenSSL\SSL.py", line 2076, in recv
    self._raise_ssl_error(self._ssl, result)
  File "C:\Users\Marios Stefanidis\AppData\Local\Programs\Python\Python311\Lib\site-packages\OpenSSL\SSL.py", line 1814, in _raise_ssl_error
    raise ZeroReturnError()
OpenSSL.SSL.ZeroReturnError
2023-11-15 18:10:57,015 - INFO - SSL Connection closed!
2023-11-15 18:10:57,780 - INFO - Handshake was successful!
2023-11-15 18:10:57,795 - INFO - Master Key and IV were successfully sent.
2023-11-15 18:10:58,102 - INFO - Encryption process completed for source file: .\..\archive\2023\HP\UPR\HHZ.D\HP.UPR..HHZ.D.2023.319.
2023-11-15 18:10:58,104 - INFO - Total Size of Data and Chunk Size were successfully sent.
2023-11-15 18:10:58,105 - INFO - Encrypted data were sent successfully.
2023-11-15 18:10:58,106 - INFO - Filename encrypted and sent successfully.
2023-11-15 18:10:58,409 - ERROR - TLS handshake error: 
Traceback (most recent call last):
  File "C:\Users\Marios Stefanidis\Documents\GitHub\Diploma-Thesis\code\slarchive-server\encryption\ssl_con.py", line 153, in run
    rejection_message = self.ssl_socket.recv(4096)
                        ^^^^^^^^^^^^^^^^^^^^^^^^^^
  File "C:\Users\Marios Stefanidis\AppData\Local\Programs\Python\Python311\Lib\site-packages\OpenSSL\SSL.py", line 2076, in recv
    self._raise_ssl_error(self._ssl, result)
  File "C:\Users\Marios Stefanidis\AppData\Local\Programs\Python\Python311\Lib\site-packages\OpenSSL\SSL.py", line 1814, in _raise_ssl_error
    raise ZeroReturnError()
OpenSSL.SSL.ZeroReturnError
2023-11-15 18:10:58,411 - INFO - SSL Connection closed!
2023-11-15 18:11:41,565 - INFO - Handshake was successful!
2023-11-15 18:11:41,584 - INFO - Master Key and IV were successfully sent.
2023-11-15 18:11:42,022 - INFO - Encryption process completed for source file: .\..\archive\2023\HP\UPR\HHZ.D\HP.UPR..HHZ.D.2023.319.
2023-11-15 18:11:42,024 - INFO - Total Size of Data and Chunk Size were successfully sent.
2023-11-15 18:11:42,025 - INFO - Encrypted data were sent successfully.
2023-11-15 18:11:42,026 - INFO - Filename encrypted and sent successfully.
2023-11-15 18:11:42,241 - ERROR - TLS handshake error: 
Traceback (most recent call last):
  File "C:\Users\Marios Stefanidis\Documents\GitHub\Diploma-Thesis\code\slarchive-server\encryption\ssl_con.py", line 153, in run
    rejection_message = self.ssl_socket.recv(4096)
                        ^^^^^^^^^^^^^^^^^^^^^^^^^^
  File "C:\Users\Marios Stefanidis\AppData\Local\Programs\Python\Python311\Lib\site-packages\OpenSSL\SSL.py", line 2076, in recv
    self._raise_ssl_error(self._ssl, result)
  File "C:\Users\Marios Stefanidis\AppData\Local\Programs\Python\Python311\Lib\site-packages\OpenSSL\SSL.py", line 1814, in _raise_ssl_error
    raise ZeroReturnError()
OpenSSL.SSL.ZeroReturnError
2023-11-15 18:11:42,243 - INFO - SSL Connection closed!
2023-11-17 23:29:30,362 - INFO - Handshake was successful!
2023-11-17 23:29:30,420 - INFO - Master Key and IV were successfully sent.
2023-11-17 23:29:30,648 - INFO - Encryption process completed for source file: .\..\archive\2023\HP\UPR\HHZ.D\HP.UPR..HHZ.D.2023.321.
2023-11-17 23:29:30,650 - INFO - Total Size of Data and Chunk Size were successfully sent.
2023-11-17 23:29:30,650 - INFO - Encrypted data were sent successfully.
2023-11-17 23:29:30,651 - INFO - Filename encrypted and sent successfully.
2023-11-17 23:29:30,864 - ERROR - TLS handshake error: 
Traceback (most recent call last):
  File "C:\Users\Marios Stefanidis\Documents\GitHub\Diploma-Thesis\code\slarchive-server\encryption\ssl_con.py", line 153, in run
    rejection_message = self.ssl_socket.recv(4096)
                        ^^^^^^^^^^^^^^^^^^^^^^^^^^
  File "C:\Users\Marios Stefanidis\AppData\Local\Programs\Python\Python311\Lib\site-packages\OpenSSL\SSL.py", line 2076, in recv
    self._raise_ssl_error(self._ssl, result)
  File "C:\Users\Marios Stefanidis\AppData\Local\Programs\Python\Python311\Lib\site-packages\OpenSSL\SSL.py", line 1814, in _raise_ssl_error
    raise ZeroReturnError()
OpenSSL.SSL.ZeroReturnError
2023-11-17 23:29:30,881 - INFO - SSL Connection closed!
2023-11-17 23:29:31,665 - INFO - Handshake was successful!
2023-11-17 23:29:31,688 - INFO - Master Key and IV were successfully sent.
2023-11-17 23:29:31,896 - INFO - Encryption process completed for source file: .\..\archive\2023\HP\UPR\HHE.D\HP.UPR..HHE.D.2023.321.
2023-11-17 23:29:31,898 - INFO - Total Size of Data and Chunk Size were successfully sent.
2023-11-17 23:29:31,898 - INFO - Encrypted data were sent successfully.
2023-11-17 23:29:31,899 - INFO - Filename encrypted and sent successfully.
2023-11-17 23:29:32,029 - ERROR - TLS handshake error: 
Traceback (most recent call last):
  File "C:\Users\Marios Stefanidis\Documents\GitHub\Diploma-Thesis\code\slarchive-server\encryption\ssl_con.py", line 153, in run
    rejection_message = self.ssl_socket.recv(4096)
                        ^^^^^^^^^^^^^^^^^^^^^^^^^^
  File "C:\Users\Marios Stefanidis\AppData\Local\Programs\Python\Python311\Lib\site-packages\OpenSSL\SSL.py", line 2076, in recv
    self._raise_ssl_error(self._ssl, result)
  File "C:\Users\Marios Stefanidis\AppData\Local\Programs\Python\Python311\Lib\site-packages\OpenSSL\SSL.py", line 1814, in _raise_ssl_error
    raise ZeroReturnError()
OpenSSL.SSL.ZeroReturnError
2023-11-17 23:29:32,031 - INFO - SSL Connection closed!
2023-11-17 23:29:32,862 - INFO - Handshake was successful!
2023-11-17 23:29:32,880 - INFO - Master Key and IV were successfully sent.
2023-11-17 23:29:33,093 - INFO - Encryption process completed for source file: .\..\archive\2023\HP\UPR\HHN.D\HP.UPR..HHN.D.2023.321.
2023-11-17 23:29:33,093 - INFO - Total Size of Data and Chunk Size were successfully sent.
2023-11-17 23:29:33,093 - INFO - Encrypted data were sent successfully.
2023-11-17 23:29:33,093 - INFO - Filename encrypted and sent successfully.
2023-11-17 23:29:33,225 - ERROR - TLS handshake error: 
Traceback (most recent call last):
  File "C:\Users\Marios Stefanidis\Documents\GitHub\Diploma-Thesis\code\slarchive-server\encryption\ssl_con.py", line 153, in run
    rejection_message = self.ssl_socket.recv(4096)
                        ^^^^^^^^^^^^^^^^^^^^^^^^^^
  File "C:\Users\Marios Stefanidis\AppData\Local\Programs\Python\Python311\Lib\site-packages\OpenSSL\SSL.py", line 2076, in recv
    self._raise_ssl_error(self._ssl, result)
  File "C:\Users\Marios Stefanidis\AppData\Local\Programs\Python\Python311\Lib\site-packages\OpenSSL\SSL.py", line 1814, in _raise_ssl_error
    raise ZeroReturnError()
OpenSSL.SSL.ZeroReturnError
2023-11-17 23:29:33,225 - INFO - SSL Connection closed!
2023-11-17 23:30:05,589 - INFO - Handshake was successful!
2023-11-17 23:30:05,601 - INFO - Master Key and IV were successfully sent.
2023-11-17 23:30:05,787 - INFO - Encryption process completed for source file: .\..\archive\2023\HP\UPR\HHE.D\HP.UPR..HHE.D.2023.321.
2023-11-17 23:30:05,787 - INFO - Total Size of Data and Chunk Size were successfully sent.
2023-11-17 23:30:05,787 - INFO - Encrypted data were sent successfully.
2023-11-17 23:30:05,787 - INFO - Filename encrypted and sent successfully.
2023-11-17 23:30:05,915 - ERROR - TLS handshake error: 
Traceback (most recent call last):
  File "C:\Users\Marios Stefanidis\Documents\GitHub\Diploma-Thesis\code\slarchive-server\encryption\ssl_con.py", line 153, in run
    rejection_message = self.ssl_socket.recv(4096)
                        ^^^^^^^^^^^^^^^^^^^^^^^^^^
  File "C:\Users\Marios Stefanidis\AppData\Local\Programs\Python\Python311\Lib\site-packages\OpenSSL\SSL.py", line 2076, in recv
    self._raise_ssl_error(self._ssl, result)
  File "C:\Users\Marios Stefanidis\AppData\Local\Programs\Python\Python311\Lib\site-packages\OpenSSL\SSL.py", line 1814, in _raise_ssl_error
    raise ZeroReturnError()
OpenSSL.SSL.ZeroReturnError
2023-11-17 23:30:05,917 - INFO - SSL Connection closed!
2023-11-17 23:30:06,604 - INFO - Handshake was successful!
2023-11-17 23:30:06,615 - INFO - Master Key and IV were successfully sent.
2023-11-17 23:30:06,914 - INFO - Encryption process completed for source file: .\..\archive\2023\HP\UPR\HHZ.D\HP.UPR..HHZ.D.2023.321.
2023-11-17 23:30:06,914 - INFO - Total Size of Data and Chunk Size were successfully sent.
2023-11-17 23:30:06,914 - INFO - Encrypted data were sent successfully.
2023-11-17 23:30:06,914 - INFO - Filename encrypted and sent successfully.
2023-11-17 23:30:07,036 - ERROR - TLS handshake error: 
Traceback (most recent call last):
  File "C:\Users\Marios Stefanidis\Documents\GitHub\Diploma-Thesis\code\slarchive-server\encryption\ssl_con.py", line 153, in run
    rejection_message = self.ssl_socket.recv(4096)
                        ^^^^^^^^^^^^^^^^^^^^^^^^^^
  File "C:\Users\Marios Stefanidis\AppData\Local\Programs\Python\Python311\Lib\site-packages\OpenSSL\SSL.py", line 2076, in recv
    self._raise_ssl_error(self._ssl, result)
  File "C:\Users\Marios Stefanidis\AppData\Local\Programs\Python\Python311\Lib\site-packages\OpenSSL\SSL.py", line 1814, in _raise_ssl_error
    raise ZeroReturnError()
OpenSSL.SSL.ZeroReturnError
2023-11-17 23:30:07,036 - INFO - SSL Connection closed!
2023-11-17 23:30:07,648 - INFO - Handshake was successful!
2023-11-17 23:30:07,674 - INFO - Master Key and IV were successfully sent.
2023-11-17 23:30:07,857 - INFO - Encryption process completed for source file: .\..\archive\2023\HP\UPR\HHN.D\HP.UPR..HHN.D.2023.321.
2023-11-17 23:30:07,857 - INFO - Total Size of Data and Chunk Size were successfully sent.
2023-11-17 23:30:07,857 - INFO - Encrypted data were sent successfully.
2023-11-17 23:30:07,857 - INFO - Filename encrypted and sent successfully.
2023-11-17 23:30:07,998 - ERROR - TLS handshake error: 
Traceback (most recent call last):
  File "C:\Users\Marios Stefanidis\Documents\GitHub\Diploma-Thesis\code\slarchive-server\encryption\ssl_con.py", line 153, in run
    rejection_message = self.ssl_socket.recv(4096)
                        ^^^^^^^^^^^^^^^^^^^^^^^^^^
  File "C:\Users\Marios Stefanidis\AppData\Local\Programs\Python\Python311\Lib\site-packages\OpenSSL\SSL.py", line 2076, in recv
    self._raise_ssl_error(self._ssl, result)
  File "C:\Users\Marios Stefanidis\AppData\Local\Programs\Python\Python311\Lib\site-packages\OpenSSL\SSL.py", line 1814, in _raise_ssl_error
    raise ZeroReturnError()
OpenSSL.SSL.ZeroReturnError
2023-11-17 23:30:07,998 - INFO - SSL Connection closed!
